[2025-01-28T04:24:11.184+0000] {local_task_job_runner.py:123} INFO - ::group::Pre task execution logs
[2025-01-28T04:24:12.051+0000] {taskinstance.py:2613} INFO - Dependencies all met for dep_context=non-requeueable deps ti=<TaskInstance: etl_reporte_como_vamos.task_bot_como_vamos manual__2025-01-28T04:24:08.704438+00:00 [queued]>
[2025-01-28T04:24:12.068+0000] {taskinstance.py:2613} INFO - Dependencies all met for dep_context=requeueable deps ti=<TaskInstance: etl_reporte_como_vamos.task_bot_como_vamos manual__2025-01-28T04:24:08.704438+00:00 [queued]>
[2025-01-28T04:24:12.070+0000] {taskinstance.py:2866} INFO - Starting attempt 1 of 2
[2025-01-28T04:24:12.096+0000] {taskinstance.py:2889} INFO - Executing <Task(BashOperator): task_bot_como_vamos> on 2025-01-28 04:24:08.704438+00:00
[2025-01-28T04:24:12.109+0000] {standard_task_runner.py:104} INFO - Running: ['***', 'tasks', 'run', 'etl_reporte_como_vamos', 'task_bot_como_vamos', 'manual__2025-01-28T04:24:08.704438+00:00', '--job-id', '21', '--raw', '--subdir', 'DAGS_FOLDER/etl_como_vamos_dag.py', '--cfg-path', '/tmp/tmpi68nxd69']
[2025-01-28T04:24:12.115+0000] {standard_task_runner.py:105} INFO - Job 21: Subtask task_bot_como_vamos
[2025-01-28T04:24:12.116+0000] {logging_mixin.py:190} WARNING - /home/***/.local/lib/python3.12/site-packages/***/task/task_runner/standard_task_runner.py:70 DeprecationWarning: This process (pid=214) is multi-threaded, use of fork() may lead to deadlocks in the child.
[2025-01-28T04:24:12.120+0000] {standard_task_runner.py:72} INFO - Started process 218 to run task
[2025-01-28T04:24:12.233+0000] {task_command.py:467} INFO - Running <TaskInstance: etl_reporte_como_vamos.task_bot_como_vamos manual__2025-01-28T04:24:08.704438+00:00 [running]> on host 9f50f588cff7
[2025-01-28T04:24:12.382+0000] {taskinstance.py:3132} INFO - Exporting env vars: AIRFLOW_CTX_DAG_OWNER='***' AIRFLOW_CTX_DAG_ID='etl_reporte_como_vamos' AIRFLOW_CTX_TASK_ID='task_bot_como_vamos' AIRFLOW_CTX_EXECUTION_DATE='2025-01-28T04:24:08.704438+00:00' AIRFLOW_CTX_TRY_NUMBER='1' AIRFLOW_CTX_DAG_RUN_ID='manual__2025-01-28T04:24:08.704438+00:00'
[2025-01-28T04:24:12.384+0000] {taskinstance.py:731} INFO - ::endgroup::
[2025-01-28T04:24:12.426+0000] {subprocess.py:78} INFO - Tmp dir root location: /tmp
[2025-01-28T04:24:12.429+0000] {subprocess.py:88} INFO - Running command: ['/usr/bin/bash', '-c', 'python /opt/***/scripts/bot_reporte_como_vamos.py']
[2025-01-28T04:24:12.444+0000] {subprocess.py:99} INFO - Output:
[2025-01-28T04:24:16.427+0000] {subprocess.py:106} INFO - ic| start_date: '01/01/2025', end_date: '28/01/2025'
[2025-01-28T04:24:16.429+0000] {subprocess.py:106} INFO - 2025-01-28 04:24:16,427 - bot_como_vamos - INFO - Starting script bot_como_vamos.py
[2025-01-28T04:25:15.835+0000] {subprocess.py:106} INFO - Starting script bot_como_vamos.py
[2025-01-28T04:25:15.861+0000] {subprocess.py:106} INFO - Traceback (most recent call last):
[2025-01-28T04:25:15.863+0000] {subprocess.py:106} INFO -   File "/opt/***/scripts/bot_reporte_como_vamos.py", line 143, in <module>
[2025-01-28T04:25:15.867+0000] {subprocess.py:106} INFO -     main()
[2025-01-28T04:25:15.869+0000] {subprocess.py:106} INFO -   File "/opt/***/scripts/bot_reporte_como_vamos.py", line 94, in main
[2025-01-28T04:25:15.870+0000] {subprocess.py:106} INFO -     menu_button = driver.find_element(By.XPATH, "/html/body/div[3]/nav/ul[2]/li[2]/a")
[2025-01-28T04:25:15.871+0000] {subprocess.py:106} INFO -                   ^^^^^^^^^^^^^^^^^^^^^^^^^^^^^^^^^^^^^^^^^^^^^^^^^^^^^^^^^^^^^^^^^^^^
[2025-01-28T04:25:15.871+0000] {subprocess.py:106} INFO -   File "/home/***/.local/lib/python3.12/site-packages/selenium/webdriver/remote/webdriver.py", line 888, in find_element
[2025-01-28T04:25:15.873+0000] {subprocess.py:106} INFO -     return self.execute(Command.FIND_ELEMENT, {"using": by, "value": value})["value"]
[2025-01-28T04:25:15.874+0000] {subprocess.py:106} INFO -            ^^^^^^^^^^^^^^^^^^^^^^^^^^^^^^^^^^^^^^^^^^^^^^^^^^^^^^^^^^^^^^^^^
[2025-01-28T04:25:15.876+0000] {subprocess.py:106} INFO -   File "/home/***/.local/lib/python3.12/site-packages/selenium/webdriver/remote/webdriver.py", line 429, in execute
[2025-01-28T04:25:15.877+0000] {subprocess.py:106} INFO -     self.error_handler.check_response(response)
[2025-01-28T04:25:15.878+0000] {subprocess.py:106} INFO -   File "/home/***/.local/lib/python3.12/site-packages/selenium/webdriver/remote/errorhandler.py", line 232, in check_response
[2025-01-28T04:25:15.881+0000] {subprocess.py:106} INFO -     raise exception_class(message, screen, stacktrace)
[2025-01-28T04:25:15.883+0000] {subprocess.py:106} INFO - selenium.common.exceptions.WebDriverException: Message: unknown error: session deleted because of page crash
[2025-01-28T04:25:15.884+0000] {subprocess.py:106} INFO - from unknown error: cannot determine loading status
[2025-01-28T04:25:15.886+0000] {subprocess.py:106} INFO - from tab crashed
[2025-01-28T04:25:15.888+0000] {subprocess.py:106} INFO -   (Session info: chrome=132.0.6834.110)
[2025-01-28T04:25:15.888+0000] {subprocess.py:106} INFO - Stacktrace:
[2025-01-28T04:25:15.889+0000] {subprocess.py:106} INFO - #0 0x5621f67c3dca <unknown>
[2025-01-28T04:25:15.890+0000] {subprocess.py:106} INFO - #1 0x5621f62ba24d <unknown>
[2025-01-28T04:25:15.891+0000] {subprocess.py:106} INFO - #2 0x5621f62a2366 <unknown>
[2025-01-28T04:25:15.892+0000] {subprocess.py:106} INFO - #3 0x5621f62a0346 <unknown>
[2025-01-28T04:25:15.893+0000] {subprocess.py:106} INFO - #4 0x5621f62a0b2f <unknown>
[2025-01-28T04:25:15.894+0000] {subprocess.py:106} INFO - #5 0x5621f62b0447 <unknown>
[2025-01-28T04:25:15.895+0000] {subprocess.py:106} INFO - #6 0x5621f62c76b4 <unknown>
[2025-01-28T04:25:15.896+0000] {subprocess.py:106} INFO - #7 0x5621f62cd5ab <unknown>
[2025-01-28T04:25:15.896+0000] {subprocess.py:106} INFO - #8 0x5621f62a1237 <unknown>
[2025-01-28T04:25:15.897+0000] {subprocess.py:106} INFO - #9 0x5621f62c718d <unknown>
[2025-01-28T04:25:15.897+0000] {subprocess.py:106} INFO - #10 0x5621f634d382 <unknown>
[2025-01-28T04:25:15.898+0000] {subprocess.py:106} INFO - #11 0x5621f632e833 <unknown>
[2025-01-28T04:25:15.898+0000] {subprocess.py:106} INFO - #12 0x5621f62fb5a0 <unknown>
[2025-01-28T04:25:15.899+0000] {subprocess.py:106} INFO - #13 0x5621f62fcece <unknown>
[2025-01-28T04:25:15.900+0000] {subprocess.py:106} INFO - #14 0x5621f678dbdb <unknown>
[2025-01-28T04:25:15.900+0000] {subprocess.py:106} INFO - #15 0x5621f6791b67 <unknown>
[2025-01-28T04:25:15.901+0000] {subprocess.py:106} INFO - #16 0x5621f67793bc <unknown>
[2025-01-28T04:25:15.902+0000] {subprocess.py:106} INFO - #17 0x5621f6792727 <unknown>
[2025-01-28T04:25:15.903+0000] {subprocess.py:106} INFO - #18 0x5621f675d74f <unknown>
[2025-01-28T04:25:15.904+0000] {subprocess.py:106} INFO - #19 0x5621f67b2938 <unknown>
[2025-01-28T04:25:15.905+0000] {subprocess.py:106} INFO - #20 0x5621f67b2b00 <unknown>
[2025-01-28T04:25:15.905+0000] {subprocess.py:106} INFO - #21 0x5621f67c2c46 <unknown>
[2025-01-28T04:25:15.906+0000] {subprocess.py:106} INFO - #22 0x7f426409ca94 <unknown>
[2025-01-28T04:25:15.907+0000] {subprocess.py:106} INFO - #23 0x7f4264129c3c <unknown>
[2025-01-28T04:25:15.908+0000] {subprocess.py:106} INFO - 
[2025-01-28T04:25:16.082+0000] {subprocess.py:110} INFO - Command exited with return code 1
[2025-01-28T04:25:16.120+0000] {taskinstance.py:3311} ERROR - Task failed with exception
Traceback (most recent call last):
  File "/home/airflow/.local/lib/python3.12/site-packages/airflow/models/taskinstance.py", line 767, in _execute_task
    result = _execute_callable(context=context, **execute_callable_kwargs)
             ^^^^^^^^^^^^^^^^^^^^^^^^^^^^^^^^^^^^^^^^^^^^^^^^^^^^^^^^^^^^^
  File "/home/airflow/.local/lib/python3.12/site-packages/airflow/models/taskinstance.py", line 733, in _execute_callable
    return ExecutionCallableRunner(
           ^^^^^^^^^^^^^^^^^^^^^^^^
  File "/home/airflow/.local/lib/python3.12/site-packages/airflow/utils/operator_helpers.py", line 252, in run
    return self.func(*args, **kwargs)
           ^^^^^^^^^^^^^^^^^^^^^^^^^^
  File "/home/airflow/.local/lib/python3.12/site-packages/airflow/models/baseoperator.py", line 422, in wrapper
    return func(self, *args, **kwargs)
           ^^^^^^^^^^^^^^^^^^^^^^^^^^^
  File "/home/airflow/.local/lib/python3.12/site-packages/airflow/operators/bash.py", line 276, in execute
    raise AirflowException(
airflow.exceptions.AirflowException: Bash command failed. The command returned a non-zero exit code 1.
[2025-01-28T04:25:16.158+0000] {taskinstance.py:1225} INFO - Marking task as UP_FOR_RETRY. dag_id=etl_reporte_como_vamos, task_id=task_bot_como_vamos, run_id=manual__2025-01-28T04:24:08.704438+00:00, execution_date=20250128T042408, start_date=20250128T042412, end_date=20250128T042516
[2025-01-28T04:25:16.198+0000] {taskinstance.py:340} INFO - ::group::Post task execution logs
[2025-01-28T04:25:16.201+0000] {standard_task_runner.py:124} ERROR - Failed to execute job 21 for task task_bot_como_vamos (Bash command failed. The command returned a non-zero exit code 1.; 218)
Traceback (most recent call last):
  File "/home/airflow/.local/lib/python3.12/site-packages/airflow/task/task_runner/standard_task_runner.py", line 117, in _start_by_fork
    ret = args.func(args, dag=self.dag)
          ^^^^^^^^^^^^^^^^^^^^^^^^^^^^^
  File "/home/airflow/.local/lib/python3.12/site-packages/airflow/cli/cli_config.py", line 49, in command
    return func(*args, **kwargs)
           ^^^^^^^^^^^^^^^^^^^^^
  File "/home/airflow/.local/lib/python3.12/site-packages/airflow/utils/cli.py", line 116, in wrapper
    return f(*args, **kwargs)
           ^^^^^^^^^^^^^^^^^^
  File "/home/airflow/.local/lib/python3.12/site-packages/airflow/cli/commands/task_command.py", line 483, in task_run
    task_return_code = _run_task_by_selected_method(args, _dag, ti)
                       ^^^^^^^^^^^^^^^^^^^^^^^^^^^^^^^^^^^^^^^^^^^^
  File "/home/airflow/.local/lib/python3.12/site-packages/airflow/cli/commands/task_command.py", line 256, in _run_task_by_selected_method
    return _run_raw_task(args, ti)
           ^^^^^^^^^^^^^^^^^^^^^^^
  File "/home/airflow/.local/lib/python3.12/site-packages/airflow/cli/commands/task_command.py", line 341, in _run_raw_task
    return ti._run_raw_task(
           ^^^^^^^^^^^^^^^^^
  File "/home/airflow/.local/lib/python3.12/site-packages/airflow/utils/session.py", line 97, in wrapper
    return func(*args, session=session, **kwargs)
           ^^^^^^^^^^^^^^^^^^^^^^^^^^^^^^^^^^^^^^
  File "/home/airflow/.local/lib/python3.12/site-packages/airflow/models/taskinstance.py", line 3005, in _run_raw_task
    return _run_raw_task(
           ^^^^^^^^^^^^^^
  File "/home/airflow/.local/lib/python3.12/site-packages/airflow/models/taskinstance.py", line 273, in _run_raw_task
    TaskInstance._execute_task_with_callbacks(
  File "/home/airflow/.local/lib/python3.12/site-packages/airflow/models/taskinstance.py", line 3159, in _execute_task_with_callbacks
    result = self._execute_task(context, task_orig)
             ^^^^^^^^^^^^^^^^^^^^^^^^^^^^^^^^^^^^^^
  File "/home/airflow/.local/lib/python3.12/site-packages/airflow/models/taskinstance.py", line 3183, in _execute_task
    return _execute_task(self, context, task_orig)
           ^^^^^^^^^^^^^^^^^^^^^^^^^^^^^^^^^^^^^^^
  File "/home/airflow/.local/lib/python3.12/site-packages/airflow/models/taskinstance.py", line 767, in _execute_task
    result = _execute_callable(context=context, **execute_callable_kwargs)
             ^^^^^^^^^^^^^^^^^^^^^^^^^^^^^^^^^^^^^^^^^^^^^^^^^^^^^^^^^^^^^
  File "/home/airflow/.local/lib/python3.12/site-packages/airflow/models/taskinstance.py", line 733, in _execute_callable
    return ExecutionCallableRunner(
           ^^^^^^^^^^^^^^^^^^^^^^^^
  File "/home/airflow/.local/lib/python3.12/site-packages/airflow/utils/operator_helpers.py", line 252, in run
    return self.func(*args, **kwargs)
           ^^^^^^^^^^^^^^^^^^^^^^^^^^
  File "/home/airflow/.local/lib/python3.12/site-packages/airflow/models/baseoperator.py", line 422, in wrapper
    return func(self, *args, **kwargs)
           ^^^^^^^^^^^^^^^^^^^^^^^^^^^
  File "/home/airflow/.local/lib/python3.12/site-packages/airflow/operators/bash.py", line 276, in execute
    raise AirflowException(
airflow.exceptions.AirflowException: Bash command failed. The command returned a non-zero exit code 1.
[2025-01-28T04:25:16.247+0000] {local_task_job_runner.py:266} INFO - Task exited with return code 1
[2025-01-28T04:25:16.292+0000] {taskinstance.py:3895} INFO - 0 downstream tasks scheduled from follow-on schedule check
[2025-01-28T04:25:16.295+0000] {local_task_job_runner.py:245} INFO - ::endgroup::
