[2025-01-28T04:30:19.505+0000] {local_task_job_runner.py:123} INFO - ::group::Pre task execution logs
[2025-01-28T04:30:24.001+0000] {taskinstance.py:2613} INFO - Dependencies all met for dep_context=non-requeueable deps ti=<TaskInstance: etl_reporte_como_vamos.task_bot_como_vamos manual__2025-01-28T04:24:08.704438+00:00 [queued]>
[2025-01-28T04:30:24.022+0000] {taskinstance.py:2613} INFO - Dependencies all met for dep_context=requeueable deps ti=<TaskInstance: etl_reporte_como_vamos.task_bot_como_vamos manual__2025-01-28T04:24:08.704438+00:00 [queued]>
[2025-01-28T04:30:24.024+0000] {taskinstance.py:2866} INFO - Starting attempt 2 of 2
[2025-01-28T04:30:24.058+0000] {taskinstance.py:2889} INFO - Executing <Task(BashOperator): task_bot_como_vamos> on 2025-01-28 04:24:08.704438+00:00
[2025-01-28T04:30:24.074+0000] {standard_task_runner.py:104} INFO - Running: ['***', 'tasks', 'run', 'etl_reporte_como_vamos', 'task_bot_como_vamos', 'manual__2025-01-28T04:24:08.704438+00:00', '--job-id', '22', '--raw', '--subdir', 'DAGS_FOLDER/etl_como_vamos_dag.py', '--cfg-path', '/tmp/tmppg59ywhr']
[2025-01-28T04:30:24.082+0000] {standard_task_runner.py:105} INFO - Job 22: Subtask task_bot_como_vamos
[2025-01-28T04:30:24.086+0000] {logging_mixin.py:190} WARNING - /home/***/.local/lib/python3.12/site-packages/***/task/task_runner/standard_task_runner.py:70 DeprecationWarning: This process (pid=463) is multi-threaded, use of fork() may lead to deadlocks in the child.
[2025-01-28T04:30:24.090+0000] {standard_task_runner.py:72} INFO - Started process 467 to run task
[2025-01-28T04:30:24.260+0000] {task_command.py:467} INFO - Running <TaskInstance: etl_reporte_como_vamos.task_bot_como_vamos manual__2025-01-28T04:24:08.704438+00:00 [running]> on host 9f50f588cff7
[2025-01-28T04:30:24.466+0000] {taskinstance.py:3132} INFO - Exporting env vars: AIRFLOW_CTX_DAG_OWNER='***' AIRFLOW_CTX_DAG_ID='etl_reporte_como_vamos' AIRFLOW_CTX_TASK_ID='task_bot_como_vamos' AIRFLOW_CTX_EXECUTION_DATE='2025-01-28T04:24:08.704438+00:00' AIRFLOW_CTX_TRY_NUMBER='2' AIRFLOW_CTX_DAG_RUN_ID='manual__2025-01-28T04:24:08.704438+00:00'
[2025-01-28T04:30:24.468+0000] {taskinstance.py:731} INFO - ::endgroup::
[2025-01-28T04:30:24.530+0000] {subprocess.py:78} INFO - Tmp dir root location: /tmp
[2025-01-28T04:30:24.534+0000] {subprocess.py:88} INFO - Running command: ['/usr/bin/bash', '-c', 'python /opt/***/scripts/bot_reporte_como_vamos.py']
[2025-01-28T04:30:24.554+0000] {subprocess.py:99} INFO - Output:
[2025-01-28T04:30:29.505+0000] {job.py:229} INFO - Heartbeat recovered after 10.58 seconds
[2025-01-28T04:30:30.193+0000] {subprocess.py:106} INFO - ic| start_date: '01/01/2025', end_date: '28/01/2025'
[2025-01-28T04:30:30.235+0000] {subprocess.py:106} INFO - 2025-01-28 04:30:30,193 - bot_como_vamos - INFO - Starting script bot_como_vamos.py
[2025-01-28T04:32:11.564+0000] {subprocess.py:106} INFO - 2025-01-28 04:32:11,560 - bot_como_vamos - INFO - Click in menu button successfully
[2025-01-28T04:32:22.451+0000] {subprocess.py:106} INFO - 2025-01-28 04:32:22,448 - bot_como_vamos - INFO - Input dates successfully
[2025-01-28T04:32:32.897+0000] {subprocess.py:106} INFO - 2025-01-28 04:32:32,894 - bot_como_vamos - INFO - Click in 'Empresas Y Negocios' successfully
[2025-01-28T04:33:38.288+0000] {job.py:229} INFO - Heartbeat recovered after 14.17 seconds
[2025-01-28T04:33:38.801+0000] {subprocess.py:106} INFO - Starting script bot_como_vamos.py
[2025-01-28T04:33:38.810+0000] {subprocess.py:106} INFO - Traceback (most recent call last):
[2025-01-28T04:33:38.816+0000] {subprocess.py:106} INFO -   File "/opt/***/scripts/bot_reporte_como_vamos.py", line 143, in <module>
[2025-01-28T04:33:38.887+0000] {subprocess.py:106} INFO -     main()
[2025-01-28T04:33:38.890+0000] {subprocess.py:106} INFO -   File "/opt/***/scripts/bot_reporte_como_vamos.py", line 117, in main
[2025-01-28T04:33:38.922+0000] {subprocess.py:106} INFO -     reporte_como_vamos.click()
[2025-01-28T04:33:38.925+0000] {subprocess.py:106} INFO -   File "/home/***/.local/lib/python3.12/site-packages/selenium/webdriver/remote/webelement.py", line 119, in click
[2025-01-28T04:33:38.931+0000] {subprocess.py:106} INFO -     self._execute(Command.CLICK_ELEMENT)
[2025-01-28T04:33:38.936+0000] {subprocess.py:106} INFO -   File "/home/***/.local/lib/python3.12/site-packages/selenium/webdriver/remote/webelement.py", line 570, in _execute
[2025-01-28T04:33:38.994+0000] {subprocess.py:106} INFO -     return self._parent.execute(command, params)
[2025-01-28T04:33:38.999+0000] {subprocess.py:106} INFO -            ^^^^^^^^^^^^^^^^^^^^^^^^^^^^^^^^^^^^^
[2025-01-28T04:33:39.015+0000] {subprocess.py:106} INFO -   File "/home/***/.local/lib/python3.12/site-packages/selenium/webdriver/remote/webdriver.py", line 429, in execute
[2025-01-28T04:33:39.026+0000] {subprocess.py:106} INFO -     self.error_handler.check_response(response)
[2025-01-28T04:33:39.035+0000] {subprocess.py:106} INFO -   File "/home/***/.local/lib/python3.12/site-packages/selenium/webdriver/remote/errorhandler.py", line 232, in check_response
[2025-01-28T04:33:39.038+0000] {subprocess.py:106} INFO -     raise exception_class(message, screen, stacktrace)
[2025-01-28T04:33:39.046+0000] {subprocess.py:106} INFO - selenium.common.exceptions.WebDriverException: Message: unknown error: session deleted because of page crash
[2025-01-28T04:33:39.052+0000] {subprocess.py:106} INFO - from unknown error: cannot determine loading status
[2025-01-28T04:33:39.055+0000] {subprocess.py:106} INFO - from tab crashed
[2025-01-28T04:33:39.058+0000] {subprocess.py:106} INFO -   (Session info: chrome=132.0.6834.110)
[2025-01-28T04:33:39.060+0000] {subprocess.py:106} INFO - Stacktrace:
[2025-01-28T04:33:39.064+0000] {subprocess.py:106} INFO - #0 0x561f2cbb6dca <unknown>
[2025-01-28T04:33:39.070+0000] {subprocess.py:106} INFO - #1 0x561f2c6ad24d <unknown>
[2025-01-28T04:33:39.072+0000] {subprocess.py:106} INFO - #2 0x561f2c696b4e <unknown>
[2025-01-28T04:33:39.074+0000] {subprocess.py:106} INFO - #3 0x561f2c695d4e <unknown>
[2025-01-28T04:33:39.077+0000] {subprocess.py:106} INFO - #4 0x561f2c6956dc <unknown>
[2025-01-28T04:33:39.080+0000] {subprocess.py:106} INFO - #5 0x561f2c6953b9 <unknown>
[2025-01-28T04:33:39.086+0000] {subprocess.py:106} INFO - #6 0x561f2c693346 <unknown>
[2025-01-28T04:33:39.090+0000] {subprocess.py:106} INFO - #7 0x561f2c693b2f <unknown>
[2025-01-28T04:33:39.092+0000] {subprocess.py:106} INFO - #8 0x561f2c6a3447 <unknown>
[2025-01-28T04:33:39.095+0000] {subprocess.py:106} INFO - #9 0x561f2c6ba6b4 <unknown>
[2025-01-28T04:33:39.097+0000] {subprocess.py:106} INFO - #10 0x561f2c6c05ab <unknown>
[2025-01-28T04:33:39.102+0000] {subprocess.py:106} INFO - #11 0x561f2c694237 <unknown>
[2025-01-28T04:33:39.109+0000] {subprocess.py:106} INFO - #12 0x561f2c6ba18d <unknown>
[2025-01-28T04:33:39.113+0000] {subprocess.py:106} INFO - #13 0x561f2c740849 <unknown>
[2025-01-28T04:33:39.119+0000] {subprocess.py:106} INFO - #14 0x561f2c721833 <unknown>
[2025-01-28T04:33:39.122+0000] {subprocess.py:106} INFO - #15 0x561f2c6ee5a0 <unknown>
[2025-01-28T04:33:39.125+0000] {subprocess.py:106} INFO - #16 0x561f2c6efece <unknown>
[2025-01-28T04:33:39.131+0000] {subprocess.py:106} INFO - #17 0x561f2cb80bdb <unknown>
[2025-01-28T04:33:39.135+0000] {subprocess.py:106} INFO - #18 0x561f2cb84b67 <unknown>
[2025-01-28T04:33:39.138+0000] {subprocess.py:106} INFO - #19 0x561f2cb6c3bc <unknown>
[2025-01-28T04:33:39.141+0000] {subprocess.py:106} INFO - #20 0x561f2cb85727 <unknown>
[2025-01-28T04:33:39.144+0000] {subprocess.py:106} INFO - #21 0x561f2cb5074f <unknown>
[2025-01-28T04:33:39.147+0000] {subprocess.py:106} INFO - #22 0x561f2cba5938 <unknown>
[2025-01-28T04:33:39.150+0000] {subprocess.py:106} INFO - #23 0x561f2cba5b00 <unknown>
[2025-01-28T04:33:39.153+0000] {subprocess.py:106} INFO - #24 0x561f2cbb5c46 <unknown>
[2025-01-28T04:33:39.156+0000] {subprocess.py:106} INFO - #25 0x7f254ce9ca94 <unknown>
[2025-01-28T04:33:39.159+0000] {subprocess.py:106} INFO - #26 0x7f254cf29c3c <unknown>
[2025-01-28T04:33:39.161+0000] {subprocess.py:106} INFO - 
[2025-01-28T04:33:39.910+0000] {subprocess.py:110} INFO - Command exited with return code 1
[2025-01-28T04:33:39.957+0000] {taskinstance.py:3311} ERROR - Task failed with exception
Traceback (most recent call last):
  File "/home/airflow/.local/lib/python3.12/site-packages/airflow/models/taskinstance.py", line 767, in _execute_task
    result = _execute_callable(context=context, **execute_callable_kwargs)
             ^^^^^^^^^^^^^^^^^^^^^^^^^^^^^^^^^^^^^^^^^^^^^^^^^^^^^^^^^^^^^
  File "/home/airflow/.local/lib/python3.12/site-packages/airflow/models/taskinstance.py", line 733, in _execute_callable
    return ExecutionCallableRunner(
           ^^^^^^^^^^^^^^^^^^^^^^^^
  File "/home/airflow/.local/lib/python3.12/site-packages/airflow/utils/operator_helpers.py", line 252, in run
    return self.func(*args, **kwargs)
           ^^^^^^^^^^^^^^^^^^^^^^^^^^
  File "/home/airflow/.local/lib/python3.12/site-packages/airflow/models/baseoperator.py", line 422, in wrapper
    return func(self, *args, **kwargs)
           ^^^^^^^^^^^^^^^^^^^^^^^^^^^
  File "/home/airflow/.local/lib/python3.12/site-packages/airflow/operators/bash.py", line 276, in execute
    raise AirflowException(
airflow.exceptions.AirflowException: Bash command failed. The command returned a non-zero exit code 1.
[2025-01-28T04:33:39.983+0000] {taskinstance.py:1225} INFO - Marking task as FAILED. dag_id=etl_reporte_como_vamos, task_id=task_bot_como_vamos, run_id=manual__2025-01-28T04:24:08.704438+00:00, execution_date=20250128T042408, start_date=20250128T043024, end_date=20250128T043339
[2025-01-28T04:33:40.046+0000] {taskinstance.py:340} INFO - ::group::Post task execution logs
[2025-01-28T04:33:40.049+0000] {standard_task_runner.py:124} ERROR - Failed to execute job 22 for task task_bot_como_vamos (Bash command failed. The command returned a non-zero exit code 1.; 467)
Traceback (most recent call last):
  File "/home/airflow/.local/lib/python3.12/site-packages/airflow/task/task_runner/standard_task_runner.py", line 117, in _start_by_fork
    ret = args.func(args, dag=self.dag)
          ^^^^^^^^^^^^^^^^^^^^^^^^^^^^^
  File "/home/airflow/.local/lib/python3.12/site-packages/airflow/cli/cli_config.py", line 49, in command
    return func(*args, **kwargs)
           ^^^^^^^^^^^^^^^^^^^^^
  File "/home/airflow/.local/lib/python3.12/site-packages/airflow/utils/cli.py", line 116, in wrapper
    return f(*args, **kwargs)
           ^^^^^^^^^^^^^^^^^^
  File "/home/airflow/.local/lib/python3.12/site-packages/airflow/cli/commands/task_command.py", line 483, in task_run
    task_return_code = _run_task_by_selected_method(args, _dag, ti)
                       ^^^^^^^^^^^^^^^^^^^^^^^^^^^^^^^^^^^^^^^^^^^^
  File "/home/airflow/.local/lib/python3.12/site-packages/airflow/cli/commands/task_command.py", line 256, in _run_task_by_selected_method
    return _run_raw_task(args, ti)
           ^^^^^^^^^^^^^^^^^^^^^^^
  File "/home/airflow/.local/lib/python3.12/site-packages/airflow/cli/commands/task_command.py", line 341, in _run_raw_task
    return ti._run_raw_task(
           ^^^^^^^^^^^^^^^^^
  File "/home/airflow/.local/lib/python3.12/site-packages/airflow/utils/session.py", line 97, in wrapper
    return func(*args, session=session, **kwargs)
           ^^^^^^^^^^^^^^^^^^^^^^^^^^^^^^^^^^^^^^
  File "/home/airflow/.local/lib/python3.12/site-packages/airflow/models/taskinstance.py", line 3005, in _run_raw_task
    return _run_raw_task(
           ^^^^^^^^^^^^^^
  File "/home/airflow/.local/lib/python3.12/site-packages/airflow/models/taskinstance.py", line 273, in _run_raw_task
    TaskInstance._execute_task_with_callbacks(
  File "/home/airflow/.local/lib/python3.12/site-packages/airflow/models/taskinstance.py", line 3159, in _execute_task_with_callbacks
    result = self._execute_task(context, task_orig)
             ^^^^^^^^^^^^^^^^^^^^^^^^^^^^^^^^^^^^^^
  File "/home/airflow/.local/lib/python3.12/site-packages/airflow/models/taskinstance.py", line 3183, in _execute_task
    return _execute_task(self, context, task_orig)
           ^^^^^^^^^^^^^^^^^^^^^^^^^^^^^^^^^^^^^^^
  File "/home/airflow/.local/lib/python3.12/site-packages/airflow/models/taskinstance.py", line 767, in _execute_task
    result = _execute_callable(context=context, **execute_callable_kwargs)
             ^^^^^^^^^^^^^^^^^^^^^^^^^^^^^^^^^^^^^^^^^^^^^^^^^^^^^^^^^^^^^
  File "/home/airflow/.local/lib/python3.12/site-packages/airflow/models/taskinstance.py", line 733, in _execute_callable
    return ExecutionCallableRunner(
           ^^^^^^^^^^^^^^^^^^^^^^^^
  File "/home/airflow/.local/lib/python3.12/site-packages/airflow/utils/operator_helpers.py", line 252, in run
    return self.func(*args, **kwargs)
           ^^^^^^^^^^^^^^^^^^^^^^^^^^
  File "/home/airflow/.local/lib/python3.12/site-packages/airflow/models/baseoperator.py", line 422, in wrapper
    return func(self, *args, **kwargs)
           ^^^^^^^^^^^^^^^^^^^^^^^^^^^
  File "/home/airflow/.local/lib/python3.12/site-packages/airflow/operators/bash.py", line 276, in execute
    raise AirflowException(
airflow.exceptions.AirflowException: Bash command failed. The command returned a non-zero exit code 1.
[2025-01-28T04:33:40.087+0000] {local_task_job_runner.py:266} INFO - Task exited with return code 1
[2025-01-28T04:33:40.172+0000] {taskinstance.py:3895} INFO - 0 downstream tasks scheduled from follow-on schedule check
[2025-01-28T04:33:40.185+0000] {local_task_job_runner.py:245} INFO - ::endgroup::
