[2025-01-28T03:30:58.803+0000] {local_task_job_runner.py:123} INFO - ::group::Pre task execution logs
[2025-01-28T03:30:58.898+0000] {taskinstance.py:2613} INFO - Dependencies all met for dep_context=non-requeueable deps ti=<TaskInstance: etl_reporte_como_vamos.task_bot_como_vamos manual__2025-01-28T03:30:55.523728+00:00 [queued]>
[2025-01-28T03:30:58.950+0000] {taskinstance.py:2613} INFO - Dependencies all met for dep_context=requeueable deps ti=<TaskInstance: etl_reporte_como_vamos.task_bot_como_vamos manual__2025-01-28T03:30:55.523728+00:00 [queued]>
[2025-01-28T03:30:58.967+0000] {taskinstance.py:2866} INFO - Starting attempt 1 of 2
[2025-01-28T03:30:59.040+0000] {taskinstance.py:2889} INFO - Executing <Task(BashOperator): task_bot_como_vamos> on 2025-01-28 03:30:55.523728+00:00
[2025-01-28T03:30:59.056+0000] {standard_task_runner.py:104} INFO - Running: ['***', 'tasks', 'run', 'etl_reporte_como_vamos', 'task_bot_como_vamos', 'manual__2025-01-28T03:30:55.523728+00:00', '--job-id', '6', '--raw', '--subdir', 'DAGS_FOLDER/etl_como_vamos_dag.py', '--cfg-path', '/tmp/tmp9en6mw6c']
[2025-01-28T03:30:59.062+0000] {standard_task_runner.py:105} INFO - Job 6: Subtask task_bot_como_vamos
[2025-01-28T03:30:59.065+0000] {logging_mixin.py:190} WARNING - /home/***/.local/lib/python3.12/site-packages/***/task/task_runner/standard_task_runner.py:70 DeprecationWarning: This process (pid=1449) is multi-threaded, use of fork() may lead to deadlocks in the child.
[2025-01-28T03:30:59.067+0000] {standard_task_runner.py:72} INFO - Started process 1455 to run task
[2025-01-28T03:30:59.267+0000] {task_command.py:467} INFO - Running <TaskInstance: etl_reporte_como_vamos.task_bot_como_vamos manual__2025-01-28T03:30:55.523728+00:00 [running]> on host 9f50f588cff7
[2025-01-28T03:31:00.491+0000] {taskinstance.py:3132} INFO - Exporting env vars: AIRFLOW_CTX_DAG_OWNER='***' AIRFLOW_CTX_DAG_ID='etl_reporte_como_vamos' AIRFLOW_CTX_TASK_ID='task_bot_como_vamos' AIRFLOW_CTX_EXECUTION_DATE='2025-01-28T03:30:55.523728+00:00' AIRFLOW_CTX_TRY_NUMBER='1' AIRFLOW_CTX_DAG_RUN_ID='manual__2025-01-28T03:30:55.523728+00:00'
[2025-01-28T03:31:00.494+0000] {taskinstance.py:731} INFO - ::endgroup::
[2025-01-28T03:31:00.544+0000] {subprocess.py:78} INFO - Tmp dir root location: /tmp
[2025-01-28T03:31:00.546+0000] {subprocess.py:88} INFO - Running command: ['/usr/bin/bash', '-c', 'python /opt/***/scripts/bot_reporte_como_vamos.py']
[2025-01-28T03:31:00.564+0000] {subprocess.py:99} INFO - Output:
[2025-01-28T03:31:04.397+0000] {subprocess.py:106} INFO - Traceback (most recent call last):
[2025-01-28T03:31:04.399+0000] {subprocess.py:106} INFO -   File "/opt/***/scripts/bot_reporte_como_vamos.py", line 1, in <module>
[2025-01-28T03:31:04.411+0000] {subprocess.py:106} INFO -     import assets.assets as ast
[2025-01-28T03:31:04.413+0000] {subprocess.py:106} INFO -   File "/opt/***/scripts/assets/assets.py", line 15, in <module>
[2025-01-28T03:31:04.426+0000] {subprocess.py:106} INFO -     json_handler = logging.FileHandler("../logs/main.json")
[2025-01-28T03:31:04.428+0000] {subprocess.py:106} INFO -                    ^^^^^^^^^^^^^^^^^^^^^^^^^^^^^^^^^^^^^^^^
[2025-01-28T03:31:04.429+0000] {subprocess.py:106} INFO -   File "/usr/local/lib/python3.12/logging/__init__.py", line 1231, in __init__
[2025-01-28T03:31:04.431+0000] {subprocess.py:106} INFO -     StreamHandler.__init__(self, self._open())
[2025-01-28T03:31:04.432+0000] {subprocess.py:106} INFO -                                  ^^^^^^^^^^^^
[2025-01-28T03:31:04.433+0000] {subprocess.py:106} INFO -   File "/usr/local/lib/python3.12/logging/__init__.py", line 1263, in _open
[2025-01-28T03:31:04.435+0000] {subprocess.py:106} INFO -     return open_func(self.baseFilename, self.mode,
[2025-01-28T03:31:04.437+0000] {subprocess.py:106} INFO -            ^^^^^^^^^^^^^^^^^^^^^^^^^^^^^^^^^^^^^^^
[2025-01-28T03:31:04.438+0000] {subprocess.py:106} INFO - FileNotFoundError: [Errno 2] No such file or directory: '/tmp/logs/main.json'
[2025-01-28T03:31:04.578+0000] {subprocess.py:110} INFO - Command exited with return code 1
[2025-01-28T03:31:04.598+0000] {taskinstance.py:3311} ERROR - Task failed with exception
Traceback (most recent call last):
  File "/home/airflow/.local/lib/python3.12/site-packages/airflow/models/taskinstance.py", line 767, in _execute_task
    result = _execute_callable(context=context, **execute_callable_kwargs)
             ^^^^^^^^^^^^^^^^^^^^^^^^^^^^^^^^^^^^^^^^^^^^^^^^^^^^^^^^^^^^^
  File "/home/airflow/.local/lib/python3.12/site-packages/airflow/models/taskinstance.py", line 733, in _execute_callable
    return ExecutionCallableRunner(
           ^^^^^^^^^^^^^^^^^^^^^^^^
  File "/home/airflow/.local/lib/python3.12/site-packages/airflow/utils/operator_helpers.py", line 252, in run
    return self.func(*args, **kwargs)
           ^^^^^^^^^^^^^^^^^^^^^^^^^^
  File "/home/airflow/.local/lib/python3.12/site-packages/airflow/models/baseoperator.py", line 422, in wrapper
    return func(self, *args, **kwargs)
           ^^^^^^^^^^^^^^^^^^^^^^^^^^^
  File "/home/airflow/.local/lib/python3.12/site-packages/airflow/operators/bash.py", line 276, in execute
    raise AirflowException(
airflow.exceptions.AirflowException: Bash command failed. The command returned a non-zero exit code 1.
[2025-01-28T03:31:04.615+0000] {taskinstance.py:1225} INFO - Marking task as UP_FOR_RETRY. dag_id=etl_reporte_como_vamos, task_id=task_bot_como_vamos, run_id=manual__2025-01-28T03:30:55.523728+00:00, execution_date=20250128T033055, start_date=20250128T033058, end_date=20250128T033104
[2025-01-28T03:31:04.653+0000] {taskinstance.py:340} INFO - ::group::Post task execution logs
[2025-01-28T03:31:04.655+0000] {standard_task_runner.py:124} ERROR - Failed to execute job 6 for task task_bot_como_vamos (Bash command failed. The command returned a non-zero exit code 1.; 1455)
Traceback (most recent call last):
  File "/home/airflow/.local/lib/python3.12/site-packages/airflow/task/task_runner/standard_task_runner.py", line 117, in _start_by_fork
    ret = args.func(args, dag=self.dag)
          ^^^^^^^^^^^^^^^^^^^^^^^^^^^^^
  File "/home/airflow/.local/lib/python3.12/site-packages/airflow/cli/cli_config.py", line 49, in command
    return func(*args, **kwargs)
           ^^^^^^^^^^^^^^^^^^^^^
  File "/home/airflow/.local/lib/python3.12/site-packages/airflow/utils/cli.py", line 116, in wrapper
    return f(*args, **kwargs)
           ^^^^^^^^^^^^^^^^^^
  File "/home/airflow/.local/lib/python3.12/site-packages/airflow/cli/commands/task_command.py", line 483, in task_run
    task_return_code = _run_task_by_selected_method(args, _dag, ti)
                       ^^^^^^^^^^^^^^^^^^^^^^^^^^^^^^^^^^^^^^^^^^^^
  File "/home/airflow/.local/lib/python3.12/site-packages/airflow/cli/commands/task_command.py", line 256, in _run_task_by_selected_method
    return _run_raw_task(args, ti)
           ^^^^^^^^^^^^^^^^^^^^^^^
  File "/home/airflow/.local/lib/python3.12/site-packages/airflow/cli/commands/task_command.py", line 341, in _run_raw_task
    return ti._run_raw_task(
           ^^^^^^^^^^^^^^^^^
  File "/home/airflow/.local/lib/python3.12/site-packages/airflow/utils/session.py", line 97, in wrapper
    return func(*args, session=session, **kwargs)
           ^^^^^^^^^^^^^^^^^^^^^^^^^^^^^^^^^^^^^^
  File "/home/airflow/.local/lib/python3.12/site-packages/airflow/models/taskinstance.py", line 3005, in _run_raw_task
    return _run_raw_task(
           ^^^^^^^^^^^^^^
  File "/home/airflow/.local/lib/python3.12/site-packages/airflow/models/taskinstance.py", line 273, in _run_raw_task
    TaskInstance._execute_task_with_callbacks(
  File "/home/airflow/.local/lib/python3.12/site-packages/airflow/models/taskinstance.py", line 3159, in _execute_task_with_callbacks
    result = self._execute_task(context, task_orig)
             ^^^^^^^^^^^^^^^^^^^^^^^^^^^^^^^^^^^^^^
  File "/home/airflow/.local/lib/python3.12/site-packages/airflow/models/taskinstance.py", line 3183, in _execute_task
    return _execute_task(self, context, task_orig)
           ^^^^^^^^^^^^^^^^^^^^^^^^^^^^^^^^^^^^^^^
  File "/home/airflow/.local/lib/python3.12/site-packages/airflow/models/taskinstance.py", line 767, in _execute_task
    result = _execute_callable(context=context, **execute_callable_kwargs)
             ^^^^^^^^^^^^^^^^^^^^^^^^^^^^^^^^^^^^^^^^^^^^^^^^^^^^^^^^^^^^^
  File "/home/airflow/.local/lib/python3.12/site-packages/airflow/models/taskinstance.py", line 733, in _execute_callable
    return ExecutionCallableRunner(
           ^^^^^^^^^^^^^^^^^^^^^^^^
  File "/home/airflow/.local/lib/python3.12/site-packages/airflow/utils/operator_helpers.py", line 252, in run
    return self.func(*args, **kwargs)
           ^^^^^^^^^^^^^^^^^^^^^^^^^^
  File "/home/airflow/.local/lib/python3.12/site-packages/airflow/models/baseoperator.py", line 422, in wrapper
    return func(self, *args, **kwargs)
           ^^^^^^^^^^^^^^^^^^^^^^^^^^^
  File "/home/airflow/.local/lib/python3.12/site-packages/airflow/operators/bash.py", line 276, in execute
    raise AirflowException(
airflow.exceptions.AirflowException: Bash command failed. The command returned a non-zero exit code 1.
[2025-01-28T03:31:04.695+0000] {local_task_job_runner.py:266} INFO - Task exited with return code 1
[2025-01-28T03:31:04.734+0000] {taskinstance.py:3895} INFO - 0 downstream tasks scheduled from follow-on schedule check
[2025-01-28T03:31:04.738+0000] {local_task_job_runner.py:245} INFO - ::endgroup::
