[2025-01-30T03:19:19.011+0000] {local_task_job_runner.py:123} INFO - ::group::Pre task execution logs
[2025-01-30T03:19:19.042+0000] {taskinstance.py:2613} INFO - Dependencies all met for dep_context=non-requeueable deps ti=<TaskInstance: etl_reporte_como_vamos.task_bot_como_vamos manual__2025-01-30T03:14:24.069760+00:00 [queued]>
[2025-01-30T03:19:19.058+0000] {taskinstance.py:2613} INFO - Dependencies all met for dep_context=requeueable deps ti=<TaskInstance: etl_reporte_como_vamos.task_bot_como_vamos manual__2025-01-30T03:14:24.069760+00:00 [queued]>
[2025-01-30T03:19:19.059+0000] {taskinstance.py:2866} INFO - Starting attempt 3 of 4
[2025-01-30T03:19:19.087+0000] {taskinstance.py:2889} INFO - Executing <Task(BashOperator): task_bot_como_vamos> on 2025-01-30 03:14:24.069760+00:00
[2025-01-30T03:19:19.096+0000] {warnings.py:112} WARNING - /home/***/.local/lib/python3.12/site-packages/***/task/task_runner/standard_task_runner.py:70: DeprecationWarning: This process (pid=2207) is multi-threaded, use of fork() may lead to deadlocks in the child.
  pid = os.fork()

[2025-01-30T03:19:19.098+0000] {standard_task_runner.py:72} INFO - Started process 2208 to run task
[2025-01-30T03:19:19.099+0000] {standard_task_runner.py:104} INFO - Running: ['***', 'tasks', 'run', 'etl_reporte_como_vamos', 'task_bot_como_vamos', 'manual__2025-01-30T03:14:24.069760+00:00', '--job-id', '19', '--raw', '--subdir', 'DAGS_FOLDER/etl_como_vamos_dag.py', '--cfg-path', '/tmp/tmpqpcwwzio']
[2025-01-30T03:19:19.101+0000] {standard_task_runner.py:105} INFO - Job 19: Subtask task_bot_como_vamos
[2025-01-30T03:19:19.179+0000] {task_command.py:467} INFO - Running <TaskInstance: etl_reporte_como_vamos.task_bot_como_vamos manual__2025-01-30T03:14:24.069760+00:00 [running]> on host 438c87da0b60
[2025-01-30T03:19:19.321+0000] {taskinstance.py:3132} INFO - Exporting env vars: AIRFLOW_CTX_DAG_OWNER='***' AIRFLOW_CTX_DAG_ID='etl_reporte_como_vamos' AIRFLOW_CTX_TASK_ID='task_bot_como_vamos' AIRFLOW_CTX_EXECUTION_DATE='2025-01-30T03:14:24.069760+00:00' AIRFLOW_CTX_TRY_NUMBER='3' AIRFLOW_CTX_DAG_RUN_ID='manual__2025-01-30T03:14:24.069760+00:00'
[2025-01-30T03:19:19.323+0000] {taskinstance.py:731} INFO - ::endgroup::
[2025-01-30T03:19:19.346+0000] {subprocess.py:78} INFO - Tmp dir root location: /tmp
[2025-01-30T03:19:19.348+0000] {subprocess.py:88} INFO - Running command: ['/usr/bin/bash', '-c', 'python /opt/***/scripts/bot_reporte_como_vamos.py']
[2025-01-30T03:19:19.363+0000] {subprocess.py:99} INFO - Output:
[2025-01-30T03:19:22.886+0000] {subprocess.py:106} INFO - ic| start_date: '01/01/2025', end_date: '30/01/2025'
[2025-01-30T03:19:22.887+0000] {subprocess.py:106} INFO - 2025-01-30 03:19:22,886 - bot_como_vamos - INFO - Starting script bot_como_vamos.py
[2025-01-30T03:19:22.987+0000] {subprocess.py:106} INFO - 2025-01-30 03:19:22,986 - bot_como_vamos - ERROR - Error al conectar al Selenium Hub: Message: Could not start a new session. Could not start a new session. Error while creating session with the driver service. Stopping driver service: Could not start a new session. Response code 500. Message: session not created
[2025-01-30T03:19:22.988+0000] {subprocess.py:106} INFO - from disconnected: unable to connect to renderer
[2025-01-30T03:19:22.989+0000] {subprocess.py:106} INFO - Host info: host: '7b2429a33d61', ip: '172.18.0.5'
[2025-01-30T03:19:22.990+0000] {subprocess.py:106} INFO - Build info: version: '4.28.1', revision: '73f5ad48a2'
[2025-01-30T03:19:22.991+0000] {subprocess.py:106} INFO - System info: os.name: 'Linux', os.arch: 'amd64', os.version: '5.15.153.1-microsoft-standard-WSL2', java.version: '17.0.13'
[2025-01-30T03:19:22.992+0000] {subprocess.py:106} INFO - Driver info: driver.version: unknown
[2025-01-30T03:19:22.993+0000] {subprocess.py:106} INFO - Build info: version: '4.28.1', revision: '73f5ad48a2'
[2025-01-30T03:19:22.995+0000] {subprocess.py:106} INFO - System info: os.name: 'Linux', os.arch: 'amd64', os.version: '5.15.153.1-microsoft-standard-WSL2', java.version: '17.0.13'
[2025-01-30T03:19:22.996+0000] {subprocess.py:106} INFO - Driver info: driver.version: unknown
[2025-01-30T03:19:22.997+0000] {subprocess.py:106} INFO - Build info: version: '4.28.1', revision: '73f5ad48a2'
[2025-01-30T03:19:22.999+0000] {subprocess.py:106} INFO - System info: os.name: 'Linux', os.arch: 'amd64', os.version: '5.15.153.1-microsoft-standard-WSL2', java.version: '17.0.13'
[2025-01-30T03:19:23.000+0000] {subprocess.py:106} INFO - Driver info: driver.version: unknown
[2025-01-30T03:19:23.001+0000] {subprocess.py:106} INFO - Stacktrace:
[2025-01-30T03:19:23.002+0000] {subprocess.py:106} INFO -     at org.openqa.selenium.grid.node.remote.RemoteNode.newSession (RemoteNode.java:167)
[2025-01-30T03:19:23.003+0000] {subprocess.py:106} INFO -     at org.openqa.selenium.grid.distributor.local.LocalDistributor.startSession (LocalDistributor.java:678)
[2025-01-30T03:19:23.005+0000] {subprocess.py:106} INFO -     at org.openqa.selenium.grid.distributor.local.LocalDistributor.newSession (LocalDistributor.java:597)
[2025-01-30T03:19:23.006+0000] {subprocess.py:106} INFO -     at org.openqa.selenium.grid.distributor.local.LocalDistributor$NewSessionRunnable.handleNewSessionRequest (LocalDistributor.java:861)
[2025-01-30T03:19:23.007+0000] {subprocess.py:106} INFO -     at org.openqa.selenium.grid.distributor.local.LocalDistributor$NewSessionRunnable.lambda$run$1 (LocalDistributor.java:818)
[2025-01-30T03:19:23.008+0000] {subprocess.py:106} INFO -     at java.util.concurrent.ThreadPoolExecutor.runWorker (ThreadPoolExecutor.java:1136)
[2025-01-30T03:19:23.009+0000] {subprocess.py:106} INFO -     at java.util.concurrent.ThreadPoolExecutor$Worker.run (ThreadPoolExecutor.java:635)
[2025-01-30T03:19:23.010+0000] {subprocess.py:106} INFO -     at java.lang.Thread.run (Thread.java:840)
[2025-01-30T03:19:23.012+0000] {subprocess.py:106} INFO - 2025-01-30 03:19:22,990 - bot_como_vamos - ERROR - Execution error bot_reporte_como_vamos.py:
[2025-01-30T03:19:23.013+0000] {subprocess.py:106} INFO -  Error type: SessionNotCreatedException
[2025-01-30T03:19:23.013+0000] {subprocess.py:106} INFO - Error message: Message: Could not start a new session. Could not start a new session. Error while creating session with the driver service. Stopping driver service: Could not start a new session. Response code 500. Message: session not created
[2025-01-30T03:19:23.015+0000] {subprocess.py:106} INFO - from disconnected: unable to connect to renderer
[2025-01-30T03:19:23.016+0000] {subprocess.py:106} INFO - Host info: host: '7b2429a33d61', ip: '172.18.0.5'
[2025-01-30T03:19:23.017+0000] {subprocess.py:106} INFO - Build info: version: '4.28.1', revision: '73f5ad48a2'
[2025-01-30T03:19:23.018+0000] {subprocess.py:106} INFO - System info: os.name: 'Linux', os.arch: 'amd64', os.version: '5.15.153.1-microsoft-standard-WSL2', java.version: '17.0.13'
[2025-01-30T03:19:23.019+0000] {subprocess.py:106} INFO - Driver info: driver.version: unknown
[2025-01-30T03:19:23.020+0000] {subprocess.py:106} INFO - Build info: version: '4.28.1', revision: '73f5ad48a2'
[2025-01-30T03:19:23.022+0000] {subprocess.py:106} INFO - System info: os.name: 'Linux', os.arch: 'amd64', os.version: '5.15.153.1-microsoft-standard-WSL2', java.version: '17.0.13'
[2025-01-30T03:19:23.023+0000] {subprocess.py:106} INFO - Driver info: driver.version: unknown
[2025-01-30T03:19:23.025+0000] {subprocess.py:106} INFO - Build info: version: '4.28.1', revision: '73f5ad48a2'
[2025-01-30T03:19:23.026+0000] {subprocess.py:106} INFO - System info: os.name: 'Linux', os.arch: 'amd64', os.version: '5.15.153.1-microsoft-standard-WSL2', java.version: '17.0.13'
[2025-01-30T03:19:23.027+0000] {subprocess.py:106} INFO - Driver info: driver.version: unknown
[2025-01-30T03:19:23.029+0000] {subprocess.py:106} INFO - Stacktrace:
[2025-01-30T03:19:23.030+0000] {subprocess.py:106} INFO -     at org.openqa.selenium.grid.node.remote.RemoteNode.newSession (RemoteNode.java:167)
[2025-01-30T03:19:23.031+0000] {subprocess.py:106} INFO -     at org.openqa.selenium.grid.distributor.local.LocalDistributor.startSession (LocalDistributor.java:678)
[2025-01-30T03:19:23.033+0000] {subprocess.py:106} INFO -     at org.openqa.selenium.grid.distributor.local.LocalDistributor.newSession (LocalDistributor.java:597)
[2025-01-30T03:19:23.034+0000] {subprocess.py:106} INFO -     at org.openqa.selenium.grid.distributor.local.LocalDistributor$NewSessionRunnable.handleNewSessionRequest (LocalDistributor.java:861)
[2025-01-30T03:19:23.036+0000] {subprocess.py:106} INFO -     at org.openqa.selenium.grid.distributor.local.LocalDistributor$NewSessionRunnable.lambda$run$1 (LocalDistributor.java:818)
[2025-01-30T03:19:23.037+0000] {subprocess.py:106} INFO -     at java.util.concurrent.ThreadPoolExecutor.runWorker (ThreadPoolExecutor.java:1136)
[2025-01-30T03:19:23.039+0000] {subprocess.py:106} INFO -     at java.util.concurrent.ThreadPoolExecutor$Worker.run (ThreadPoolExecutor.java:635)
[2025-01-30T03:19:23.040+0000] {subprocess.py:106} INFO -     at java.lang.Thread.run (Thread.java:840)
[2025-01-30T03:19:23.042+0000] {subprocess.py:106} INFO - Full Traceback: Traceback (most recent call last):
[2025-01-30T03:19:23.043+0000] {subprocess.py:106} INFO -   File "/opt/***/scripts/bot_reporte_como_vamos.py", line 81, in main
[2025-01-30T03:19:23.044+0000] {subprocess.py:106} INFO -     driver = webdriver.Remote(command_executor='http://selenium-hub:4444', options=chrome_options)
[2025-01-30T03:19:23.045+0000] {subprocess.py:106} INFO -              ^^^^^^^^^^^^^^^^^^^^^^^^^^^^^^^^^^^^^^^^^^^^^^^^^^^^^^^^^^^^^^^^^^^^^^^^^^^^^^^^^^^^^
[2025-01-30T03:19:23.047+0000] {subprocess.py:106} INFO -   File "/home/***/.local/lib/python3.12/site-packages/selenium/webdriver/remote/webdriver.py", line 250, in __init__
[2025-01-30T03:19:23.048+0000] {subprocess.py:106} INFO -     self.start_session(capabilities)
[2025-01-30T03:19:23.049+0000] {subprocess.py:106} INFO -   File "/home/***/.local/lib/python3.12/site-packages/selenium/webdriver/remote/webdriver.py", line 342, in start_session
[2025-01-30T03:19:23.050+0000] {subprocess.py:106} INFO -     response = self.execute(Command.NEW_SESSION, caps)["value"]
[2025-01-30T03:19:23.052+0000] {subprocess.py:106} INFO -                ^^^^^^^^^^^^^^^^^^^^^^^^^^^^^^^^^^^^^^^
[2025-01-30T03:19:23.053+0000] {subprocess.py:106} INFO -   File "/home/***/.local/lib/python3.12/site-packages/selenium/webdriver/remote/webdriver.py", line 429, in execute
[2025-01-30T03:19:23.054+0000] {subprocess.py:106} INFO -     self.error_handler.check_response(response)
[2025-01-30T03:19:23.056+0000] {subprocess.py:106} INFO -   File "/home/***/.local/lib/python3.12/site-packages/selenium/webdriver/remote/errorhandler.py", line 232, in check_response
[2025-01-30T03:19:23.057+0000] {subprocess.py:106} INFO -     raise exception_class(message, screen, stacktrace)
[2025-01-30T03:19:23.058+0000] {subprocess.py:106} INFO - selenium.common.exceptions.SessionNotCreatedException: Message: Could not start a new session. Could not start a new session. Error while creating session with the driver service. Stopping driver service: Could not start a new session. Response code 500. Message: session not created
[2025-01-30T03:19:23.060+0000] {subprocess.py:106} INFO - from disconnected: unable to connect to renderer
[2025-01-30T03:19:23.061+0000] {subprocess.py:106} INFO - Host info: host: '7b2429a33d61', ip: '172.18.0.5'
[2025-01-30T03:19:23.062+0000] {subprocess.py:106} INFO - Build info: version: '4.28.1', revision: '73f5ad48a2'
[2025-01-30T03:19:23.063+0000] {subprocess.py:106} INFO - System info: os.name: 'Linux', os.arch: 'amd64', os.version: '5.15.153.1-microsoft-standard-WSL2', java.version: '17.0.13'
[2025-01-30T03:19:23.065+0000] {subprocess.py:106} INFO - Driver info: driver.version: unknown
[2025-01-30T03:19:23.066+0000] {subprocess.py:106} INFO - Build info: version: '4.28.1', revision: '73f5ad48a2'
[2025-01-30T03:19:23.067+0000] {subprocess.py:106} INFO - System info: os.name: 'Linux', os.arch: 'amd64', os.version: '5.15.153.1-microsoft-standard-WSL2', java.version: '17.0.13'
[2025-01-30T03:19:23.068+0000] {subprocess.py:106} INFO - Driver info: driver.version: unknown
[2025-01-30T03:19:23.069+0000] {subprocess.py:106} INFO - Build info: version: '4.28.1', revision: '73f5ad48a2'
[2025-01-30T03:19:23.071+0000] {subprocess.py:106} INFO - System info: os.name: 'Linux', os.arch: 'amd64', os.version: '5.15.153.1-microsoft-standard-WSL2', java.version: '17.0.13'
[2025-01-30T03:19:23.072+0000] {subprocess.py:106} INFO - Driver info: driver.version: unknown
[2025-01-30T03:19:23.073+0000] {subprocess.py:106} INFO - Stacktrace:
[2025-01-30T03:19:23.074+0000] {subprocess.py:106} INFO -     at org.openqa.selenium.grid.node.remote.RemoteNode.newSession (RemoteNode.java:167)
[2025-01-30T03:19:23.076+0000] {subprocess.py:106} INFO -     at org.openqa.selenium.grid.distributor.local.LocalDistributor.startSession (LocalDistributor.java:678)
[2025-01-30T03:19:23.077+0000] {subprocess.py:106} INFO -     at org.openqa.selenium.grid.distributor.local.LocalDistributor.newSession (LocalDistributor.java:597)
[2025-01-30T03:19:23.079+0000] {subprocess.py:106} INFO -     at org.openqa.selenium.grid.distributor.local.LocalDistributor$NewSessionRunnable.handleNewSessionRequest (LocalDistributor.java:861)
[2025-01-30T03:19:23.081+0000] {subprocess.py:106} INFO -     at org.openqa.selenium.grid.distributor.local.LocalDistributor$NewSessionRunnable.lambda$run$1 (LocalDistributor.java:818)
[2025-01-30T03:19:23.082+0000] {subprocess.py:106} INFO -     at java.util.concurrent.ThreadPoolExecutor.runWorker (ThreadPoolExecutor.java:1136)
[2025-01-30T03:19:23.083+0000] {subprocess.py:106} INFO -     at java.util.concurrent.ThreadPoolExecutor$Worker.run (ThreadPoolExecutor.java:635)
[2025-01-30T03:19:23.084+0000] {subprocess.py:106} INFO -     at java.lang.Thread.run (Thread.java:840)
[2025-01-30T03:19:23.085+0000] {subprocess.py:106} INFO - 
[2025-01-30T03:19:23.087+0000] {subprocess.py:106} INFO - Traceback (most recent call last):
[2025-01-30T03:19:23.088+0000] {subprocess.py:106} INFO -   File "/opt/***/scripts/bot_reporte_como_vamos.py", line 173, in <module>
[2025-01-30T03:19:23.089+0000] {subprocess.py:106} INFO -     main()
[2025-01-30T03:19:23.090+0000] {subprocess.py:106} INFO -   File "/opt/***/scripts/bot_reporte_como_vamos.py", line 81, in main
[2025-01-30T03:19:23.091+0000] {subprocess.py:106} INFO -     driver = webdriver.Remote(command_executor='http://selenium-hub:4444', options=chrome_options)
[2025-01-30T03:19:23.092+0000] {subprocess.py:106} INFO -              ^^^^^^^^^^^^^^^^^^^^^^^^^^^^^^^^^^^^^^^^^^^^^^^^^^^^^^^^^^^^^^^^^^^^^^^^^^^^^^^^^^^^^
[2025-01-30T03:19:23.093+0000] {subprocess.py:106} INFO -   File "/home/***/.local/lib/python3.12/site-packages/selenium/webdriver/remote/webdriver.py", line 250, in __init__
[2025-01-30T03:19:23.095+0000] {subprocess.py:106} INFO -     self.start_session(capabilities)
[2025-01-30T03:19:23.096+0000] {subprocess.py:106} INFO -   File "/home/***/.local/lib/python3.12/site-packages/selenium/webdriver/remote/webdriver.py", line 342, in start_session
[2025-01-30T03:19:23.097+0000] {subprocess.py:106} INFO -     response = self.execute(Command.NEW_SESSION, caps)["value"]
[2025-01-30T03:19:23.099+0000] {subprocess.py:106} INFO -                ^^^^^^^^^^^^^^^^^^^^^^^^^^^^^^^^^^^^^^^
[2025-01-30T03:19:23.101+0000] {subprocess.py:106} INFO -   File "/home/***/.local/lib/python3.12/site-packages/selenium/webdriver/remote/webdriver.py", line 429, in execute
[2025-01-30T03:19:23.102+0000] {subprocess.py:106} INFO -     self.error_handler.check_response(response)
[2025-01-30T03:19:23.103+0000] {subprocess.py:106} INFO -   File "/home/***/.local/lib/python3.12/site-packages/selenium/webdriver/remote/errorhandler.py", line 232, in check_response
[2025-01-30T03:19:23.104+0000] {subprocess.py:106} INFO -     raise exception_class(message, screen, stacktrace)
[2025-01-30T03:19:23.106+0000] {subprocess.py:106} INFO - selenium.common.exceptions.SessionNotCreatedException: Message: Could not start a new session. Could not start a new session. Error while creating session with the driver service. Stopping driver service: Could not start a new session. Response code 500. Message: session not created
[2025-01-30T03:19:23.107+0000] {subprocess.py:106} INFO - from disconnected: unable to connect to renderer
[2025-01-30T03:19:23.109+0000] {subprocess.py:106} INFO - Host info: host: '7b2429a33d61', ip: '172.18.0.5'
[2025-01-30T03:19:23.110+0000] {subprocess.py:106} INFO - Build info: version: '4.28.1', revision: '73f5ad48a2'
[2025-01-30T03:19:23.112+0000] {subprocess.py:106} INFO - System info: os.name: 'Linux', os.arch: 'amd64', os.version: '5.15.153.1-microsoft-standard-WSL2', java.version: '17.0.13'
[2025-01-30T03:19:23.113+0000] {subprocess.py:106} INFO - Driver info: driver.version: unknown
[2025-01-30T03:19:23.114+0000] {subprocess.py:106} INFO - Build info: version: '4.28.1', revision: '73f5ad48a2'
[2025-01-30T03:19:23.115+0000] {subprocess.py:106} INFO - System info: os.name: 'Linux', os.arch: 'amd64', os.version: '5.15.153.1-microsoft-standard-WSL2', java.version: '17.0.13'
[2025-01-30T03:19:23.117+0000] {subprocess.py:106} INFO - Driver info: driver.version: unknown
[2025-01-30T03:19:23.118+0000] {subprocess.py:106} INFO - Build info: version: '4.28.1', revision: '73f5ad48a2'
[2025-01-30T03:19:23.119+0000] {subprocess.py:106} INFO - System info: os.name: 'Linux', os.arch: 'amd64', os.version: '5.15.153.1-microsoft-standard-WSL2', java.version: '17.0.13'
[2025-01-30T03:19:23.121+0000] {subprocess.py:106} INFO - Driver info: driver.version: unknown
[2025-01-30T03:19:23.122+0000] {subprocess.py:106} INFO - Stacktrace:
[2025-01-30T03:19:23.123+0000] {subprocess.py:106} INFO -     at org.openqa.selenium.grid.node.remote.RemoteNode.newSession (RemoteNode.java:167)
[2025-01-30T03:19:23.125+0000] {subprocess.py:106} INFO -     at org.openqa.selenium.grid.distributor.local.LocalDistributor.startSession (LocalDistributor.java:678)
[2025-01-30T03:19:23.126+0000] {subprocess.py:106} INFO -     at org.openqa.selenium.grid.distributor.local.LocalDistributor.newSession (LocalDistributor.java:597)
[2025-01-30T03:19:23.127+0000] {subprocess.py:106} INFO -     at org.openqa.selenium.grid.distributor.local.LocalDistributor$NewSessionRunnable.handleNewSessionRequest (LocalDistributor.java:861)
[2025-01-30T03:19:23.128+0000] {subprocess.py:106} INFO -     at org.openqa.selenium.grid.distributor.local.LocalDistributor$NewSessionRunnable.lambda$run$1 (LocalDistributor.java:818)
[2025-01-30T03:19:23.130+0000] {subprocess.py:106} INFO -     at java.util.concurrent.ThreadPoolExecutor.runWorker (ThreadPoolExecutor.java:1136)
[2025-01-30T03:19:23.131+0000] {subprocess.py:106} INFO -     at java.util.concurrent.ThreadPoolExecutor$Worker.run (ThreadPoolExecutor.java:635)
[2025-01-30T03:19:23.132+0000] {subprocess.py:106} INFO -     at java.lang.Thread.run (Thread.java:840)
[2025-01-30T03:19:23.192+0000] {subprocess.py:110} INFO - Command exited with return code 1
[2025-01-30T03:19:23.211+0000] {taskinstance.py:3311} ERROR - Task failed with exception
Traceback (most recent call last):
  File "/home/airflow/.local/lib/python3.12/site-packages/airflow/models/taskinstance.py", line 767, in _execute_task
    result = _execute_callable(context=context, **execute_callable_kwargs)
             ^^^^^^^^^^^^^^^^^^^^^^^^^^^^^^^^^^^^^^^^^^^^^^^^^^^^^^^^^^^^^
  File "/home/airflow/.local/lib/python3.12/site-packages/airflow/models/taskinstance.py", line 733, in _execute_callable
    return ExecutionCallableRunner(
           ^^^^^^^^^^^^^^^^^^^^^^^^
  File "/home/airflow/.local/lib/python3.12/site-packages/airflow/utils/operator_helpers.py", line 252, in run
    return self.func(*args, **kwargs)
           ^^^^^^^^^^^^^^^^^^^^^^^^^^
  File "/home/airflow/.local/lib/python3.12/site-packages/airflow/models/baseoperator.py", line 422, in wrapper
    return func(self, *args, **kwargs)
           ^^^^^^^^^^^^^^^^^^^^^^^^^^^
  File "/home/airflow/.local/lib/python3.12/site-packages/airflow/operators/bash.py", line 276, in execute
    raise AirflowException(
airflow.exceptions.AirflowException: Bash command failed. The command returned a non-zero exit code 1.
[2025-01-30T03:19:23.225+0000] {taskinstance.py:1225} INFO - Marking task as UP_FOR_RETRY. dag_id=etl_reporte_como_vamos, task_id=task_bot_como_vamos, run_id=manual__2025-01-30T03:14:24.069760+00:00, execution_date=20250130T031424, start_date=20250130T031919, end_date=20250130T031923
[2025-01-30T03:19:23.254+0000] {taskinstance.py:340} INFO - ::group::Post task execution logs
[2025-01-30T03:19:23.255+0000] {standard_task_runner.py:124} ERROR - Failed to execute job 19 for task task_bot_como_vamos (Bash command failed. The command returned a non-zero exit code 1.; 2208)
Traceback (most recent call last):
  File "/home/airflow/.local/lib/python3.12/site-packages/airflow/task/task_runner/standard_task_runner.py", line 117, in _start_by_fork
    ret = args.func(args, dag=self.dag)
          ^^^^^^^^^^^^^^^^^^^^^^^^^^^^^
  File "/home/airflow/.local/lib/python3.12/site-packages/airflow/cli/cli_config.py", line 49, in command
    return func(*args, **kwargs)
           ^^^^^^^^^^^^^^^^^^^^^
  File "/home/airflow/.local/lib/python3.12/site-packages/airflow/utils/cli.py", line 116, in wrapper
    return f(*args, **kwargs)
           ^^^^^^^^^^^^^^^^^^
  File "/home/airflow/.local/lib/python3.12/site-packages/airflow/cli/commands/task_command.py", line 483, in task_run
    task_return_code = _run_task_by_selected_method(args, _dag, ti)
                       ^^^^^^^^^^^^^^^^^^^^^^^^^^^^^^^^^^^^^^^^^^^^
  File "/home/airflow/.local/lib/python3.12/site-packages/airflow/cli/commands/task_command.py", line 256, in _run_task_by_selected_method
    return _run_raw_task(args, ti)
           ^^^^^^^^^^^^^^^^^^^^^^^
  File "/home/airflow/.local/lib/python3.12/site-packages/airflow/cli/commands/task_command.py", line 341, in _run_raw_task
    return ti._run_raw_task(
           ^^^^^^^^^^^^^^^^^
  File "/home/airflow/.local/lib/python3.12/site-packages/airflow/utils/session.py", line 97, in wrapper
    return func(*args, session=session, **kwargs)
           ^^^^^^^^^^^^^^^^^^^^^^^^^^^^^^^^^^^^^^
  File "/home/airflow/.local/lib/python3.12/site-packages/airflow/models/taskinstance.py", line 3005, in _run_raw_task
    return _run_raw_task(
           ^^^^^^^^^^^^^^
  File "/home/airflow/.local/lib/python3.12/site-packages/airflow/models/taskinstance.py", line 273, in _run_raw_task
    TaskInstance._execute_task_with_callbacks(
  File "/home/airflow/.local/lib/python3.12/site-packages/airflow/models/taskinstance.py", line 3159, in _execute_task_with_callbacks
    result = self._execute_task(context, task_orig)
             ^^^^^^^^^^^^^^^^^^^^^^^^^^^^^^^^^^^^^^
  File "/home/airflow/.local/lib/python3.12/site-packages/airflow/models/taskinstance.py", line 3183, in _execute_task
    return _execute_task(self, context, task_orig)
           ^^^^^^^^^^^^^^^^^^^^^^^^^^^^^^^^^^^^^^^
  File "/home/airflow/.local/lib/python3.12/site-packages/airflow/models/taskinstance.py", line 767, in _execute_task
    result = _execute_callable(context=context, **execute_callable_kwargs)
             ^^^^^^^^^^^^^^^^^^^^^^^^^^^^^^^^^^^^^^^^^^^^^^^^^^^^^^^^^^^^^
  File "/home/airflow/.local/lib/python3.12/site-packages/airflow/models/taskinstance.py", line 733, in _execute_callable
    return ExecutionCallableRunner(
           ^^^^^^^^^^^^^^^^^^^^^^^^
  File "/home/airflow/.local/lib/python3.12/site-packages/airflow/utils/operator_helpers.py", line 252, in run
    return self.func(*args, **kwargs)
           ^^^^^^^^^^^^^^^^^^^^^^^^^^
  File "/home/airflow/.local/lib/python3.12/site-packages/airflow/models/baseoperator.py", line 422, in wrapper
    return func(self, *args, **kwargs)
           ^^^^^^^^^^^^^^^^^^^^^^^^^^^
  File "/home/airflow/.local/lib/python3.12/site-packages/airflow/operators/bash.py", line 276, in execute
    raise AirflowException(
airflow.exceptions.AirflowException: Bash command failed. The command returned a non-zero exit code 1.
[2025-01-30T03:19:23.303+0000] {local_task_job_runner.py:266} INFO - Task exited with return code 1
[2025-01-30T03:19:23.319+0000] {local_task_job_runner.py:245} INFO - ::endgroup::
