[2025-01-28T04:14:27.536+0000] {local_task_job_runner.py:123} INFO - ::group::Pre task execution logs
[2025-01-28T04:14:31.542+0000] {taskinstance.py:2613} INFO - Dependencies all met for dep_context=non-requeueable deps ti=<TaskInstance: etl_reporte_como_vamos.task_bot_como_vamos manual__2025-01-28T04:07:32.142210+00:00 [queued]>
[2025-01-28T04:14:31.556+0000] {taskinstance.py:2613} INFO - Dependencies all met for dep_context=requeueable deps ti=<TaskInstance: etl_reporte_como_vamos.task_bot_como_vamos manual__2025-01-28T04:07:32.142210+00:00 [queued]>
[2025-01-28T04:14:31.558+0000] {taskinstance.py:2866} INFO - Starting attempt 2 of 2
[2025-01-28T04:14:31.585+0000] {taskinstance.py:2889} INFO - Executing <Task(BashOperator): task_bot_como_vamos> on 2025-01-28 04:07:32.142210+00:00
[2025-01-28T04:14:31.597+0000] {standard_task_runner.py:104} INFO - Running: ['***', 'tasks', 'run', 'etl_reporte_como_vamos', 'task_bot_como_vamos', 'manual__2025-01-28T04:07:32.142210+00:00', '--job-id', '18', '--raw', '--subdir', 'DAGS_FOLDER/etl_como_vamos_dag.py', '--cfg-path', '/tmp/tmph4vmhgi9']
[2025-01-28T04:14:31.600+0000] {standard_task_runner.py:105} INFO - Job 18: Subtask task_bot_como_vamos
[2025-01-28T04:14:31.601+0000] {logging_mixin.py:190} WARNING - /home/***/.local/lib/python3.12/site-packages/***/task/task_runner/standard_task_runner.py:70 DeprecationWarning: This process (pid=551) is multi-threaded, use of fork() may lead to deadlocks in the child.
[2025-01-28T04:14:31.604+0000] {standard_task_runner.py:72} INFO - Started process 561 to run task
[2025-01-28T04:14:31.693+0000] {task_command.py:467} INFO - Running <TaskInstance: etl_reporte_como_vamos.task_bot_como_vamos manual__2025-01-28T04:07:32.142210+00:00 [running]> on host 9f50f588cff7
[2025-01-28T04:14:31.828+0000] {taskinstance.py:3132} INFO - Exporting env vars: AIRFLOW_CTX_DAG_OWNER='***' AIRFLOW_CTX_DAG_ID='etl_reporte_como_vamos' AIRFLOW_CTX_TASK_ID='task_bot_como_vamos' AIRFLOW_CTX_EXECUTION_DATE='2025-01-28T04:07:32.142210+00:00' AIRFLOW_CTX_TRY_NUMBER='2' AIRFLOW_CTX_DAG_RUN_ID='manual__2025-01-28T04:07:32.142210+00:00'
[2025-01-28T04:14:31.830+0000] {taskinstance.py:731} INFO - ::endgroup::
[2025-01-28T04:14:31.891+0000] {subprocess.py:78} INFO - Tmp dir root location: /tmp
[2025-01-28T04:14:31.893+0000] {subprocess.py:88} INFO - Running command: ['/usr/bin/bash', '-c', 'python /opt/***/scripts/bot_reporte_como_vamos.py']
[2025-01-28T04:14:31.907+0000] {subprocess.py:99} INFO - Output:
[2025-01-28T04:14:35.238+0000] {subprocess.py:106} INFO - ic| start_date: '01/01/2025', end_date: '28/01/2025'
[2025-01-28T04:14:35.241+0000] {subprocess.py:106} INFO - 2025-01-28 04:14:35,238 - bot_como_vamos - INFO - Starting script bot_como_vamos.py
[2025-01-28T04:14:36.884+0000] {job.py:229} INFO - Heartbeat recovered after 69.50 seconds
[2025-01-28T04:19:25.098+0000] {job.py:229} INFO - Heartbeat recovered after 93.63 seconds
[2025-01-28T04:19:27.548+0000] {subprocess.py:106} INFO - Starting script bot_como_vamos.py
[2025-01-28T04:19:27.587+0000] {subprocess.py:106} INFO - Traceback (most recent call last):
[2025-01-28T04:19:27.597+0000] {subprocess.py:106} INFO -   File "/opt/***/scripts/bot_reporte_como_vamos.py", line 143, in <module>
[2025-01-28T04:19:27.654+0000] {subprocess.py:106} INFO -     main()
[2025-01-28T04:19:27.657+0000] {subprocess.py:106} INFO -   File "/opt/***/scripts/bot_reporte_como_vamos.py", line 85, in main
[2025-01-28T04:19:27.678+0000] {subprocess.py:106} INFO -     # login_success = wait.until(EC.presence_of_element_located((By.ID, "user-name")))
[2025-01-28T04:19:27.703+0000] {subprocess.py:106} INFO -                     ^^^^^^^^^^^^^^^^^^^^^^^^^^^^^^^^^^^^^^^^^^^^^^^^^^^^^^^^^^^^^^^^
[2025-01-28T04:19:27.705+0000] {subprocess.py:106} INFO -   File "/home/***/.local/lib/python3.12/site-packages/selenium/webdriver/support/wait.py", line 137, in until
[2025-01-28T04:19:27.708+0000] {subprocess.py:106} INFO -     value = method(self._driver)
[2025-01-28T04:19:27.710+0000] {subprocess.py:106} INFO -             ^^^^^^^^^^^^^^^^^^^^
[2025-01-28T04:19:27.713+0000] {subprocess.py:106} INFO -   File "/home/***/.local/lib/python3.12/site-packages/selenium/webdriver/support/expected_conditions.py", line 110, in _predicate
[2025-01-28T04:19:27.716+0000] {subprocess.py:106} INFO -     return driver.find_element(*locator)
[2025-01-28T04:19:27.718+0000] {subprocess.py:106} INFO -            ^^^^^^^^^^^^^^^^^^^^^^^^^^^^^
[2025-01-28T04:19:27.719+0000] {subprocess.py:106} INFO -   File "/home/***/.local/lib/python3.12/site-packages/selenium/webdriver/remote/webdriver.py", line 888, in find_element
[2025-01-28T04:19:27.721+0000] {subprocess.py:106} INFO -     return self.execute(Command.FIND_ELEMENT, {"using": by, "value": value})["value"]
[2025-01-28T04:19:27.723+0000] {subprocess.py:106} INFO -            ^^^^^^^^^^^^^^^^^^^^^^^^^^^^^^^^^^^^^^^^^^^^^^^^^^^^^^^^^^^^^^^^^
[2025-01-28T04:19:27.724+0000] {subprocess.py:106} INFO -   File "/home/***/.local/lib/python3.12/site-packages/selenium/webdriver/remote/webdriver.py", line 429, in execute
[2025-01-28T04:19:27.726+0000] {subprocess.py:106} INFO -     self.error_handler.check_response(response)
[2025-01-28T04:19:27.728+0000] {subprocess.py:106} INFO -   File "/home/***/.local/lib/python3.12/site-packages/selenium/webdriver/remote/errorhandler.py", line 232, in check_response
[2025-01-28T04:19:27.729+0000] {subprocess.py:106} INFO -     raise exception_class(message, screen, stacktrace)
[2025-01-28T04:19:27.731+0000] {subprocess.py:106} INFO - selenium.common.exceptions.WebDriverException: Message: unknown error: session deleted because of page crash
[2025-01-28T04:19:27.732+0000] {subprocess.py:106} INFO - from unknown error: cannot determine loading status
[2025-01-28T04:19:27.736+0000] {subprocess.py:106} INFO - from tab crashed
[2025-01-28T04:19:27.738+0000] {subprocess.py:106} INFO -   (Session info: chrome=132.0.6834.110)
[2025-01-28T04:19:27.739+0000] {subprocess.py:106} INFO - Stacktrace:
[2025-01-28T04:19:27.741+0000] {subprocess.py:106} INFO - #0 0x559ad1c0ddca <unknown>
[2025-01-28T04:19:27.743+0000] {subprocess.py:106} INFO - #1 0x559ad170424d <unknown>
[2025-01-28T04:19:27.744+0000] {subprocess.py:106} INFO - #2 0x559ad16edb4e <unknown>
[2025-01-28T04:19:27.746+0000] {subprocess.py:106} INFO - #3 0x559ad16ecd4e <unknown>
[2025-01-28T04:19:27.747+0000] {subprocess.py:106} INFO - #4 0x559ad16ec6dc <unknown>
[2025-01-28T04:19:27.749+0000] {subprocess.py:106} INFO - #5 0x559ad16ec3b9 <unknown>
[2025-01-28T04:19:27.750+0000] {subprocess.py:106} INFO - #6 0x559ad16ea346 <unknown>
[2025-01-28T04:19:27.752+0000] {subprocess.py:106} INFO - #7 0x559ad16eab2f <unknown>
[2025-01-28T04:19:27.754+0000] {subprocess.py:106} INFO - #8 0x559ad16fa447 <unknown>
[2025-01-28T04:19:27.756+0000] {subprocess.py:106} INFO - #9 0x559ad17116b4 <unknown>
[2025-01-28T04:19:27.758+0000] {subprocess.py:106} INFO - #10 0x559ad17175ab <unknown>
[2025-01-28T04:19:27.761+0000] {subprocess.py:106} INFO - #11 0x559ad16eb237 <unknown>
[2025-01-28T04:19:27.764+0000] {subprocess.py:106} INFO - #12 0x559ad171118d <unknown>
[2025-01-28T04:19:27.766+0000] {subprocess.py:106} INFO - #13 0x559ad1797382 <unknown>
[2025-01-28T04:19:27.767+0000] {subprocess.py:106} INFO - #14 0x559ad1778833 <unknown>
[2025-01-28T04:19:27.769+0000] {subprocess.py:106} INFO - #15 0x559ad17455a0 <unknown>
[2025-01-28T04:19:27.771+0000] {subprocess.py:106} INFO - #16 0x559ad1746ece <unknown>
[2025-01-28T04:19:27.773+0000] {subprocess.py:106} INFO - #17 0x559ad1bd7bdb <unknown>
[2025-01-28T04:19:27.776+0000] {subprocess.py:106} INFO - #18 0x559ad1bdbb67 <unknown>
[2025-01-28T04:19:27.778+0000] {subprocess.py:106} INFO - #19 0x559ad1bc33bc <unknown>
[2025-01-28T04:19:27.780+0000] {subprocess.py:106} INFO - #20 0x559ad1bdc727 <unknown>
[2025-01-28T04:19:27.782+0000] {subprocess.py:106} INFO - #21 0x559ad1ba774f <unknown>
[2025-01-28T04:19:27.784+0000] {subprocess.py:106} INFO - #22 0x559ad1bfc938 <unknown>
[2025-01-28T04:19:27.786+0000] {subprocess.py:106} INFO - #23 0x559ad1bfcb00 <unknown>
[2025-01-28T04:19:27.788+0000] {subprocess.py:106} INFO - #24 0x559ad1c0cc46 <unknown>
[2025-01-28T04:19:27.791+0000] {subprocess.py:106} INFO - #25 0x7f0c2049ca94 <unknown>
[2025-01-28T04:19:27.795+0000] {subprocess.py:106} INFO - #26 0x7f0c20529c3c <unknown>
[2025-01-28T04:19:27.796+0000] {subprocess.py:106} INFO - 
[2025-01-28T04:19:28.099+0000] {subprocess.py:110} INFO - Command exited with return code 1
[2025-01-28T04:19:28.281+0000] {taskinstance.py:3311} ERROR - Task failed with exception
Traceback (most recent call last):
  File "/home/airflow/.local/lib/python3.12/site-packages/airflow/models/taskinstance.py", line 767, in _execute_task
    result = _execute_callable(context=context, **execute_callable_kwargs)
             ^^^^^^^^^^^^^^^^^^^^^^^^^^^^^^^^^^^^^^^^^^^^^^^^^^^^^^^^^^^^^
  File "/home/airflow/.local/lib/python3.12/site-packages/airflow/models/taskinstance.py", line 733, in _execute_callable
    return ExecutionCallableRunner(
           ^^^^^^^^^^^^^^^^^^^^^^^^
  File "/home/airflow/.local/lib/python3.12/site-packages/airflow/utils/operator_helpers.py", line 252, in run
    return self.func(*args, **kwargs)
           ^^^^^^^^^^^^^^^^^^^^^^^^^^
  File "/home/airflow/.local/lib/python3.12/site-packages/airflow/models/baseoperator.py", line 422, in wrapper
    return func(self, *args, **kwargs)
           ^^^^^^^^^^^^^^^^^^^^^^^^^^^
  File "/home/airflow/.local/lib/python3.12/site-packages/airflow/operators/bash.py", line 276, in execute
    raise AirflowException(
airflow.exceptions.AirflowException: Bash command failed. The command returned a non-zero exit code 1.
[2025-01-28T04:19:28.460+0000] {taskinstance.py:1225} INFO - Marking task as FAILED. dag_id=etl_reporte_como_vamos, task_id=task_bot_como_vamos, run_id=manual__2025-01-28T04:07:32.142210+00:00, execution_date=20250128T040732, start_date=20250128T041431, end_date=20250128T041928
[2025-01-28T04:19:28.515+0000] {taskinstance.py:340} INFO - ::group::Post task execution logs
[2025-01-28T04:19:28.518+0000] {standard_task_runner.py:124} ERROR - Failed to execute job 18 for task task_bot_como_vamos (Bash command failed. The command returned a non-zero exit code 1.; 561)
Traceback (most recent call last):
  File "/home/airflow/.local/lib/python3.12/site-packages/airflow/task/task_runner/standard_task_runner.py", line 117, in _start_by_fork
    ret = args.func(args, dag=self.dag)
          ^^^^^^^^^^^^^^^^^^^^^^^^^^^^^
  File "/home/airflow/.local/lib/python3.12/site-packages/airflow/cli/cli_config.py", line 49, in command
    return func(*args, **kwargs)
           ^^^^^^^^^^^^^^^^^^^^^
  File "/home/airflow/.local/lib/python3.12/site-packages/airflow/utils/cli.py", line 116, in wrapper
    return f(*args, **kwargs)
           ^^^^^^^^^^^^^^^^^^
  File "/home/airflow/.local/lib/python3.12/site-packages/airflow/cli/commands/task_command.py", line 483, in task_run
    task_return_code = _run_task_by_selected_method(args, _dag, ti)
                       ^^^^^^^^^^^^^^^^^^^^^^^^^^^^^^^^^^^^^^^^^^^^
  File "/home/airflow/.local/lib/python3.12/site-packages/airflow/cli/commands/task_command.py", line 256, in _run_task_by_selected_method
    return _run_raw_task(args, ti)
           ^^^^^^^^^^^^^^^^^^^^^^^
  File "/home/airflow/.local/lib/python3.12/site-packages/airflow/cli/commands/task_command.py", line 341, in _run_raw_task
    return ti._run_raw_task(
           ^^^^^^^^^^^^^^^^^
  File "/home/airflow/.local/lib/python3.12/site-packages/airflow/utils/session.py", line 97, in wrapper
    return func(*args, session=session, **kwargs)
           ^^^^^^^^^^^^^^^^^^^^^^^^^^^^^^^^^^^^^^
  File "/home/airflow/.local/lib/python3.12/site-packages/airflow/models/taskinstance.py", line 3005, in _run_raw_task
    return _run_raw_task(
           ^^^^^^^^^^^^^^
  File "/home/airflow/.local/lib/python3.12/site-packages/airflow/models/taskinstance.py", line 273, in _run_raw_task
    TaskInstance._execute_task_with_callbacks(
  File "/home/airflow/.local/lib/python3.12/site-packages/airflow/models/taskinstance.py", line 3159, in _execute_task_with_callbacks
    result = self._execute_task(context, task_orig)
             ^^^^^^^^^^^^^^^^^^^^^^^^^^^^^^^^^^^^^^
  File "/home/airflow/.local/lib/python3.12/site-packages/airflow/models/taskinstance.py", line 3183, in _execute_task
    return _execute_task(self, context, task_orig)
           ^^^^^^^^^^^^^^^^^^^^^^^^^^^^^^^^^^^^^^^
  File "/home/airflow/.local/lib/python3.12/site-packages/airflow/models/taskinstance.py", line 767, in _execute_task
    result = _execute_callable(context=context, **execute_callable_kwargs)
             ^^^^^^^^^^^^^^^^^^^^^^^^^^^^^^^^^^^^^^^^^^^^^^^^^^^^^^^^^^^^^
  File "/home/airflow/.local/lib/python3.12/site-packages/airflow/models/taskinstance.py", line 733, in _execute_callable
    return ExecutionCallableRunner(
           ^^^^^^^^^^^^^^^^^^^^^^^^
  File "/home/airflow/.local/lib/python3.12/site-packages/airflow/utils/operator_helpers.py", line 252, in run
    return self.func(*args, **kwargs)
           ^^^^^^^^^^^^^^^^^^^^^^^^^^
  File "/home/airflow/.local/lib/python3.12/site-packages/airflow/models/baseoperator.py", line 422, in wrapper
    return func(self, *args, **kwargs)
           ^^^^^^^^^^^^^^^^^^^^^^^^^^^
  File "/home/airflow/.local/lib/python3.12/site-packages/airflow/operators/bash.py", line 276, in execute
    raise AirflowException(
airflow.exceptions.AirflowException: Bash command failed. The command returned a non-zero exit code 1.
[2025-01-28T04:19:28.568+0000] {local_task_job_runner.py:266} INFO - Task exited with return code 1
[2025-01-28T04:19:28.614+0000] {taskinstance.py:3895} INFO - 0 downstream tasks scheduled from follow-on schedule check
[2025-01-28T04:19:28.626+0000] {local_task_job_runner.py:245} INFO - ::endgroup::
