[2025-01-28T01:10:21.124+0000] {local_task_job_runner.py:123} INFO - ::group::Pre task execution logs
[2025-01-28T01:10:21.171+0000] {taskinstance.py:2613} INFO - Dependencies all met for dep_context=non-requeueable deps ti=<TaskInstance: etl_reporte_como_vamos.execute_bot_como_vamos manual__2025-01-28T01:10:18.953635+00:00 [queued]>
[2025-01-28T01:10:21.191+0000] {taskinstance.py:2613} INFO - Dependencies all met for dep_context=requeueable deps ti=<TaskInstance: etl_reporte_como_vamos.execute_bot_como_vamos manual__2025-01-28T01:10:18.953635+00:00 [queued]>
[2025-01-28T01:10:21.193+0000] {taskinstance.py:2866} INFO - Starting attempt 1 of 2
[2025-01-28T01:10:21.223+0000] {taskinstance.py:2889} INFO - Executing <Task(PythonOperator): execute_bot_como_vamos> on 2025-01-28 01:10:18.953635+00:00
[2025-01-28T01:10:21.236+0000] {standard_task_runner.py:104} INFO - Running: ['***', 'tasks', 'run', 'etl_reporte_como_vamos', 'execute_bot_como_vamos', 'manual__2025-01-28T01:10:18.953635+00:00', '--job-id', '27', '--raw', '--subdir', 'DAGS_FOLDER/etl_como_vamos_dag.py', '--cfg-path', '/tmp/tmpopmkig8h']
[2025-01-28T01:10:21.241+0000] {standard_task_runner.py:105} INFO - Job 27: Subtask execute_bot_como_vamos
[2025-01-28T01:10:21.245+0000] {logging_mixin.py:190} WARNING - /home/***/.local/lib/python3.12/site-packages/***/task/task_runner/standard_task_runner.py:70 DeprecationWarning: This process (pid=347) is multi-threaded, use of fork() may lead to deadlocks in the child.
[2025-01-28T01:10:21.247+0000] {standard_task_runner.py:72} INFO - Started process 348 to run task
[2025-01-28T01:10:21.479+0000] {task_command.py:467} INFO - Running <TaskInstance: etl_reporte_como_vamos.execute_bot_como_vamos manual__2025-01-28T01:10:18.953635+00:00 [running]> on host d847f7cae963
[2025-01-28T01:10:22.128+0000] {taskinstance.py:3132} INFO - Exporting env vars: AIRFLOW_CTX_DAG_OWNER='***' AIRFLOW_CTX_DAG_ID='etl_reporte_como_vamos' AIRFLOW_CTX_TASK_ID='execute_bot_como_vamos' AIRFLOW_CTX_EXECUTION_DATE='2025-01-28T01:10:18.953635+00:00' AIRFLOW_CTX_TRY_NUMBER='1' AIRFLOW_CTX_DAG_RUN_ID='manual__2025-01-28T01:10:18.953635+00:00'
[2025-01-28T01:10:22.132+0000] {taskinstance.py:731} INFO - ::endgroup::
[2025-01-28T01:10:26.061+0000] {logging_mixin.py:190} INFO - 

Script failed:
Traceback (most recent call last):
  File "/usr/local/lib/python3.12/logging/config.py", line 608, in configure
    handler = self.configure_handler(handlers[name])
              ^^^^^^^^^^^^^^^^^^^^^^^^^^^^^^^^^^^^^^
  File "/usr/local/lib/python3.12/logging/config.py", line 876, in configure_handler
    result = factory(**kwargs)
             ^^^^^^^^^^^^^^^^^
  File "/usr/local/lib/python3.12/logging/handlers.py", line 155, in __init__
    BaseRotatingHandler.__init__(self, filename, mode, encoding=encoding,
  File "/usr/local/lib/python3.12/logging/handlers.py", line 58, in __init__
    logging.FileHandler.__init__(self, filename, mode=mode,
  File "/usr/local/lib/python3.12/logging/__init__.py", line 1231, in __init__
    StreamHandler.__init__(self, self._open())
                                 ^^^^^^^^^^^^
  File "/usr/local/lib/python3.12/logging/__init__.py", line 1263, in _open
    return open_func(self.baseFilename, self.mode,
           ^^^^^^^^^^^^^^^^^^^^^^^^^^^^^^^^^^^^^^^
FileNotFoundError: [Errno 2] No such file or directory: '/opt/logs/scripts_logs/main.json'

The above exception was the direct cause of the following exception:

Traceback (most recent call last):
  File "/opt/***/scripts/bot_reporte_como_vamos.py", line 1, in <module>
    import assets.assets as ast
  File "/opt/***/scripts/assets/assets.py", line 9, in <module>
    from logging_config import logging
  File "/opt/***/scripts/logging_config.py", line 42, in <module>
    logging.config.dictConfig(LOGGING_CONFIG)
  File "/usr/local/lib/python3.12/logging/config.py", line 942, in dictConfig
    dictConfigClass(config).configure()
  File "/usr/local/lib/python3.12/logging/config.py", line 615, in configure
    raise ValueError('Unable to configure handler '
ValueError: Unable to configure handler 'file_main'
[2025-01-28T01:10:26.066+0000] {taskinstance.py:3311} ERROR - Task failed with exception
Traceback (most recent call last):
  File "/home/airflow/.local/lib/python3.12/site-packages/airflow/models/taskinstance.py", line 767, in _execute_task
    result = _execute_callable(context=context, **execute_callable_kwargs)
             ^^^^^^^^^^^^^^^^^^^^^^^^^^^^^^^^^^^^^^^^^^^^^^^^^^^^^^^^^^^^^
  File "/home/airflow/.local/lib/python3.12/site-packages/airflow/models/taskinstance.py", line 733, in _execute_callable
    return ExecutionCallableRunner(
           ^^^^^^^^^^^^^^^^^^^^^^^^
  File "/home/airflow/.local/lib/python3.12/site-packages/airflow/utils/operator_helpers.py", line 252, in run
    return self.func(*args, **kwargs)
           ^^^^^^^^^^^^^^^^^^^^^^^^^^
  File "/home/airflow/.local/lib/python3.12/site-packages/airflow/models/baseoperator.py", line 422, in wrapper
    return func(self, *args, **kwargs)
           ^^^^^^^^^^^^^^^^^^^^^^^^^^^
  File "/home/airflow/.local/lib/python3.12/site-packages/airflow/operators/python.py", line 238, in execute
    return_value = self.execute_callable()
                   ^^^^^^^^^^^^^^^^^^^^^^^
  File "/home/airflow/.local/lib/python3.12/site-packages/airflow/operators/python.py", line 256, in execute_callable
    return runner.run(*self.op_args, **self.op_kwargs)
           ^^^^^^^^^^^^^^^^^^^^^^^^^^^^^^^^^^^^^^^^^^^
  File "/home/airflow/.local/lib/python3.12/site-packages/airflow/utils/operator_helpers.py", line 252, in run
    return self.func(*args, **kwargs)
           ^^^^^^^^^^^^^^^^^^^^^^^^^^
  File "/opt/airflow/dags/etl_como_vamos_dag.py", line 14, in run_bot_como_vamos
    result = subprocess.run(
             ^^^^^^^^^^^^^^^
  File "/usr/local/lib/python3.12/subprocess.py", line 571, in run
    raise CalledProcessError(retcode, process.args,
subprocess.CalledProcessError: Command '['python', '/opt/airflow/scripts/bot_reporte_como_vamos.py']' returned non-zero exit status 1.
[2025-01-28T01:10:26.166+0000] {taskinstance.py:1225} INFO - Marking task as UP_FOR_RETRY. dag_id=etl_reporte_como_vamos, task_id=execute_bot_como_vamos, run_id=manual__2025-01-28T01:10:18.953635+00:00, execution_date=20250128T011018, start_date=20250128T011021, end_date=20250128T011026
[2025-01-28T01:10:26.219+0000] {taskinstance.py:340} INFO - ::group::Post task execution logs
[2025-01-28T01:10:26.223+0000] {standard_task_runner.py:124} ERROR - Failed to execute job 27 for task execute_bot_como_vamos (Command '['python', '/opt/airflow/scripts/bot_reporte_como_vamos.py']' returned non-zero exit status 1.; 348)
Traceback (most recent call last):
  File "/home/airflow/.local/lib/python3.12/site-packages/airflow/task/task_runner/standard_task_runner.py", line 117, in _start_by_fork
    ret = args.func(args, dag=self.dag)
          ^^^^^^^^^^^^^^^^^^^^^^^^^^^^^
  File "/home/airflow/.local/lib/python3.12/site-packages/airflow/cli/cli_config.py", line 49, in command
    return func(*args, **kwargs)
           ^^^^^^^^^^^^^^^^^^^^^
  File "/home/airflow/.local/lib/python3.12/site-packages/airflow/utils/cli.py", line 116, in wrapper
    return f(*args, **kwargs)
           ^^^^^^^^^^^^^^^^^^
  File "/home/airflow/.local/lib/python3.12/site-packages/airflow/cli/commands/task_command.py", line 483, in task_run
    task_return_code = _run_task_by_selected_method(args, _dag, ti)
                       ^^^^^^^^^^^^^^^^^^^^^^^^^^^^^^^^^^^^^^^^^^^^
  File "/home/airflow/.local/lib/python3.12/site-packages/airflow/cli/commands/task_command.py", line 256, in _run_task_by_selected_method
    return _run_raw_task(args, ti)
           ^^^^^^^^^^^^^^^^^^^^^^^
  File "/home/airflow/.local/lib/python3.12/site-packages/airflow/cli/commands/task_command.py", line 341, in _run_raw_task
    return ti._run_raw_task(
           ^^^^^^^^^^^^^^^^^
  File "/home/airflow/.local/lib/python3.12/site-packages/airflow/utils/session.py", line 97, in wrapper
    return func(*args, session=session, **kwargs)
           ^^^^^^^^^^^^^^^^^^^^^^^^^^^^^^^^^^^^^^
  File "/home/airflow/.local/lib/python3.12/site-packages/airflow/models/taskinstance.py", line 3005, in _run_raw_task
    return _run_raw_task(
           ^^^^^^^^^^^^^^
  File "/home/airflow/.local/lib/python3.12/site-packages/airflow/models/taskinstance.py", line 273, in _run_raw_task
    TaskInstance._execute_task_with_callbacks(
  File "/home/airflow/.local/lib/python3.12/site-packages/airflow/models/taskinstance.py", line 3159, in _execute_task_with_callbacks
    result = self._execute_task(context, task_orig)
             ^^^^^^^^^^^^^^^^^^^^^^^^^^^^^^^^^^^^^^
  File "/home/airflow/.local/lib/python3.12/site-packages/airflow/models/taskinstance.py", line 3183, in _execute_task
    return _execute_task(self, context, task_orig)
           ^^^^^^^^^^^^^^^^^^^^^^^^^^^^^^^^^^^^^^^
  File "/home/airflow/.local/lib/python3.12/site-packages/airflow/models/taskinstance.py", line 767, in _execute_task
    result = _execute_callable(context=context, **execute_callable_kwargs)
             ^^^^^^^^^^^^^^^^^^^^^^^^^^^^^^^^^^^^^^^^^^^^^^^^^^^^^^^^^^^^^
  File "/home/airflow/.local/lib/python3.12/site-packages/airflow/models/taskinstance.py", line 733, in _execute_callable
    return ExecutionCallableRunner(
           ^^^^^^^^^^^^^^^^^^^^^^^^
  File "/home/airflow/.local/lib/python3.12/site-packages/airflow/utils/operator_helpers.py", line 252, in run
    return self.func(*args, **kwargs)
           ^^^^^^^^^^^^^^^^^^^^^^^^^^
  File "/home/airflow/.local/lib/python3.12/site-packages/airflow/models/baseoperator.py", line 422, in wrapper
    return func(self, *args, **kwargs)
           ^^^^^^^^^^^^^^^^^^^^^^^^^^^
  File "/home/airflow/.local/lib/python3.12/site-packages/airflow/operators/python.py", line 238, in execute
    return_value = self.execute_callable()
                   ^^^^^^^^^^^^^^^^^^^^^^^
  File "/home/airflow/.local/lib/python3.12/site-packages/airflow/operators/python.py", line 256, in execute_callable
    return runner.run(*self.op_args, **self.op_kwargs)
           ^^^^^^^^^^^^^^^^^^^^^^^^^^^^^^^^^^^^^^^^^^^
  File "/home/airflow/.local/lib/python3.12/site-packages/airflow/utils/operator_helpers.py", line 252, in run
    return self.func(*args, **kwargs)
           ^^^^^^^^^^^^^^^^^^^^^^^^^^
  File "/opt/airflow/dags/etl_como_vamos_dag.py", line 14, in run_bot_como_vamos
    result = subprocess.run(
             ^^^^^^^^^^^^^^^
  File "/usr/local/lib/python3.12/subprocess.py", line 571, in run
    raise CalledProcessError(retcode, process.args,
subprocess.CalledProcessError: Command '['python', '/opt/airflow/scripts/bot_reporte_como_vamos.py']' returned non-zero exit status 1.
[2025-01-28T01:10:26.265+0000] {local_task_job_runner.py:266} INFO - Task exited with return code 1
[2025-01-28T01:10:26.335+0000] {taskinstance.py:3895} INFO - 0 downstream tasks scheduled from follow-on schedule check
[2025-01-28T01:10:26.342+0000] {local_task_job_runner.py:245} INFO - ::endgroup::
