[2025-01-30T03:39:56.567+0000] {local_task_job_runner.py:123} INFO - ::group::Pre task execution logs
[2025-01-30T03:39:56.591+0000] {taskinstance.py:2613} INFO - Dependencies all met for dep_context=non-requeueable deps ti=<TaskInstance: etl_reporte_como_vamos.task_bot_como_vamos manual__2025-01-30T03:39:55.489070+00:00 [queued]>
[2025-01-30T03:39:56.602+0000] {taskinstance.py:2613} INFO - Dependencies all met for dep_context=requeueable deps ti=<TaskInstance: etl_reporte_como_vamos.task_bot_como_vamos manual__2025-01-30T03:39:55.489070+00:00 [queued]>
[2025-01-30T03:39:56.603+0000] {taskinstance.py:2866} INFO - Starting attempt 1 of 1
[2025-01-30T03:39:56.620+0000] {taskinstance.py:2889} INFO - Executing <Task(BashOperator): task_bot_como_vamos> on 2025-01-30 03:39:55.489070+00:00
[2025-01-30T03:39:56.627+0000] {warnings.py:112} WARNING - /home/***/.local/lib/python3.12/site-packages/***/task/task_runner/standard_task_runner.py:70: DeprecationWarning: This process (pid=2529) is multi-threaded, use of fork() may lead to deadlocks in the child.
  pid = os.fork()

[2025-01-30T03:39:56.629+0000] {standard_task_runner.py:72} INFO - Started process 2530 to run task
[2025-01-30T03:39:56.629+0000] {standard_task_runner.py:104} INFO - Running: ['***', 'tasks', 'run', 'etl_reporte_como_vamos', 'task_bot_como_vamos', 'manual__2025-01-30T03:39:55.489070+00:00', '--job-id', '26', '--raw', '--subdir', 'DAGS_FOLDER/etl_como_vamos_dag.py', '--cfg-path', '/tmp/tmp8oon7xix']
[2025-01-30T03:39:56.631+0000] {standard_task_runner.py:105} INFO - Job 26: Subtask task_bot_como_vamos
[2025-01-30T03:39:56.702+0000] {task_command.py:467} INFO - Running <TaskInstance: etl_reporte_como_vamos.task_bot_como_vamos manual__2025-01-30T03:39:55.489070+00:00 [running]> on host 438c87da0b60
[2025-01-30T03:39:56.786+0000] {taskinstance.py:3132} INFO - Exporting env vars: AIRFLOW_CTX_DAG_OWNER='***' AIRFLOW_CTX_DAG_ID='etl_reporte_como_vamos' AIRFLOW_CTX_TASK_ID='task_bot_como_vamos' AIRFLOW_CTX_EXECUTION_DATE='2025-01-30T03:39:55.489070+00:00' AIRFLOW_CTX_TRY_NUMBER='1' AIRFLOW_CTX_DAG_RUN_ID='manual__2025-01-30T03:39:55.489070+00:00'
[2025-01-30T03:39:56.788+0000] {taskinstance.py:731} INFO - ::endgroup::
[2025-01-30T03:39:56.804+0000] {subprocess.py:78} INFO - Tmp dir root location: /tmp
[2025-01-30T03:39:56.805+0000] {subprocess.py:88} INFO - Running command: ['/usr/bin/bash', '-c', 'python /opt/***/scripts/bot_reporte_como_vamos.py']
[2025-01-30T03:39:56.816+0000] {subprocess.py:99} INFO - Output:
[2025-01-30T03:40:04.695+0000] {subprocess.py:106} INFO - ic| start_date: '01/01/2025', end_date: '30/01/2025'
[2025-01-30T03:40:04.698+0000] {subprocess.py:106} INFO - 2025-01-30 03:40:04,694 - bot_como_vamos - INFO - Starting script bot_como_vamos.py
[2025-01-30T03:40:05.874+0000] {subprocess.py:106} INFO - 2025-01-30 03:40:05,873 - bot_como_vamos - INFO - Conexi√≥n al Selenium Hub establecida correctamente
[2025-01-30T03:40:58.752+0000] {subprocess.py:106} INFO - ic| login_success: <selenium.webdriver.remote.webelement.WebElement (session="9571a3520c67aedc2d6294f777366bbc", element="f.EFF7FA48B8A261C457EF3257B3C98596.d.EE16A0F76D9CE91F2FA4B2E249E3CE7D.e.75")>
[2025-01-30T03:40:58.753+0000] {subprocess.py:106} INFO - 2025-01-30 03:40:58,752 - bot_como_vamos - INFO - Loging success
[2025-01-30T03:41:08.857+0000] {subprocess.py:106} INFO - 2025-01-30 03:41:08,857 - bot_como_vamos - INFO - Click in menu button successfully
[2025-01-30T03:41:19.278+0000] {subprocess.py:106} INFO - 2025-01-30 03:41:19,278 - bot_como_vamos - INFO - Input dates successfully
[2025-01-30T03:41:29.421+0000] {subprocess.py:106} INFO - 2025-01-30 03:41:29,421 - bot_como_vamos - INFO - Click in 'Empresas Y Negocios' successfully
[2025-01-30T03:41:39.469+0000] {subprocess.py:106} INFO - 2025-01-30 03:41:39,469 - bot_como_vamos - ERROR - Execution error bot_reporte_como_vamos.py:
[2025-01-30T03:41:39.470+0000] {subprocess.py:106} INFO -  Error type: ElementNotInteractableException
[2025-01-30T03:41:39.470+0000] {subprocess.py:106} INFO - Error message: Message: element not interactable
[2025-01-30T03:41:39.471+0000] {subprocess.py:106} INFO -   (Session info: chrome=132.0.6834.110)
[2025-01-30T03:41:39.471+0000] {subprocess.py:106} INFO - Stacktrace:
[2025-01-30T03:41:39.471+0000] {subprocess.py:106} INFO - #0 0x5612a8688dca <unknown>
[2025-01-30T03:41:39.472+0000] {subprocess.py:106} INFO - #1 0x5612a817f24d <unknown>
[2025-01-30T03:41:39.472+0000] {subprocess.py:106} INFO - #2 0x5612a81d02d9 <unknown>
[2025-01-30T03:41:39.473+0000] {subprocess.py:106} INFO - #3 0x5612a81c32bd <unknown>
[2025-01-30T03:41:39.473+0000] {subprocess.py:106} INFO - #4 0x5612a81f3a92 <unknown>
[2025-01-30T03:41:39.473+0000] {subprocess.py:106} INFO - #5 0x5612a81c2c48 <unknown>
[2025-01-30T03:41:39.474+0000] {subprocess.py:106} INFO - #6 0x5612a81f3c5e <unknown>
[2025-01-30T03:41:39.474+0000] {subprocess.py:106} INFO - #7 0x5612a82124b3 <unknown>
[2025-01-30T03:41:39.474+0000] {subprocess.py:106} INFO - #8 0x5612a81f3833 <unknown>
[2025-01-30T03:41:39.475+0000] {subprocess.py:106} INFO - #9 0x5612a81c05a0 <unknown>
[2025-01-30T03:41:39.475+0000] {subprocess.py:106} INFO - #10 0x5612a81c1ece <unknown>
[2025-01-30T03:41:39.475+0000] {subprocess.py:106} INFO - #11 0x5612a8652bdb <unknown>
[2025-01-30T03:41:39.476+0000] {subprocess.py:106} INFO - #12 0x5612a8656b67 <unknown>
[2025-01-30T03:41:39.476+0000] {subprocess.py:106} INFO - #13 0x5612a863e3bc <unknown>
[2025-01-30T03:41:39.477+0000] {subprocess.py:106} INFO - #14 0x5612a8657727 <unknown>
[2025-01-30T03:41:39.477+0000] {subprocess.py:106} INFO - #15 0x5612a862274f <unknown>
[2025-01-30T03:41:39.477+0000] {subprocess.py:106} INFO - #16 0x5612a8677938 <unknown>
[2025-01-30T03:41:39.478+0000] {subprocess.py:106} INFO - #17 0x5612a8677b00 <unknown>
[2025-01-30T03:41:39.478+0000] {subprocess.py:106} INFO - #18 0x5612a8687c46 <unknown>
[2025-01-30T03:41:39.478+0000] {subprocess.py:106} INFO - #19 0x7f5f8302aa94 <unknown>
[2025-01-30T03:41:39.479+0000] {subprocess.py:106} INFO - #20 0x7f5f830b7c3c <unknown>
[2025-01-30T03:41:39.479+0000] {subprocess.py:106} INFO - 
[2025-01-30T03:41:39.479+0000] {subprocess.py:106} INFO - Full Traceback: Traceback (most recent call last):
[2025-01-30T03:41:39.480+0000] {subprocess.py:106} INFO -   File "/opt/***/scripts/bot_reporte_como_vamos.py", line 137, in main
[2025-01-30T03:41:39.480+0000] {subprocess.py:106} INFO -     reporte_como_vamos.click()
[2025-01-30T03:41:39.481+0000] {subprocess.py:106} INFO -   File "/home/***/.local/lib/python3.12/site-packages/selenium/webdriver/remote/webelement.py", line 119, in click
[2025-01-30T03:41:39.482+0000] {subprocess.py:106} INFO -     self._execute(Command.CLICK_ELEMENT)
[2025-01-30T03:41:39.482+0000] {subprocess.py:106} INFO -   File "/home/***/.local/lib/python3.12/site-packages/selenium/webdriver/remote/webelement.py", line 570, in _execute
[2025-01-30T03:41:39.483+0000] {subprocess.py:106} INFO -     return self._parent.execute(command, params)
[2025-01-30T03:41:39.483+0000] {subprocess.py:106} INFO -            ^^^^^^^^^^^^^^^^^^^^^^^^^^^^^^^^^^^^^
[2025-01-30T03:41:39.484+0000] {subprocess.py:106} INFO -   File "/home/***/.local/lib/python3.12/site-packages/selenium/webdriver/remote/webdriver.py", line 429, in execute
[2025-01-30T03:41:39.484+0000] {subprocess.py:106} INFO -     self.error_handler.check_response(response)
[2025-01-30T03:41:39.485+0000] {subprocess.py:106} INFO -   File "/home/***/.local/lib/python3.12/site-packages/selenium/webdriver/remote/errorhandler.py", line 232, in check_response
[2025-01-30T03:41:39.486+0000] {subprocess.py:106} INFO -     raise exception_class(message, screen, stacktrace)
[2025-01-30T03:41:39.487+0000] {subprocess.py:106} INFO - selenium.common.exceptions.ElementNotInteractableException: Message: element not interactable
[2025-01-30T03:41:39.487+0000] {subprocess.py:106} INFO -   (Session info: chrome=132.0.6834.110)
[2025-01-30T03:41:39.488+0000] {subprocess.py:106} INFO - Stacktrace:
[2025-01-30T03:41:39.489+0000] {subprocess.py:106} INFO - #0 0x5612a8688dca <unknown>
[2025-01-30T03:41:39.490+0000] {subprocess.py:106} INFO - #1 0x5612a817f24d <unknown>
[2025-01-30T03:41:39.491+0000] {subprocess.py:106} INFO - #2 0x5612a81d02d9 <unknown>
[2025-01-30T03:41:39.491+0000] {subprocess.py:106} INFO - #3 0x5612a81c32bd <unknown>
[2025-01-30T03:41:39.492+0000] {subprocess.py:106} INFO - #4 0x5612a81f3a92 <unknown>
[2025-01-30T03:41:39.492+0000] {subprocess.py:106} INFO - #5 0x5612a81c2c48 <unknown>
[2025-01-30T03:41:39.493+0000] {subprocess.py:106} INFO - #6 0x5612a81f3c5e <unknown>
[2025-01-30T03:41:39.493+0000] {subprocess.py:106} INFO - #7 0x5612a82124b3 <unknown>
[2025-01-30T03:41:39.494+0000] {subprocess.py:106} INFO - #8 0x5612a81f3833 <unknown>
[2025-01-30T03:41:39.494+0000] {subprocess.py:106} INFO - #9 0x5612a81c05a0 <unknown>
[2025-01-30T03:41:39.495+0000] {subprocess.py:106} INFO - #10 0x5612a81c1ece <unknown>
[2025-01-30T03:41:39.496+0000] {subprocess.py:106} INFO - #11 0x5612a8652bdb <unknown>
[2025-01-30T03:41:39.496+0000] {subprocess.py:106} INFO - #12 0x5612a8656b67 <unknown>
[2025-01-30T03:41:39.497+0000] {subprocess.py:106} INFO - #13 0x5612a863e3bc <unknown>
[2025-01-30T03:41:39.497+0000] {subprocess.py:106} INFO - #14 0x5612a8657727 <unknown>
[2025-01-30T03:41:39.498+0000] {subprocess.py:106} INFO - #15 0x5612a862274f <unknown>
[2025-01-30T03:41:39.499+0000] {subprocess.py:106} INFO - #16 0x5612a8677938 <unknown>
[2025-01-30T03:41:39.499+0000] {subprocess.py:106} INFO - #17 0x5612a8677b00 <unknown>
[2025-01-30T03:41:39.500+0000] {subprocess.py:106} INFO - #18 0x5612a8687c46 <unknown>
[2025-01-30T03:41:39.500+0000] {subprocess.py:106} INFO - #19 0x7f5f8302aa94 <unknown>
[2025-01-30T03:41:39.501+0000] {subprocess.py:106} INFO - #20 0x7f5f830b7c3c <unknown>
[2025-01-30T03:41:39.501+0000] {subprocess.py:106} INFO - 
[2025-01-30T03:41:39.502+0000] {subprocess.py:106} INFO - 
[2025-01-30T03:41:39.502+0000] {subprocess.py:106} INFO - Traceback (most recent call last):
[2025-01-30T03:41:39.502+0000] {subprocess.py:106} INFO -   File "/opt/***/scripts/bot_reporte_como_vamos.py", line 173, in <module>
[2025-01-30T03:41:39.503+0000] {subprocess.py:106} INFO -     main()
[2025-01-30T03:41:39.503+0000] {subprocess.py:106} INFO -   File "/opt/***/scripts/bot_reporte_como_vamos.py", line 137, in main
[2025-01-30T03:41:39.504+0000] {subprocess.py:106} INFO -     reporte_como_vamos.click()
[2025-01-30T03:41:39.504+0000] {subprocess.py:106} INFO -   File "/home/***/.local/lib/python3.12/site-packages/selenium/webdriver/remote/webelement.py", line 119, in click
[2025-01-30T03:41:39.505+0000] {subprocess.py:106} INFO -     self._execute(Command.CLICK_ELEMENT)
[2025-01-30T03:41:39.506+0000] {subprocess.py:106} INFO -   File "/home/***/.local/lib/python3.12/site-packages/selenium/webdriver/remote/webelement.py", line 570, in _execute
[2025-01-30T03:41:39.506+0000] {subprocess.py:106} INFO -     return self._parent.execute(command, params)
[2025-01-30T03:41:39.507+0000] {subprocess.py:106} INFO -            ^^^^^^^^^^^^^^^^^^^^^^^^^^^^^^^^^^^^^
[2025-01-30T03:41:39.507+0000] {subprocess.py:106} INFO -   File "/home/***/.local/lib/python3.12/site-packages/selenium/webdriver/remote/webdriver.py", line 429, in execute
[2025-01-30T03:41:39.508+0000] {subprocess.py:106} INFO -     self.error_handler.check_response(response)
[2025-01-30T03:41:39.508+0000] {subprocess.py:106} INFO -   File "/home/***/.local/lib/python3.12/site-packages/selenium/webdriver/remote/errorhandler.py", line 232, in check_response
[2025-01-30T03:41:39.509+0000] {subprocess.py:106} INFO -     raise exception_class(message, screen, stacktrace)
[2025-01-30T03:41:39.510+0000] {subprocess.py:106} INFO - selenium.common.exceptions.ElementNotInteractableException: Message: element not interactable
[2025-01-30T03:41:39.510+0000] {subprocess.py:106} INFO -   (Session info: chrome=132.0.6834.110)
[2025-01-30T03:41:39.511+0000] {subprocess.py:106} INFO - Stacktrace:
[2025-01-30T03:41:39.511+0000] {subprocess.py:106} INFO - #0 0x5612a8688dca <unknown>
[2025-01-30T03:41:39.512+0000] {subprocess.py:106} INFO - #1 0x5612a817f24d <unknown>
[2025-01-30T03:41:39.512+0000] {subprocess.py:106} INFO - #2 0x5612a81d02d9 <unknown>
[2025-01-30T03:41:39.513+0000] {subprocess.py:106} INFO - #3 0x5612a81c32bd <unknown>
[2025-01-30T03:41:39.513+0000] {subprocess.py:106} INFO - #4 0x5612a81f3a92 <unknown>
[2025-01-30T03:41:39.514+0000] {subprocess.py:106} INFO - #5 0x5612a81c2c48 <unknown>
[2025-01-30T03:41:39.515+0000] {subprocess.py:106} INFO - #6 0x5612a81f3c5e <unknown>
[2025-01-30T03:41:39.515+0000] {subprocess.py:106} INFO - #7 0x5612a82124b3 <unknown>
[2025-01-30T03:41:39.516+0000] {subprocess.py:106} INFO - #8 0x5612a81f3833 <unknown>
[2025-01-30T03:41:39.516+0000] {subprocess.py:106} INFO - #9 0x5612a81c05a0 <unknown>
[2025-01-30T03:41:39.517+0000] {subprocess.py:106} INFO - #10 0x5612a81c1ece <unknown>
[2025-01-30T03:41:39.517+0000] {subprocess.py:106} INFO - #11 0x5612a8652bdb <unknown>
[2025-01-30T03:41:39.518+0000] {subprocess.py:106} INFO - #12 0x5612a8656b67 <unknown>
[2025-01-30T03:41:39.518+0000] {subprocess.py:106} INFO - #13 0x5612a863e3bc <unknown>
[2025-01-30T03:41:39.519+0000] {subprocess.py:106} INFO - #14 0x5612a8657727 <unknown>
[2025-01-30T03:41:39.520+0000] {subprocess.py:106} INFO - #15 0x5612a862274f <unknown>
[2025-01-30T03:41:39.520+0000] {subprocess.py:106} INFO - #16 0x5612a8677938 <unknown>
[2025-01-30T03:41:39.521+0000] {subprocess.py:106} INFO - #17 0x5612a8677b00 <unknown>
[2025-01-30T03:41:39.521+0000] {subprocess.py:106} INFO - #18 0x5612a8687c46 <unknown>
[2025-01-30T03:41:39.522+0000] {subprocess.py:106} INFO - #19 0x7f5f8302aa94 <unknown>
[2025-01-30T03:41:39.522+0000] {subprocess.py:106} INFO - #20 0x7f5f830b7c3c <unknown>
[2025-01-30T03:41:39.523+0000] {subprocess.py:106} INFO - 
[2025-01-30T03:41:39.587+0000] {subprocess.py:110} INFO - Command exited with return code 1
[2025-01-30T03:41:39.599+0000] {taskinstance.py:3311} ERROR - Task failed with exception
Traceback (most recent call last):
  File "/home/airflow/.local/lib/python3.12/site-packages/airflow/models/taskinstance.py", line 767, in _execute_task
    result = _execute_callable(context=context, **execute_callable_kwargs)
             ^^^^^^^^^^^^^^^^^^^^^^^^^^^^^^^^^^^^^^^^^^^^^^^^^^^^^^^^^^^^^
  File "/home/airflow/.local/lib/python3.12/site-packages/airflow/models/taskinstance.py", line 733, in _execute_callable
    return ExecutionCallableRunner(
           ^^^^^^^^^^^^^^^^^^^^^^^^
  File "/home/airflow/.local/lib/python3.12/site-packages/airflow/utils/operator_helpers.py", line 252, in run
    return self.func(*args, **kwargs)
           ^^^^^^^^^^^^^^^^^^^^^^^^^^
  File "/home/airflow/.local/lib/python3.12/site-packages/airflow/models/baseoperator.py", line 422, in wrapper
    return func(self, *args, **kwargs)
           ^^^^^^^^^^^^^^^^^^^^^^^^^^^
  File "/home/airflow/.local/lib/python3.12/site-packages/airflow/operators/bash.py", line 276, in execute
    raise AirflowException(
airflow.exceptions.AirflowException: Bash command failed. The command returned a non-zero exit code 1.
[2025-01-30T03:41:39.603+0000] {taskinstance.py:1225} INFO - Marking task as FAILED. dag_id=etl_reporte_como_vamos, task_id=task_bot_como_vamos, run_id=manual__2025-01-30T03:39:55.489070+00:00, execution_date=20250130T033955, start_date=20250130T033956, end_date=20250130T034139
[2025-01-30T03:41:39.619+0000] {taskinstance.py:340} INFO - ::group::Post task execution logs
[2025-01-30T03:41:39.620+0000] {standard_task_runner.py:124} ERROR - Failed to execute job 26 for task task_bot_como_vamos (Bash command failed. The command returned a non-zero exit code 1.; 2530)
Traceback (most recent call last):
  File "/home/airflow/.local/lib/python3.12/site-packages/airflow/task/task_runner/standard_task_runner.py", line 117, in _start_by_fork
    ret = args.func(args, dag=self.dag)
          ^^^^^^^^^^^^^^^^^^^^^^^^^^^^^
  File "/home/airflow/.local/lib/python3.12/site-packages/airflow/cli/cli_config.py", line 49, in command
    return func(*args, **kwargs)
           ^^^^^^^^^^^^^^^^^^^^^
  File "/home/airflow/.local/lib/python3.12/site-packages/airflow/utils/cli.py", line 116, in wrapper
    return f(*args, **kwargs)
           ^^^^^^^^^^^^^^^^^^
  File "/home/airflow/.local/lib/python3.12/site-packages/airflow/cli/commands/task_command.py", line 483, in task_run
    task_return_code = _run_task_by_selected_method(args, _dag, ti)
                       ^^^^^^^^^^^^^^^^^^^^^^^^^^^^^^^^^^^^^^^^^^^^
  File "/home/airflow/.local/lib/python3.12/site-packages/airflow/cli/commands/task_command.py", line 256, in _run_task_by_selected_method
    return _run_raw_task(args, ti)
           ^^^^^^^^^^^^^^^^^^^^^^^
  File "/home/airflow/.local/lib/python3.12/site-packages/airflow/cli/commands/task_command.py", line 341, in _run_raw_task
    return ti._run_raw_task(
           ^^^^^^^^^^^^^^^^^
  File "/home/airflow/.local/lib/python3.12/site-packages/airflow/utils/session.py", line 97, in wrapper
    return func(*args, session=session, **kwargs)
           ^^^^^^^^^^^^^^^^^^^^^^^^^^^^^^^^^^^^^^
  File "/home/airflow/.local/lib/python3.12/site-packages/airflow/models/taskinstance.py", line 3005, in _run_raw_task
    return _run_raw_task(
           ^^^^^^^^^^^^^^
  File "/home/airflow/.local/lib/python3.12/site-packages/airflow/models/taskinstance.py", line 273, in _run_raw_task
    TaskInstance._execute_task_with_callbacks(
  File "/home/airflow/.local/lib/python3.12/site-packages/airflow/models/taskinstance.py", line 3159, in _execute_task_with_callbacks
    result = self._execute_task(context, task_orig)
             ^^^^^^^^^^^^^^^^^^^^^^^^^^^^^^^^^^^^^^
  File "/home/airflow/.local/lib/python3.12/site-packages/airflow/models/taskinstance.py", line 3183, in _execute_task
    return _execute_task(self, context, task_orig)
           ^^^^^^^^^^^^^^^^^^^^^^^^^^^^^^^^^^^^^^^
  File "/home/airflow/.local/lib/python3.12/site-packages/airflow/models/taskinstance.py", line 767, in _execute_task
    result = _execute_callable(context=context, **execute_callable_kwargs)
             ^^^^^^^^^^^^^^^^^^^^^^^^^^^^^^^^^^^^^^^^^^^^^^^^^^^^^^^^^^^^^
  File "/home/airflow/.local/lib/python3.12/site-packages/airflow/models/taskinstance.py", line 733, in _execute_callable
    return ExecutionCallableRunner(
           ^^^^^^^^^^^^^^^^^^^^^^^^
  File "/home/airflow/.local/lib/python3.12/site-packages/airflow/utils/operator_helpers.py", line 252, in run
    return self.func(*args, **kwargs)
           ^^^^^^^^^^^^^^^^^^^^^^^^^^
  File "/home/airflow/.local/lib/python3.12/site-packages/airflow/models/baseoperator.py", line 422, in wrapper
    return func(self, *args, **kwargs)
           ^^^^^^^^^^^^^^^^^^^^^^^^^^^
  File "/home/airflow/.local/lib/python3.12/site-packages/airflow/operators/bash.py", line 276, in execute
    raise AirflowException(
airflow.exceptions.AirflowException: Bash command failed. The command returned a non-zero exit code 1.
[2025-01-30T03:41:39.664+0000] {local_task_job_runner.py:266} INFO - Task exited with return code 1
[2025-01-30T03:41:39.681+0000] {taskinstance.py:3895} INFO - 0 downstream tasks scheduled from follow-on schedule check
[2025-01-30T03:41:39.685+0000] {local_task_job_runner.py:245} INFO - ::endgroup::
