[2025-02-08T06:32:14.576-0500] {local_task_job_runner.py:123} INFO - ::group::Pre task execution logs
[2025-02-08T06:32:14.596-0500] {taskinstance.py:2613} INFO - Dependencies all met for dep_context=non-requeueable deps ti=<TaskInstance: etl_reporte_como_vamos.bot_ex_bbva scheduled__2025-02-07T11:30:00+00:00 [queued]>
[2025-02-08T06:32:14.606-0500] {taskinstance.py:2613} INFO - Dependencies all met for dep_context=requeueable deps ti=<TaskInstance: etl_reporte_como_vamos.bot_ex_bbva scheduled__2025-02-07T11:30:00+00:00 [queued]>
[2025-02-08T06:32:14.608-0500] {taskinstance.py:2866} INFO - Starting attempt 1 of 4
[2025-02-08T06:32:14.625-0500] {taskinstance.py:2889} INFO - Executing <Task(BashOperator): bot_ex_bbva> on 2025-02-07 11:30:00+00:00
[2025-02-08T06:32:14.633-0500] {warnings.py:112} WARNING - /home/***/.local/lib/python3.12/site-packages/***/task/task_runner/standard_task_runner.py:70: DeprecationWarning: This process (pid=53830) is multi-threaded, use of fork() may lead to deadlocks in the child.
  pid = os.fork()

[2025-02-08T06:32:14.635-0500] {standard_task_runner.py:72} INFO - Started process 53831 to run task
[2025-02-08T06:32:14.635-0500] {standard_task_runner.py:104} INFO - Running: ['***', 'tasks', 'run', 'etl_reporte_como_vamos', 'bot_ex_bbva', 'scheduled__2025-02-07T11:30:00+00:00', '--job-id', '80', '--raw', '--subdir', 'DAGS_FOLDER/etl_como_vamos_dag.py', '--cfg-path', '/tmp/tmpxpwbmjxw']
[2025-02-08T06:32:14.636-0500] {standard_task_runner.py:105} INFO - Job 80: Subtask bot_ex_bbva
[2025-02-08T06:32:14.694-0500] {task_command.py:467} INFO - Running <TaskInstance: etl_reporte_como_vamos.bot_ex_bbva scheduled__2025-02-07T11:30:00+00:00 [running]> on host 21f1c1b48730
[2025-02-08T06:32:14.809-0500] {taskinstance.py:3132} INFO - Exporting env vars: AIRFLOW_CTX_DAG_OWNER='***' AIRFLOW_CTX_DAG_ID='etl_reporte_como_vamos' AIRFLOW_CTX_TASK_ID='bot_ex_bbva' AIRFLOW_CTX_EXECUTION_DATE='2025-02-07T11:30:00+00:00' AIRFLOW_CTX_TRY_NUMBER='1' AIRFLOW_CTX_DAG_RUN_ID='scheduled__2025-02-07T11:30:00+00:00'
[2025-02-08T06:32:14.810-0500] {taskinstance.py:731} INFO - ::endgroup::
[2025-02-08T06:32:14.830-0500] {subprocess.py:78} INFO - Tmp dir root location: /tmp
[2025-02-08T06:32:14.832-0500] {subprocess.py:88} INFO - Running command: ['/usr/bin/bash', '-c', 'python /opt/***/scripts/bot_etl_ex_bbva.py']
[2025-02-08T06:32:14.843-0500] {subprocess.py:99} INFO - Output:
[2025-02-08T06:32:15.764-0500] {subprocess.py:106} INFO - 2025-02-08 06:32:15,764 - bot_etl_ex_bbva - INFO - Bot ETL Exito-BBVA started
[2025-02-08T06:32:16.227-0500] {subprocess.py:106} INFO - 2025-02-08 06:32:16,227 - bot_etl_ex_bbva - INFO - Conexi√≥n al Selenium Hub establecida correctamente
[2025-02-08T06:32:18.428-0500] {subprocess.py:106} INFO - 2025-02-08 06:32:18,428 - bot_etl_ex_bbva - INFO - Credentials input success
[2025-02-08T06:32:19.636-0500] {subprocess.py:106} INFO - 2025-02-08 06:32:19,636 - bot_etl_ex_bbva - INFO - Click in login button
[2025-02-08T06:32:29.656-0500] {subprocess.py:106} INFO - 2025-02-08 06:32:29,656 - bot_etl_ex_bbva - INFO - Loging success
[2025-02-08T06:32:29.894-0500] {subprocess.py:106} INFO - 2025-02-08 06:32:29,893 - bot_etl_ex_bbva - ERROR - Error Loading Cerrados.xlsx to ETL:
[2025-02-08T06:32:29.895-0500] {subprocess.py:106} INFO - ***Error type:*** ElementNotInteractableException
[2025-02-08T06:32:29.895-0500] {subprocess.py:106} INFO - ***Error message:*** Message: element not interactable
[2025-02-08T06:32:29.896-0500] {subprocess.py:106} INFO -   (Session info: chrome=132.0.6834.110)
[2025-02-08T06:32:29.897-0500] {subprocess.py:106} INFO - Stacktrace:
[2025-02-08T06:32:29.898-0500] {subprocess.py:106} INFO - #0 0x55bfd290fdca <unknown>
[2025-02-08T06:32:29.899-0500] {subprocess.py:106} INFO - #1 0x55bfd240624d <unknown>
[2025-02-08T06:32:29.900-0500] {subprocess.py:106} INFO - #2 0x55bfd24572d9 <unknown>
[2025-02-08T06:32:29.900-0500] {subprocess.py:106} INFO - #3 0x55bfd244a2bd <unknown>
[2025-02-08T06:32:29.901-0500] {subprocess.py:106} INFO - #4 0x55bfd247aa92 <unknown>
[2025-02-08T06:32:29.901-0500] {subprocess.py:106} INFO - #5 0x55bfd2449c48 <unknown>
[2025-02-08T06:32:29.902-0500] {subprocess.py:106} INFO - #6 0x55bfd247ac5e <unknown>
[2025-02-08T06:32:29.903-0500] {subprocess.py:106} INFO - #7 0x55bfd24994b3 <unknown>
[2025-02-08T06:32:29.903-0500] {subprocess.py:106} INFO - #8 0x55bfd247a833 <unknown>
[2025-02-08T06:32:29.904-0500] {subprocess.py:106} INFO - #9 0x55bfd24475a0 <unknown>
[2025-02-08T06:32:29.904-0500] {subprocess.py:106} INFO - #10 0x55bfd2448ece <unknown>
[2025-02-08T06:32:29.905-0500] {subprocess.py:106} INFO - #11 0x55bfd28d9bdb <unknown>
[2025-02-08T06:32:29.905-0500] {subprocess.py:106} INFO - #12 0x55bfd28ddb67 <unknown>
[2025-02-08T06:32:29.908-0500] {subprocess.py:106} INFO - #13 0x55bfd28c53bc <unknown>
[2025-02-08T06:32:29.909-0500] {subprocess.py:106} INFO - #14 0x55bfd28de727 <unknown>
[2025-02-08T06:32:29.911-0500] {subprocess.py:106} INFO - #15 0x55bfd28a974f <unknown>
[2025-02-08T06:32:29.912-0500] {subprocess.py:106} INFO - #16 0x55bfd28fe938 <unknown>
[2025-02-08T06:32:29.913-0500] {subprocess.py:106} INFO - #17 0x55bfd28feb00 <unknown>
[2025-02-08T06:32:29.914-0500] {subprocess.py:106} INFO - #18 0x55bfd290ec46 <unknown>
[2025-02-08T06:32:29.914-0500] {subprocess.py:106} INFO - #19 0x7fc40918da94 <unknown>
[2025-02-08T06:32:29.915-0500] {subprocess.py:106} INFO - #20 0x7fc40921ac3c <unknown>
[2025-02-08T06:32:29.916-0500] {subprocess.py:106} INFO - 
[2025-02-08T06:32:29.917-0500] {subprocess.py:106} INFO - ***Full Traceback:*** Traceback (most recent call last):
[2025-02-08T06:32:29.918-0500] {subprocess.py:106} INFO -   File "/opt/***/scripts/bot_etl_ex_bbva.py", line 105, in main
[2025-02-08T06:32:29.919-0500] {subprocess.py:106} INFO -     up_button.click()
[2025-02-08T06:32:29.920-0500] {subprocess.py:106} INFO -   File "/home/***/.local/lib/python3.12/site-packages/selenium/webdriver/remote/webelement.py", line 119, in click
[2025-02-08T06:32:29.921-0500] {subprocess.py:106} INFO -     self._execute(Command.CLICK_ELEMENT)
[2025-02-08T06:32:29.922-0500] {subprocess.py:106} INFO -   File "/home/***/.local/lib/python3.12/site-packages/selenium/webdriver/remote/webelement.py", line 570, in _execute
[2025-02-08T06:32:29.922-0500] {subprocess.py:106} INFO -     return self._parent.execute(command, params)
[2025-02-08T06:32:29.923-0500] {subprocess.py:106} INFO -            ^^^^^^^^^^^^^^^^^^^^^^^^^^^^^^^^^^^^^
[2025-02-08T06:32:29.924-0500] {subprocess.py:106} INFO -   File "/home/***/.local/lib/python3.12/site-packages/selenium/webdriver/remote/webdriver.py", line 429, in execute
[2025-02-08T06:32:29.924-0500] {subprocess.py:106} INFO -     self.error_handler.check_response(response)
[2025-02-08T06:32:29.925-0500] {subprocess.py:106} INFO -   File "/home/***/.local/lib/python3.12/site-packages/selenium/webdriver/remote/errorhandler.py", line 232, in check_response
[2025-02-08T06:32:29.927-0500] {subprocess.py:106} INFO -     raise exception_class(message, screen, stacktrace)
[2025-02-08T06:32:29.928-0500] {subprocess.py:106} INFO - selenium.common.exceptions.ElementNotInteractableException: Message: element not interactable
[2025-02-08T06:32:29.929-0500] {subprocess.py:106} INFO -   (Session info: chrome=132.0.6834.110)
[2025-02-08T06:32:29.930-0500] {subprocess.py:106} INFO - Stacktrace:
[2025-02-08T06:32:29.930-0500] {subprocess.py:106} INFO - #0 0x55bfd290fdca <unknown>
[2025-02-08T06:32:29.931-0500] {subprocess.py:106} INFO - #1 0x55bfd240624d <unknown>
[2025-02-08T06:32:29.932-0500] {subprocess.py:106} INFO - #2 0x55bfd24572d9 <unknown>
[2025-02-08T06:32:29.932-0500] {subprocess.py:106} INFO - #3 0x55bfd244a2bd <unknown>
[2025-02-08T06:32:29.933-0500] {subprocess.py:106} INFO - #4 0x55bfd247aa92 <unknown>
[2025-02-08T06:32:29.933-0500] {subprocess.py:106} INFO - #5 0x55bfd2449c48 <unknown>
[2025-02-08T06:32:29.934-0500] {subprocess.py:106} INFO - #6 0x55bfd247ac5e <unknown>
[2025-02-08T06:32:29.935-0500] {subprocess.py:106} INFO - #7 0x55bfd24994b3 <unknown>
[2025-02-08T06:32:29.936-0500] {subprocess.py:106} INFO - #8 0x55bfd247a833 <unknown>
[2025-02-08T06:32:29.937-0500] {subprocess.py:106} INFO - #9 0x55bfd24475a0 <unknown>
[2025-02-08T06:32:29.937-0500] {subprocess.py:106} INFO - #10 0x55bfd2448ece <unknown>
[2025-02-08T06:32:29.938-0500] {subprocess.py:106} INFO - #11 0x55bfd28d9bdb <unknown>
[2025-02-08T06:32:29.938-0500] {subprocess.py:106} INFO - #12 0x55bfd28ddb67 <unknown>
[2025-02-08T06:32:29.939-0500] {subprocess.py:106} INFO - #13 0x55bfd28c53bc <unknown>
[2025-02-08T06:32:29.939-0500] {subprocess.py:106} INFO - #14 0x55bfd28de727 <unknown>
[2025-02-08T06:32:29.940-0500] {subprocess.py:106} INFO - #15 0x55bfd28a974f <unknown>
[2025-02-08T06:32:29.940-0500] {subprocess.py:106} INFO - #16 0x55bfd28fe938 <unknown>
[2025-02-08T06:32:29.941-0500] {subprocess.py:106} INFO - #17 0x55bfd28feb00 <unknown>
[2025-02-08T06:32:29.941-0500] {subprocess.py:106} INFO - #18 0x55bfd290ec46 <unknown>
[2025-02-08T06:32:29.942-0500] {subprocess.py:106} INFO - #19 0x7fc40918da94 <unknown>
[2025-02-08T06:32:29.942-0500] {subprocess.py:106} INFO - #20 0x7fc40921ac3c <unknown>
[2025-02-08T06:32:29.943-0500] {subprocess.py:106} INFO - 
[2025-02-08T06:32:29.943-0500] {subprocess.py:106} INFO - 
[2025-02-08T06:32:29.982-0500] {subprocess.py:106} INFO - 2025-02-08 06:32:29,981 - bot_etl_ex_bbva - INFO - bot_etl_ex_bbva finish execution
[2025-02-08T06:32:29.987-0500] {subprocess.py:106} INFO - Traceback (most recent call last):
[2025-02-08T06:32:29.988-0500] {subprocess.py:106} INFO -   File "/opt/***/scripts/bot_etl_ex_bbva.py", line 136, in <module>
[2025-02-08T06:32:29.992-0500] {subprocess.py:106} INFO -     main()
[2025-02-08T06:32:29.993-0500] {subprocess.py:106} INFO -   File "/opt/***/scripts/bot_etl_ex_bbva.py", line 131, in main
[2025-02-08T06:32:30.002-0500] {subprocess.py:106} INFO -     driver.quit()
[2025-02-08T06:32:30.002-0500] {subprocess.py:106} INFO -   File "/home/***/.local/lib/python3.12/site-packages/selenium/webdriver/remote/webdriver.py", line 589, in quit
[2025-02-08T06:32:30.006-0500] {subprocess.py:106} INFO -     self.execute(Command.QUIT)
[2025-02-08T06:32:30.006-0500] {subprocess.py:106} INFO -   File "/home/***/.local/lib/python3.12/site-packages/selenium/webdriver/remote/webdriver.py", line 429, in execute
[2025-02-08T06:32:30.007-0500] {subprocess.py:106} INFO -     self.error_handler.check_response(response)
[2025-02-08T06:32:30.010-0500] {subprocess.py:106} INFO -   File "/home/***/.local/lib/python3.12/site-packages/selenium/webdriver/remote/errorhandler.py", line 232, in check_response
[2025-02-08T06:32:30.011-0500] {subprocess.py:106} INFO -     raise exception_class(message, screen, stacktrace)
[2025-02-08T06:32:30.011-0500] {subprocess.py:106} INFO - selenium.common.exceptions.InvalidSessionIdException: Message: Unable to find session with ID: c0b80674f981c5d7302f75420dd86800
[2025-02-08T06:32:30.014-0500] {subprocess.py:106} INFO - Build info: version: '4.28.1', revision: '73f5ad48a2'
[2025-02-08T06:32:30.015-0500] {subprocess.py:106} INFO - System info: os.name: 'Linux', os.arch: 'amd64', os.version: '5.15.153.1-microsoft-standard-WSL2', java.version: '17.0.13'
[2025-02-08T06:32:30.015-0500] {subprocess.py:106} INFO - Driver info: driver.version: unknown
[2025-02-08T06:32:30.016-0500] {subprocess.py:106} INFO - Stacktrace:
[2025-02-08T06:32:30.016-0500] {subprocess.py:106} INFO - org.openqa.selenium.NoSuchSessionException: Unable to find session with ID: c0b80674f981c5d7302f75420dd86800
[2025-02-08T06:32:30.017-0500] {subprocess.py:106} INFO - Build info: version: '4.28.1', revision: '73f5ad48a2'
[2025-02-08T06:32:30.017-0500] {subprocess.py:106} INFO - System info: os.name: 'Linux', os.arch: 'amd64', os.version: '5.15.153.1-microsoft-standard-WSL2', java.version: '17.0.13'
[2025-02-08T06:32:30.018-0500] {subprocess.py:106} INFO - Driver info: driver.version: unknown
[2025-02-08T06:32:30.019-0500] {subprocess.py:106} INFO - 	at org.openqa.selenium.grid.sessionmap.local.LocalSessionMap.get(LocalSessionMap.java:117)
[2025-02-08T06:32:30.020-0500] {subprocess.py:106} INFO - 	at org.openqa.selenium.grid.sessionmap.SessionMap.getUri(SessionMap.java:84)
[2025-02-08T06:32:30.021-0500] {subprocess.py:106} INFO - 	at org.openqa.selenium.grid.router.HandleSession.lambda$loadSessionId$4(HandleSession.java:225)
[2025-02-08T06:32:30.021-0500] {subprocess.py:106} INFO - 	at org.openqa.selenium.grid.router.HandleSession.execute(HandleSession.java:182)
[2025-02-08T06:32:30.022-0500] {subprocess.py:106} INFO - 	at org.openqa.selenium.remote.http.Route$PredicatedRoute.handle(Route.java:397)
[2025-02-08T06:32:30.022-0500] {subprocess.py:106} INFO - 	at org.openqa.selenium.remote.http.Route.execute(Route.java:69)
[2025-02-08T06:32:30.023-0500] {subprocess.py:106} INFO - 	at org.openqa.selenium.remote.http.Route$CombinedRoute.handle(Route.java:360)
[2025-02-08T06:32:30.023-0500] {subprocess.py:106} INFO - 	at org.openqa.selenium.remote.http.Route.execute(Route.java:69)
[2025-02-08T06:32:30.024-0500] {subprocess.py:106} INFO - 	at org.openqa.selenium.grid.router.Router.execute(Router.java:89)
[2025-02-08T06:32:30.024-0500] {subprocess.py:106} INFO - 	at org.openqa.selenium.grid.web.EnsureSpecCompliantResponseHeaders.lambda$apply$0(EnsureSpecCompliantResponseHeaders.java:34)
[2025-02-08T06:32:30.028-0500] {subprocess.py:106} INFO - 	at org.openqa.selenium.remote.http.Filter$1.execute(Filter.java:63)
[2025-02-08T06:32:30.028-0500] {subprocess.py:106} INFO - 	at org.openqa.selenium.remote.http.Route$CombinedRoute.handle(Route.java:360)
[2025-02-08T06:32:30.029-0500] {subprocess.py:106} INFO - 	at org.openqa.selenium.remote.http.Route.execute(Route.java:69)
[2025-02-08T06:32:30.029-0500] {subprocess.py:106} INFO - 	at org.openqa.selenium.remote.AddWebDriverSpecHeaders.lambda$apply$0(AddWebDriverSpecHeaders.java:35)
[2025-02-08T06:32:30.030-0500] {subprocess.py:106} INFO - 	at org.openqa.selenium.remote.ErrorFilter.lambda$apply$0(ErrorFilter.java:44)
[2025-02-08T06:32:30.033-0500] {subprocess.py:106} INFO - 	at org.openqa.selenium.remote.http.Filter$1.execute(Filter.java:63)
[2025-02-08T06:32:30.033-0500] {subprocess.py:106} INFO - 	at org.openqa.selenium.remote.ErrorFilter.lambda$apply$0(ErrorFilter.java:44)
[2025-02-08T06:32:30.034-0500] {subprocess.py:106} INFO - 	at org.openqa.selenium.remote.http.Filter$1.execute(Filter.java:63)
[2025-02-08T06:32:30.035-0500] {subprocess.py:106} INFO - 	at org.openqa.selenium.netty.server.SeleniumHandler.lambda$channelRead0$0(SeleniumHandler.java:49)
[2025-02-08T06:32:30.035-0500] {subprocess.py:106} INFO - 	at java.base/java.util.concurrent.Executors$RunnableAdapter.call(Executors.java:539)
[2025-02-08T06:32:30.036-0500] {subprocess.py:106} INFO - 	at java.base/java.util.concurrent.FutureTask.run(FutureTask.java:264)
[2025-02-08T06:32:30.036-0500] {subprocess.py:106} INFO - 	at java.base/java.util.concurrent.ThreadPoolExecutor.runWorker(ThreadPoolExecutor.java:1136)
[2025-02-08T06:32:30.037-0500] {subprocess.py:106} INFO - 	at java.base/java.util.concurrent.ThreadPoolExecutor$Worker.run(ThreadPoolExecutor.java:635)
[2025-02-08T06:32:30.037-0500] {subprocess.py:106} INFO - 	at java.base/java.lang.Thread.run(Thread.java:840)
[2025-02-08T06:32:30.038-0500] {subprocess.py:106} INFO - 
[2025-02-08T06:32:30.043-0500] {subprocess.py:110} INFO - Command exited with return code 1
[2025-02-08T06:32:30.056-0500] {taskinstance.py:3311} ERROR - Task failed with exception
Traceback (most recent call last):
  File "/home/airflow/.local/lib/python3.12/site-packages/airflow/models/taskinstance.py", line 767, in _execute_task
    result = _execute_callable(context=context, **execute_callable_kwargs)
             ^^^^^^^^^^^^^^^^^^^^^^^^^^^^^^^^^^^^^^^^^^^^^^^^^^^^^^^^^^^^^
  File "/home/airflow/.local/lib/python3.12/site-packages/airflow/models/taskinstance.py", line 733, in _execute_callable
    return ExecutionCallableRunner(
           ^^^^^^^^^^^^^^^^^^^^^^^^
  File "/home/airflow/.local/lib/python3.12/site-packages/airflow/utils/operator_helpers.py", line 252, in run
    return self.func(*args, **kwargs)
           ^^^^^^^^^^^^^^^^^^^^^^^^^^
  File "/home/airflow/.local/lib/python3.12/site-packages/airflow/models/baseoperator.py", line 422, in wrapper
    return func(self, *args, **kwargs)
           ^^^^^^^^^^^^^^^^^^^^^^^^^^^
  File "/home/airflow/.local/lib/python3.12/site-packages/airflow/operators/bash.py", line 276, in execute
    raise AirflowException(
airflow.exceptions.AirflowException: Bash command failed. The command returned a non-zero exit code 1.
[2025-02-08T06:32:30.067-0500] {taskinstance.py:1225} INFO - Marking task as UP_FOR_RETRY. dag_id=etl_reporte_como_vamos, task_id=bot_ex_bbva, run_id=scheduled__2025-02-07T11:30:00+00:00, execution_date=20250207T113000, start_date=20250208T113214, end_date=20250208T113230
[2025-02-08T06:32:30.086-0500] {taskinstance.py:340} INFO - ::group::Post task execution logs
[2025-02-08T06:32:30.087-0500] {standard_task_runner.py:124} ERROR - Failed to execute job 80 for task bot_ex_bbva (Bash command failed. The command returned a non-zero exit code 1.; 53831)
Traceback (most recent call last):
  File "/home/airflow/.local/lib/python3.12/site-packages/airflow/task/task_runner/standard_task_runner.py", line 117, in _start_by_fork
    ret = args.func(args, dag=self.dag)
          ^^^^^^^^^^^^^^^^^^^^^^^^^^^^^
  File "/home/airflow/.local/lib/python3.12/site-packages/airflow/cli/cli_config.py", line 49, in command
    return func(*args, **kwargs)
           ^^^^^^^^^^^^^^^^^^^^^
  File "/home/airflow/.local/lib/python3.12/site-packages/airflow/utils/cli.py", line 116, in wrapper
    return f(*args, **kwargs)
           ^^^^^^^^^^^^^^^^^^
  File "/home/airflow/.local/lib/python3.12/site-packages/airflow/cli/commands/task_command.py", line 483, in task_run
    task_return_code = _run_task_by_selected_method(args, _dag, ti)
                       ^^^^^^^^^^^^^^^^^^^^^^^^^^^^^^^^^^^^^^^^^^^^
  File "/home/airflow/.local/lib/python3.12/site-packages/airflow/cli/commands/task_command.py", line 256, in _run_task_by_selected_method
    return _run_raw_task(args, ti)
           ^^^^^^^^^^^^^^^^^^^^^^^
  File "/home/airflow/.local/lib/python3.12/site-packages/airflow/cli/commands/task_command.py", line 341, in _run_raw_task
    return ti._run_raw_task(
           ^^^^^^^^^^^^^^^^^
  File "/home/airflow/.local/lib/python3.12/site-packages/airflow/utils/session.py", line 97, in wrapper
    return func(*args, session=session, **kwargs)
           ^^^^^^^^^^^^^^^^^^^^^^^^^^^^^^^^^^^^^^
  File "/home/airflow/.local/lib/python3.12/site-packages/airflow/models/taskinstance.py", line 3005, in _run_raw_task
    return _run_raw_task(
           ^^^^^^^^^^^^^^
  File "/home/airflow/.local/lib/python3.12/site-packages/airflow/models/taskinstance.py", line 273, in _run_raw_task
    TaskInstance._execute_task_with_callbacks(
  File "/home/airflow/.local/lib/python3.12/site-packages/airflow/models/taskinstance.py", line 3159, in _execute_task_with_callbacks
    result = self._execute_task(context, task_orig)
             ^^^^^^^^^^^^^^^^^^^^^^^^^^^^^^^^^^^^^^
  File "/home/airflow/.local/lib/python3.12/site-packages/airflow/models/taskinstance.py", line 3183, in _execute_task
    return _execute_task(self, context, task_orig)
           ^^^^^^^^^^^^^^^^^^^^^^^^^^^^^^^^^^^^^^^
  File "/home/airflow/.local/lib/python3.12/site-packages/airflow/models/taskinstance.py", line 767, in _execute_task
    result = _execute_callable(context=context, **execute_callable_kwargs)
             ^^^^^^^^^^^^^^^^^^^^^^^^^^^^^^^^^^^^^^^^^^^^^^^^^^^^^^^^^^^^^
  File "/home/airflow/.local/lib/python3.12/site-packages/airflow/models/taskinstance.py", line 733, in _execute_callable
    return ExecutionCallableRunner(
           ^^^^^^^^^^^^^^^^^^^^^^^^
  File "/home/airflow/.local/lib/python3.12/site-packages/airflow/utils/operator_helpers.py", line 252, in run
    return self.func(*args, **kwargs)
           ^^^^^^^^^^^^^^^^^^^^^^^^^^
  File "/home/airflow/.local/lib/python3.12/site-packages/airflow/models/baseoperator.py", line 422, in wrapper
    return func(self, *args, **kwargs)
           ^^^^^^^^^^^^^^^^^^^^^^^^^^^
  File "/home/airflow/.local/lib/python3.12/site-packages/airflow/operators/bash.py", line 276, in execute
    raise AirflowException(
airflow.exceptions.AirflowException: Bash command failed. The command returned a non-zero exit code 1.
[2025-02-08T06:32:30.126-0500] {local_task_job_runner.py:266} INFO - Task exited with return code 1
[2025-02-08T06:32:30.147-0500] {taskinstance.py:3895} INFO - 0 downstream tasks scheduled from follow-on schedule check
[2025-02-08T06:32:30.151-0500] {local_task_job_runner.py:245} INFO - ::endgroup::
