[2025-01-28T06:40:41.718+0000] {local_task_job_runner.py:123} INFO - ::group::Pre task execution logs
[2025-01-28T06:40:41.761+0000] {taskinstance.py:2613} INFO - Dependencies all met for dep_context=non-requeueable deps ti=<TaskInstance: etl_reporte_como_vamos.task_bot_como_vamos manual__2025-01-28T06:27:38.303126+00:00 [queued]>
[2025-01-28T06:40:41.782+0000] {taskinstance.py:2613} INFO - Dependencies all met for dep_context=requeueable deps ti=<TaskInstance: etl_reporte_como_vamos.task_bot_como_vamos manual__2025-01-28T06:27:38.303126+00:00 [queued]>
[2025-01-28T06:40:41.785+0000] {taskinstance.py:2866} INFO - Starting attempt 2 of 2
[2025-01-28T06:40:41.820+0000] {taskinstance.py:2889} INFO - Executing <Task(BashOperator): task_bot_como_vamos> on 2025-01-28 06:27:38.303126+00:00
[2025-01-28T06:40:41.834+0000] {standard_task_runner.py:104} INFO - Running: ['***', 'tasks', 'run', 'etl_reporte_como_vamos', 'task_bot_como_vamos', 'manual__2025-01-28T06:27:38.303126+00:00', '--job-id', '50', '--raw', '--subdir', 'DAGS_FOLDER/etl_como_vamos_dag.py', '--cfg-path', '/tmp/tmpvovkca61']
[2025-01-28T06:40:41.841+0000] {standard_task_runner.py:105} INFO - Job 50: Subtask task_bot_como_vamos
[2025-01-28T06:40:41.845+0000] {logging_mixin.py:190} WARNING - /home/***/.local/lib/python3.12/site-packages/***/task/task_runner/standard_task_runner.py:70 DeprecationWarning: This process (pid=198) is multi-threaded, use of fork() may lead to deadlocks in the child.
[2025-01-28T06:40:41.849+0000] {standard_task_runner.py:72} INFO - Started process 202 to run task
[2025-01-28T06:40:41.979+0000] {task_command.py:467} INFO - Running <TaskInstance: etl_reporte_como_vamos.task_bot_como_vamos manual__2025-01-28T06:27:38.303126+00:00 [running]> on host 08150d224bd2
[2025-01-28T06:40:42.668+0000] {taskinstance.py:3132} INFO - Exporting env vars: AIRFLOW_CTX_DAG_OWNER='***' AIRFLOW_CTX_DAG_ID='etl_reporte_como_vamos' AIRFLOW_CTX_TASK_ID='task_bot_como_vamos' AIRFLOW_CTX_EXECUTION_DATE='2025-01-28T06:27:38.303126+00:00' AIRFLOW_CTX_TRY_NUMBER='2' AIRFLOW_CTX_DAG_RUN_ID='manual__2025-01-28T06:27:38.303126+00:00'
[2025-01-28T06:40:42.670+0000] {taskinstance.py:731} INFO - ::endgroup::
[2025-01-28T06:40:42.799+0000] {subprocess.py:78} INFO - Tmp dir root location: /tmp
[2025-01-28T06:40:42.803+0000] {subprocess.py:88} INFO - Running command: ['/usr/bin/bash', '-c', 'python /opt/***/scripts/bot_reporte_como_vamos.py']
[2025-01-28T06:40:42.835+0000] {subprocess.py:99} INFO - Output:
[2025-01-28T06:40:49.876+0000] {subprocess.py:106} INFO - ic| start_date: '01/01/2025', end_date: '28/01/2025'
[2025-01-28T06:40:49.877+0000] {subprocess.py:106} INFO - 2025-01-28 06:40:49,876 - bot_como_vamos - INFO - Starting script bot_como_vamos.py
[2025-01-28T06:40:56.545+0000] {subprocess.py:106} INFO - 2025-01-28 06:40:56,544 - root - ERROR - Execution error: Message: Could not start a new session. Could not start a new session. Error while creating session with the driver service. Stopping driver service: Could not start a new session. Response code 404. Message: invalid session id: session deleted as the browser has closed the connection
[2025-01-28T06:40:56.551+0000] {subprocess.py:106} INFO - from disconnected: Unable to receive message from renderer
[2025-01-28T06:40:56.554+0000] {subprocess.py:106} INFO -   (Session info: chrome=132.0.6834.110)
[2025-01-28T06:40:56.556+0000] {subprocess.py:106} INFO - Host info: host: '55c85d6c8bc2', ip: '172.18.0.5'
[2025-01-28T06:40:56.567+0000] {subprocess.py:106} INFO - Build info: version: '4.28.1', revision: '73f5ad48a2'
[2025-01-28T06:40:56.571+0000] {subprocess.py:106} INFO - System info: os.name: 'Linux', os.arch: 'amd64', os.version: '6.10.4-linuxkit', java.version: '17.0.13'
[2025-01-28T06:40:56.575+0000] {subprocess.py:106} INFO - Driver info: driver.version: unknown
[2025-01-28T06:40:56.579+0000] {subprocess.py:106} INFO - Build info: version: '4.28.1', revision: '73f5ad48a2'
[2025-01-28T06:40:56.583+0000] {subprocess.py:106} INFO - System info: os.name: 'Linux', os.arch: 'amd64', os.version: '6.10.4-linuxkit', java.version: '17.0.13'
[2025-01-28T06:40:56.591+0000] {subprocess.py:106} INFO - Driver info: driver.version: unknown
[2025-01-28T06:40:56.594+0000] {subprocess.py:106} INFO - Build info: version: '4.28.1', revision: '73f5ad48a2'
[2025-01-28T06:40:56.596+0000] {subprocess.py:106} INFO - System info: os.name: 'Linux', os.arch: 'amd64', os.version: '6.10.4-linuxkit', java.version: '17.0.13'
[2025-01-28T06:40:56.598+0000] {subprocess.py:106} INFO - Driver info: driver.version: unknown
[2025-01-28T06:40:56.601+0000] {subprocess.py:106} INFO - Stacktrace:
[2025-01-28T06:40:56.604+0000] {subprocess.py:106} INFO -     at org.openqa.selenium.grid.node.remote.RemoteNode.newSession (RemoteNode.java:167)
[2025-01-28T06:40:56.607+0000] {subprocess.py:106} INFO -     at org.openqa.selenium.grid.distributor.local.LocalDistributor.startSession (LocalDistributor.java:678)
[2025-01-28T06:40:56.609+0000] {subprocess.py:106} INFO -     at org.openqa.selenium.grid.distributor.local.LocalDistributor.newSession (LocalDistributor.java:597)
[2025-01-28T06:40:56.611+0000] {subprocess.py:106} INFO -     at org.openqa.selenium.grid.distributor.local.LocalDistributor$NewSessionRunnable.handleNewSessionRequest (LocalDistributor.java:861)
[2025-01-28T06:40:56.613+0000] {subprocess.py:106} INFO -     at org.openqa.selenium.grid.distributor.local.LocalDistributor$NewSessionRunnable.lambda$run$1 (LocalDistributor.java:818)
[2025-01-28T06:40:56.615+0000] {subprocess.py:106} INFO -     at java.util.concurrent.ThreadPoolExecutor.runWorker (ThreadPoolExecutor.java:1136)
[2025-01-28T06:40:56.618+0000] {subprocess.py:106} INFO -     at java.util.concurrent.ThreadPoolExecutor$Worker.run (ThreadPoolExecutor.java:635)
[2025-01-28T06:40:56.620+0000] {subprocess.py:106} INFO -     at java.lang.Thread.run (Thread.java:840)
[2025-01-28T06:40:56.662+0000] {subprocess.py:106} INFO - ic| file: '***tmpg431l7gm'
[2025-01-28T06:40:56.667+0000] {subprocess.py:106} INFO - ic| file: 'pymp-hmyjbm0g'
[2025-01-28T06:40:56.669+0000] {subprocess.py:106} INFO - ic| file: 'hsperfdata_root'
[2025-01-28T06:41:01.667+0000] {subprocess.py:106} INFO - ic| file: '***tmpg431l7gm'
[2025-01-28T06:41:01.669+0000] {subprocess.py:106} INFO - ic| file: 'pymp-hmyjbm0g'
[2025-01-28T06:41:01.670+0000] {subprocess.py:106} INFO - ic| file: 'hsperfdata_root'
[2025-01-28T06:41:06.669+0000] {subprocess.py:106} INFO - ic| file: '***tmpg431l7gm'
[2025-01-28T06:41:06.670+0000] {subprocess.py:106} INFO - ic| file: 'pymp-hmyjbm0g'
[2025-01-28T06:41:06.671+0000] {subprocess.py:106} INFO - ic| file: 'hsperfdata_root'
[2025-01-28T06:41:11.671+0000] {subprocess.py:106} INFO - ic| file: '***tmpg431l7gm'
[2025-01-28T06:41:11.672+0000] {subprocess.py:106} INFO - ic| file: 'pymp-hmyjbm0g'
[2025-01-28T06:41:11.674+0000] {subprocess.py:106} INFO - ic| file: 'hsperfdata_root'
[2025-01-28T06:41:16.674+0000] {subprocess.py:106} INFO - ic| file: '***tmpg431l7gm'
[2025-01-28T06:41:16.681+0000] {subprocess.py:106} INFO - ic| file: 'pymp-hmyjbm0g'
[2025-01-28T06:41:16.682+0000] {subprocess.py:106} INFO - ic| file: 'hsperfdata_root'
[2025-01-28T06:41:21.682+0000] {subprocess.py:106} INFO - ic| file: '***tmpg431l7gm'
[2025-01-28T06:41:21.686+0000] {subprocess.py:106} INFO - ic| file: 'pymp-hmyjbm0g'
[2025-01-28T06:41:21.690+0000] {subprocess.py:106} INFO - ic| file: 'hsperfdata_root'
[2025-01-28T06:41:26.691+0000] {subprocess.py:106} INFO - ic| file: '***tmpg431l7gm'
[2025-01-28T06:41:26.698+0000] {subprocess.py:106} INFO - ic| file: 'pymp-hmyjbm0g'
[2025-01-28T06:41:26.705+0000] {subprocess.py:106} INFO - ic| file: 'hsperfdata_root'
[2025-01-28T06:41:31.706+0000] {subprocess.py:106} INFO - ic| file: '***tmpg431l7gm'
[2025-01-28T06:41:31.710+0000] {subprocess.py:106} INFO - ic| file: 'pymp-hmyjbm0g'
[2025-01-28T06:41:31.713+0000] {subprocess.py:106} INFO - ic| file: 'hsperfdata_root'
[2025-01-28T06:41:36.710+0000] {subprocess.py:106} INFO - ic| file: '***tmpg431l7gm'
[2025-01-28T06:41:36.714+0000] {subprocess.py:106} INFO - ic| file: 'pymp-hmyjbm0g'
[2025-01-28T06:41:36.717+0000] {subprocess.py:106} INFO - ic| file: 'hsperfdata_root'
[2025-01-28T06:41:37.496+0000] {local_task_job_runner.py:346} WARNING - State of this instance has been externally set to None. Terminating instance.
[2025-01-28T06:41:37.613+0000] {local_task_job_runner.py:245} INFO - ::endgroup::
[2025-01-28T06:41:37.628+0000] {process_utils.py:132} INFO - Sending 15 to group 202. PIDs of all processes in the group: [206, 202]
[2025-01-28T06:41:37.633+0000] {process_utils.py:87} INFO - Sending the signal 15 to group 202
[2025-01-28T06:41:37.649+0000] {taskinstance.py:3093} ERROR - Received SIGTERM. Terminating subprocesses.
[2025-01-28T06:41:37.661+0000] {subprocess.py:117} INFO - Sending SIGTERM signal to process group
[2025-01-28T06:41:38.414+0000] {taskinstance.py:3311} ERROR - Task failed with exception
Traceback (most recent call last):
  File "/home/airflow/.local/lib/python3.12/site-packages/airflow/models/taskinstance.py", line 767, in _execute_task
    result = _execute_callable(context=context, **execute_callable_kwargs)
             ^^^^^^^^^^^^^^^^^^^^^^^^^^^^^^^^^^^^^^^^^^^^^^^^^^^^^^^^^^^^^
  File "/home/airflow/.local/lib/python3.12/site-packages/airflow/models/taskinstance.py", line 733, in _execute_callable
    return ExecutionCallableRunner(
           ^^^^^^^^^^^^^^^^^^^^^^^^
  File "/home/airflow/.local/lib/python3.12/site-packages/airflow/utils/operator_helpers.py", line 252, in run
    return self.func(*args, **kwargs)
           ^^^^^^^^^^^^^^^^^^^^^^^^^^
  File "/home/airflow/.local/lib/python3.12/site-packages/airflow/models/baseoperator.py", line 422, in wrapper
    return func(self, *args, **kwargs)
           ^^^^^^^^^^^^^^^^^^^^^^^^^^^
  File "/home/airflow/.local/lib/python3.12/site-packages/airflow/operators/bash.py", line 257, in execute
    result = self._run_inline_command(bash_path=bash_path, env=env)
             ^^^^^^^^^^^^^^^^^^^^^^^^^^^^^^^^^^^^^^^^^^^^^^^^^^^^^^
  File "/home/airflow/.local/lib/python3.12/site-packages/airflow/operators/bash.py", line 284, in _run_inline_command
    return self.subprocess_hook.run_command(
           ^^^^^^^^^^^^^^^^^^^^^^^^^^^^^^^^^
  File "/home/airflow/.local/lib/python3.12/site-packages/airflow/hooks/subprocess.py", line 104, in run_command
    for raw_line in iter(self.sub_process.stdout.readline, b""):
                    ^^^^^^^^^^^^^^^^^^^^^^^^^^^^^^^^^^^^^^^^^^^
  File "/home/airflow/.local/lib/python3.12/site-packages/airflow/models/taskinstance.py", line 3095, in signal_handler
    raise AirflowTaskTerminated("Task received SIGTERM signal")
airflow.exceptions.AirflowTaskTerminated: Task received SIGTERM signal
[2025-01-28T06:41:38.634+0000] {taskinstance.py:1225} INFO - Marking task as FAILED. dag_id=etl_reporte_como_vamos, task_id=task_bot_como_vamos, run_id=manual__2025-01-28T06:27:38.303126+00:00, execution_date=20250128T062738, start_date=20250128T064041, end_date=20250128T064138
[2025-01-28T06:41:39.123+0000] {taskinstance.py:340} INFO - ::group::Post task execution logs
[2025-01-28T06:41:39.154+0000] {standard_task_runner.py:124} ERROR - Failed to execute job 50 for task task_bot_como_vamos ((psycopg2.errors.ForeignKeyViolation) insert or update on table "task_fail" violates foreign key constraint "task_fail_ti_fkey"
DETAIL:  Key (dag_id, task_id, run_id, map_index)=(etl_reporte_como_vamos, task_bot_como_vamos, manual__2025-01-28T06:27:38.303126+00:00, -1) is not present in table "task_instance".

[SQL: INSERT INTO task_fail (task_id, dag_id, run_id, map_index, start_date, end_date, duration) VALUES (%(task_id)s, %(dag_id)s, %(run_id)s, %(map_index)s, %(start_date)s, %(end_date)s, %(duration)s) RETURNING task_fail.id]
[parameters: {'task_id': 'task_bot_como_vamos', 'dag_id': 'etl_reporte_como_vamos', 'run_id': 'manual__2025-01-28T06:27:38.303126+00:00', 'map_index': -1, 'start_date': datetime.datetime(2025, 1, 28, 6, 40, 41, 764403, tzinfo=Timezone('UTC')), 'end_date': datetime.datetime(2025, 1, 28, 6, 41, 38, 556496, tzinfo=Timezone('UTC')), 'duration': 56}]
(Background on this error at: https://sqlalche.me/e/14/gkpj); 202)
Traceback (most recent call last):
  File "/home/airflow/.local/lib/python3.12/site-packages/airflow/models/taskinstance.py", line 273, in _run_raw_task
    TaskInstance._execute_task_with_callbacks(
  File "/home/airflow/.local/lib/python3.12/site-packages/airflow/models/taskinstance.py", line 3159, in _execute_task_with_callbacks
    result = self._execute_task(context, task_orig)
             ^^^^^^^^^^^^^^^^^^^^^^^^^^^^^^^^^^^^^^
  File "/home/airflow/.local/lib/python3.12/site-packages/airflow/models/taskinstance.py", line 3183, in _execute_task
    return _execute_task(self, context, task_orig)
           ^^^^^^^^^^^^^^^^^^^^^^^^^^^^^^^^^^^^^^^
  File "/home/airflow/.local/lib/python3.12/site-packages/airflow/models/taskinstance.py", line 767, in _execute_task
    result = _execute_callable(context=context, **execute_callable_kwargs)
             ^^^^^^^^^^^^^^^^^^^^^^^^^^^^^^^^^^^^^^^^^^^^^^^^^^^^^^^^^^^^^
  File "/home/airflow/.local/lib/python3.12/site-packages/airflow/models/taskinstance.py", line 733, in _execute_callable
    return ExecutionCallableRunner(
           ^^^^^^^^^^^^^^^^^^^^^^^^
  File "/home/airflow/.local/lib/python3.12/site-packages/airflow/utils/operator_helpers.py", line 252, in run
    return self.func(*args, **kwargs)
           ^^^^^^^^^^^^^^^^^^^^^^^^^^
  File "/home/airflow/.local/lib/python3.12/site-packages/airflow/models/baseoperator.py", line 422, in wrapper
    return func(self, *args, **kwargs)
           ^^^^^^^^^^^^^^^^^^^^^^^^^^^
  File "/home/airflow/.local/lib/python3.12/site-packages/airflow/operators/bash.py", line 257, in execute
    result = self._run_inline_command(bash_path=bash_path, env=env)
             ^^^^^^^^^^^^^^^^^^^^^^^^^^^^^^^^^^^^^^^^^^^^^^^^^^^^^^
  File "/home/airflow/.local/lib/python3.12/site-packages/airflow/operators/bash.py", line 284, in _run_inline_command
    return self.subprocess_hook.run_command(
           ^^^^^^^^^^^^^^^^^^^^^^^^^^^^^^^^^
  File "/home/airflow/.local/lib/python3.12/site-packages/airflow/hooks/subprocess.py", line 104, in run_command
    for raw_line in iter(self.sub_process.stdout.readline, b""):
                    ^^^^^^^^^^^^^^^^^^^^^^^^^^^^^^^^^^^^^^^^^^^
  File "/home/airflow/.local/lib/python3.12/site-packages/airflow/models/taskinstance.py", line 3095, in signal_handler
    raise AirflowTaskTerminated("Task received SIGTERM signal")
airflow.exceptions.AirflowTaskTerminated: Task received SIGTERM signal

During handling of the above exception, another exception occurred:

Traceback (most recent call last):
  File "/home/airflow/.local/lib/python3.12/site-packages/sqlalchemy/engine/base.py", line 1910, in _execute_context
    self.dialect.do_execute(
  File "/home/airflow/.local/lib/python3.12/site-packages/sqlalchemy/engine/default.py", line 736, in do_execute
    cursor.execute(statement, parameters)
psycopg2.errors.ForeignKeyViolation: insert or update on table "task_fail" violates foreign key constraint "task_fail_ti_fkey"
DETAIL:  Key (dag_id, task_id, run_id, map_index)=(etl_reporte_como_vamos, task_bot_como_vamos, manual__2025-01-28T06:27:38.303126+00:00, -1) is not present in table "task_instance".


The above exception was the direct cause of the following exception:

Traceback (most recent call last):
  File "/home/airflow/.local/lib/python3.12/site-packages/airflow/task/task_runner/standard_task_runner.py", line 117, in _start_by_fork
    ret = args.func(args, dag=self.dag)
          ^^^^^^^^^^^^^^^^^^^^^^^^^^^^^
  File "/home/airflow/.local/lib/python3.12/site-packages/airflow/cli/cli_config.py", line 49, in command
    return func(*args, **kwargs)
           ^^^^^^^^^^^^^^^^^^^^^
  File "/home/airflow/.local/lib/python3.12/site-packages/airflow/utils/cli.py", line 116, in wrapper
    return f(*args, **kwargs)
           ^^^^^^^^^^^^^^^^^^
  File "/home/airflow/.local/lib/python3.12/site-packages/airflow/cli/commands/task_command.py", line 483, in task_run
    task_return_code = _run_task_by_selected_method(args, _dag, ti)
                       ^^^^^^^^^^^^^^^^^^^^^^^^^^^^^^^^^^^^^^^^^^^^
  File "/home/airflow/.local/lib/python3.12/site-packages/airflow/cli/commands/task_command.py", line 256, in _run_task_by_selected_method
    return _run_raw_task(args, ti)
           ^^^^^^^^^^^^^^^^^^^^^^^
  File "/home/airflow/.local/lib/python3.12/site-packages/airflow/cli/commands/task_command.py", line 341, in _run_raw_task
    return ti._run_raw_task(
           ^^^^^^^^^^^^^^^^^
  File "/home/airflow/.local/lib/python3.12/site-packages/airflow/utils/session.py", line 97, in wrapper
    return func(*args, session=session, **kwargs)
           ^^^^^^^^^^^^^^^^^^^^^^^^^^^^^^^^^^^^^^
  File "/home/airflow/.local/lib/python3.12/site-packages/airflow/models/taskinstance.py", line 3005, in _run_raw_task
    return _run_raw_task(
           ^^^^^^^^^^^^^^
  File "/home/airflow/.local/lib/python3.12/site-packages/airflow/models/taskinstance.py", line 327, in _run_raw_task
    ti.handle_failure(e, test_mode, context, session=session)
  File "/home/airflow/.local/lib/python3.12/site-packages/airflow/utils/session.py", line 94, in wrapper
    return func(*args, **kwargs)
           ^^^^^^^^^^^^^^^^^^^^^
  File "/home/airflow/.local/lib/python3.12/site-packages/airflow/models/taskinstance.py", line 3428, in handle_failure
    _handle_failure(
  File "/home/airflow/.local/lib/python3.12/site-packages/airflow/utils/session.py", line 94, in wrapper
    return func(*args, **kwargs)
           ^^^^^^^^^^^^^^^^^^^^^
  File "/home/airflow/.local/lib/python3.12/site-packages/airflow/api_internal/internal_api_call.py", line 166, in wrapper
    return func(*args, **kwargs)
           ^^^^^^^^^^^^^^^^^^^^^
  File "/home/airflow/.local/lib/python3.12/site-packages/airflow/models/taskinstance.py", line 1243, in _handle_failure
    TaskInstance.save_to_db(failure_context["ti"], session)
  File "/home/airflow/.local/lib/python3.12/site-packages/airflow/api_internal/internal_api_call.py", line 166, in wrapper
    return func(*args, **kwargs)
           ^^^^^^^^^^^^^^^^^^^^^
  File "/home/airflow/.local/lib/python3.12/site-packages/airflow/utils/session.py", line 94, in wrapper
    return func(*args, **kwargs)
           ^^^^^^^^^^^^^^^^^^^^^
  File "/home/airflow/.local/lib/python3.12/site-packages/airflow/models/taskinstance.py", line 3400, in save_to_db
    session.flush()
  File "/home/airflow/.local/lib/python3.12/site-packages/sqlalchemy/orm/session.py", line 3449, in flush
    self._flush(objects)
  File "/home/airflow/.local/lib/python3.12/site-packages/sqlalchemy/orm/session.py", line 3588, in _flush
    with util.safe_reraise():
         ^^^^^^^^^^^^^^^^^^^
  File "/home/airflow/.local/lib/python3.12/site-packages/sqlalchemy/util/langhelpers.py", line 70, in __exit__
    compat.raise_(
  File "/home/airflow/.local/lib/python3.12/site-packages/sqlalchemy/util/compat.py", line 211, in raise_
    raise exception
  File "/home/airflow/.local/lib/python3.12/site-packages/sqlalchemy/orm/session.py", line 3549, in _flush
    flush_context.execute()
  File "/home/airflow/.local/lib/python3.12/site-packages/sqlalchemy/orm/unitofwork.py", line 456, in execute
    rec.execute(self)
  File "/home/airflow/.local/lib/python3.12/site-packages/sqlalchemy/orm/unitofwork.py", line 630, in execute
    util.preloaded.orm_persistence.save_obj(
  File "/home/airflow/.local/lib/python3.12/site-packages/sqlalchemy/orm/persistence.py", line 245, in save_obj
    _emit_insert_statements(
  File "/home/airflow/.local/lib/python3.12/site-packages/sqlalchemy/orm/persistence.py", line 1238, in _emit_insert_statements
    result = connection._execute_20(
             ^^^^^^^^^^^^^^^^^^^^^^^
  File "/home/airflow/.local/lib/python3.12/site-packages/sqlalchemy/engine/base.py", line 1710, in _execute_20
    return meth(self, args_10style, kwargs_10style, execution_options)
           ^^^^^^^^^^^^^^^^^^^^^^^^^^^^^^^^^^^^^^^^^^^^^^^^^^^^^^^^^^^
  File "/home/airflow/.local/lib/python3.12/site-packages/sqlalchemy/sql/elements.py", line 334, in _execute_on_connection
    return connection._execute_clauseelement(
           ^^^^^^^^^^^^^^^^^^^^^^^^^^^^^^^^^^
  File "/home/airflow/.local/lib/python3.12/site-packages/sqlalchemy/engine/base.py", line 1577, in _execute_clauseelement
    ret = self._execute_context(
          ^^^^^^^^^^^^^^^^^^^^^^
  File "/home/airflow/.local/lib/python3.12/site-packages/sqlalchemy/engine/base.py", line 1953, in _execute_context
    self._handle_dbapi_exception(
  File "/home/airflow/.local/lib/python3.12/site-packages/sqlalchemy/engine/base.py", line 2134, in _handle_dbapi_exception
    util.raise_(
  File "/home/airflow/.local/lib/python3.12/site-packages/sqlalchemy/util/compat.py", line 211, in raise_
    raise exception
  File "/home/airflow/.local/lib/python3.12/site-packages/sqlalchemy/engine/base.py", line 1910, in _execute_context
    self.dialect.do_execute(
  File "/home/airflow/.local/lib/python3.12/site-packages/sqlalchemy/engine/default.py", line 736, in do_execute
    cursor.execute(statement, parameters)
sqlalchemy.exc.IntegrityError: (psycopg2.errors.ForeignKeyViolation) insert or update on table "task_fail" violates foreign key constraint "task_fail_ti_fkey"
DETAIL:  Key (dag_id, task_id, run_id, map_index)=(etl_reporte_como_vamos, task_bot_como_vamos, manual__2025-01-28T06:27:38.303126+00:00, -1) is not present in table "task_instance".

[SQL: INSERT INTO task_fail (task_id, dag_id, run_id, map_index, start_date, end_date, duration) VALUES (%(task_id)s, %(dag_id)s, %(run_id)s, %(map_index)s, %(start_date)s, %(end_date)s, %(duration)s) RETURNING task_fail.id]
[parameters: {'task_id': 'task_bot_como_vamos', 'dag_id': 'etl_reporte_como_vamos', 'run_id': 'manual__2025-01-28T06:27:38.303126+00:00', 'map_index': -1, 'start_date': datetime.datetime(2025, 1, 28, 6, 40, 41, 764403, tzinfo=Timezone('UTC')), 'end_date': datetime.datetime(2025, 1, 28, 6, 41, 38, 556496, tzinfo=Timezone('UTC')), 'duration': 56}]
(Background on this error at: https://sqlalche.me/e/14/gkpj)
[2025-01-28T06:41:39.298+0000] {process_utils.py:80} INFO - Process psutil.Process(pid=202, status='terminated', exitcode=1, started='06:40:41') (202) terminated with exit code 1
[2025-01-28T06:41:39.303+0000] {process_utils.py:80} INFO - Process psutil.Process(pid=206, status='terminated', started='06:40:42') (206) terminated with exit code None
