[2025-02-02T22:01:17.462-0500] {local_task_job_runner.py:123} INFO - ::group::Pre task execution logs
[2025-02-02T22:01:17.488-0500] {taskinstance.py:2613} INFO - Dependencies all met for dep_context=non-requeueable deps ti=<TaskInstance: etl_reporte_como_vamos.task_bot_como_vamos scheduled__2025-02-02T06:47:00+00:00 [queued]>
[2025-02-02T22:01:17.499-0500] {taskinstance.py:2613} INFO - Dependencies all met for dep_context=requeueable deps ti=<TaskInstance: etl_reporte_como_vamos.task_bot_como_vamos scheduled__2025-02-02T06:47:00+00:00 [queued]>
[2025-02-02T22:01:17.500-0500] {taskinstance.py:2866} INFO - Starting attempt 2 of 4
[2025-02-02T22:01:17.520-0500] {taskinstance.py:2889} INFO - Executing <Task(BashOperator): task_bot_como_vamos> on 2025-02-02 06:47:00+00:00
[2025-02-02T22:01:17.528-0500] {warnings.py:112} WARNING - /home/***/.local/lib/python3.12/site-packages/***/task/task_runner/standard_task_runner.py:70: DeprecationWarning: This process (pid=892) is multi-threaded, use of fork() may lead to deadlocks in the child.
  pid = os.fork()

[2025-02-02T22:01:17.530-0500] {standard_task_runner.py:72} INFO - Started process 893 to run task
[2025-02-02T22:01:17.531-0500] {standard_task_runner.py:104} INFO - Running: ['***', 'tasks', 'run', 'etl_reporte_como_vamos', 'task_bot_como_vamos', 'scheduled__2025-02-02T06:47:00+00:00', '--job-id', '15', '--raw', '--subdir', 'DAGS_FOLDER/etl_como_vamos_dag.py', '--cfg-path', '/tmp/tmpxcxj3_3c']
[2025-02-02T22:01:17.532-0500] {standard_task_runner.py:105} INFO - Job 15: Subtask task_bot_como_vamos
[2025-02-02T22:01:17.596-0500] {task_command.py:467} INFO - Running <TaskInstance: etl_reporte_como_vamos.task_bot_como_vamos scheduled__2025-02-02T06:47:00+00:00 [running]> on host 21f1c1b48730
[2025-02-02T22:01:17.687-0500] {taskinstance.py:3132} INFO - Exporting env vars: AIRFLOW_CTX_DAG_OWNER='***' AIRFLOW_CTX_DAG_ID='etl_reporte_como_vamos' AIRFLOW_CTX_TASK_ID='task_bot_como_vamos' AIRFLOW_CTX_EXECUTION_DATE='2025-02-02T06:47:00+00:00' AIRFLOW_CTX_TRY_NUMBER='2' AIRFLOW_CTX_DAG_RUN_ID='scheduled__2025-02-02T06:47:00+00:00'
[2025-02-02T22:01:17.689-0500] {taskinstance.py:731} INFO - ::endgroup::
[2025-02-02T22:01:17.710-0500] {subprocess.py:78} INFO - Tmp dir root location: /tmp
[2025-02-02T22:01:17.712-0500] {subprocess.py:88} INFO - Running command: ['/usr/bin/bash', '-c', 'python /opt/***/scripts/bot_reporte_como_vamos.py']
[2025-02-02T22:01:17.724-0500] {subprocess.py:99} INFO - Output:
[2025-02-02T22:01:20.791-0500] {subprocess.py:106} INFO - ic| hoy: datetime.date(2025, 2, 2)
[2025-02-02T22:01:20.792-0500] {subprocess.py:106} INFO -     fecha_inicio: datetime.date(2025, 2, 1)
[2025-02-02T22:01:20.824-0500] {subprocess.py:106} INFO - ic| start_date: '01/02/2025', end_date: '02/02/2025'
[2025-02-02T22:01:20.826-0500] {subprocess.py:106} INFO - 2025-02-02 22:01:20,824 - bot_como_vamos - INFO - Starting script bot_como_vamos.py
[2025-02-02T22:01:21.760-0500] {subprocess.py:106} INFO - 2025-02-02 22:01:21,759 - bot_como_vamos - INFO - Conexi√≥n al Selenium Hub establecida correctamente
[2025-02-02T22:02:00.105-0500] {subprocess.py:106} INFO - ic| login_success: <selenium.webdriver.remote.webelement.WebElement (session="e1f340e5bb3a7d3e9859bbfa82e6977e", element="f.753CC616B9C2603F9EC05ABF619A80F2.d.840F761C91E6FB866EEFC8172B1936F2.e.76")>
[2025-02-02T22:02:00.106-0500] {subprocess.py:106} INFO - 2025-02-02 22:02:00,104 - bot_como_vamos - INFO - Loging success
[2025-02-02T22:02:10.232-0500] {subprocess.py:106} INFO - 2025-02-02 22:02:10,232 - bot_como_vamos - INFO - Click in menu button successfully
[2025-02-02T22:02:20.373-0500] {subprocess.py:106} INFO - 2025-02-02 22:02:20,373 - bot_como_vamos - INFO - Input dates successfully
[2025-02-02T22:02:30.503-0500] {subprocess.py:106} INFO - 2025-02-02 22:02:30,503 - bot_como_vamos - INFO - Click in 'Empresas Y Negocios' successfully
[2025-02-02T22:02:40.621-0500] {subprocess.py:106} INFO - 2025-02-02 22:02:40,620 - assets - INFO - Waiting for download file...............
[2025-02-02T22:12:40.999-0500] {subprocess.py:106} INFO - Traceback (most recent call last):
[2025-02-02T22:12:41.008-0500] {subprocess.py:106} INFO -   File "/opt/***/scripts/bot_reporte_como_vamos.py", line 153, in <module>
[2025-02-02T22:12:41.009-0500] {subprocess.py:106} INFO -     if __name__=="__main__":
[2025-02-02T22:12:41.010-0500] {subprocess.py:106} INFO -         ^^^^^^
[2025-02-02T22:12:41.011-0500] {subprocess.py:106} INFO -   File "/opt/***/scripts/bot_reporte_como_vamos.py", line 149, in main
[2025-02-02T22:12:41.011-0500] {subprocess.py:106} INFO -     Exception("Failed download Reporte como_vamos.xlsx")
[2025-02-02T22:12:41.012-0500] {subprocess.py:106} INFO -     ^^^^^^^^^^^^^
[2025-02-02T22:12:41.013-0500] {subprocess.py:106} INFO -   File "/home/***/.local/lib/python3.12/site-packages/selenium/webdriver/remote/webdriver.py", line 589, in quit
[2025-02-02T22:12:41.014-0500] {subprocess.py:106} INFO -     self.execute(Command.QUIT)
[2025-02-02T22:12:41.014-0500] {subprocess.py:106} INFO -   File "/home/***/.local/lib/python3.12/site-packages/selenium/webdriver/remote/webdriver.py", line 429, in execute
[2025-02-02T22:12:41.015-0500] {subprocess.py:106} INFO -     self.error_handler.check_response(response)
[2025-02-02T22:12:41.016-0500] {subprocess.py:106} INFO -   File "/home/***/.local/lib/python3.12/site-packages/selenium/webdriver/remote/errorhandler.py", line 232, in check_response
[2025-02-02T22:12:41.016-0500] {subprocess.py:106} INFO -     raise exception_class(message, screen, stacktrace)
[2025-02-02T22:12:41.017-0500] {subprocess.py:106} INFO - selenium.common.exceptions.InvalidSessionIdException: Message: Unable to find session with ID: e1f340e5bb3a7d3e9859bbfa82e6977e
[2025-02-02T22:12:41.017-0500] {subprocess.py:106} INFO - Build info: version: '4.28.1', revision: '73f5ad48a2'
[2025-02-02T22:12:41.018-0500] {subprocess.py:106} INFO - System info: os.name: 'Linux', os.arch: 'amd64', os.version: '5.15.153.1-microsoft-standard-WSL2', java.version: '17.0.13'
[2025-02-02T22:12:41.019-0500] {subprocess.py:106} INFO - Driver info: driver.version: unknown
[2025-02-02T22:12:41.019-0500] {subprocess.py:106} INFO - Stacktrace:
[2025-02-02T22:12:41.020-0500] {subprocess.py:106} INFO - org.openqa.selenium.NoSuchSessionException: Unable to find session with ID: e1f340e5bb3a7d3e9859bbfa82e6977e
[2025-02-02T22:12:41.020-0500] {subprocess.py:106} INFO - Build info: version: '4.28.1', revision: '73f5ad48a2'
[2025-02-02T22:12:41.021-0500] {subprocess.py:106} INFO - System info: os.name: 'Linux', os.arch: 'amd64', os.version: '5.15.153.1-microsoft-standard-WSL2', java.version: '17.0.13'
[2025-02-02T22:12:41.022-0500] {subprocess.py:106} INFO - Driver info: driver.version: unknown
[2025-02-02T22:12:41.022-0500] {subprocess.py:106} INFO - 	at org.openqa.selenium.grid.sessionmap.local.LocalSessionMap.get(LocalSessionMap.java:117)
[2025-02-02T22:12:41.023-0500] {subprocess.py:106} INFO - 	at org.openqa.selenium.grid.sessionmap.SessionMap.getUri(SessionMap.java:84)
[2025-02-02T22:12:41.023-0500] {subprocess.py:106} INFO - 	at org.openqa.selenium.grid.router.HandleSession.lambda$loadSessionId$4(HandleSession.java:225)
[2025-02-02T22:12:41.024-0500] {subprocess.py:106} INFO - 	at org.openqa.selenium.grid.router.HandleSession.execute(HandleSession.java:182)
[2025-02-02T22:12:41.024-0500] {subprocess.py:106} INFO - 	at org.openqa.selenium.remote.http.Route$PredicatedRoute.handle(Route.java:397)
[2025-02-02T22:12:41.025-0500] {subprocess.py:106} INFO - 	at org.openqa.selenium.remote.http.Route.execute(Route.java:69)
[2025-02-02T22:12:41.025-0500] {subprocess.py:106} INFO - 	at org.openqa.selenium.remote.http.Route$CombinedRoute.handle(Route.java:360)
[2025-02-02T22:12:41.026-0500] {subprocess.py:106} INFO - 	at org.openqa.selenium.remote.http.Route.execute(Route.java:69)
[2025-02-02T22:12:41.026-0500] {subprocess.py:106} INFO - 	at org.openqa.selenium.grid.router.Router.execute(Router.java:89)
[2025-02-02T22:12:41.026-0500] {subprocess.py:106} INFO - 	at org.openqa.selenium.grid.web.EnsureSpecCompliantResponseHeaders.lambda$apply$0(EnsureSpecCompliantResponseHeaders.java:34)
[2025-02-02T22:12:41.027-0500] {subprocess.py:106} INFO - 	at org.openqa.selenium.remote.http.Filter$1.execute(Filter.java:63)
[2025-02-02T22:12:41.027-0500] {subprocess.py:106} INFO - 	at org.openqa.selenium.remote.http.Route$CombinedRoute.handle(Route.java:360)
[2025-02-02T22:12:41.028-0500] {subprocess.py:106} INFO - 	at org.openqa.selenium.remote.http.Route.execute(Route.java:69)
[2025-02-02T22:12:41.029-0500] {subprocess.py:106} INFO - 	at org.openqa.selenium.remote.AddWebDriverSpecHeaders.lambda$apply$0(AddWebDriverSpecHeaders.java:35)
[2025-02-02T22:12:41.029-0500] {subprocess.py:106} INFO - 	at org.openqa.selenium.remote.ErrorFilter.lambda$apply$0(ErrorFilter.java:44)
[2025-02-02T22:12:41.030-0500] {subprocess.py:106} INFO - 	at org.openqa.selenium.remote.http.Filter$1.execute(Filter.java:63)
[2025-02-02T22:12:41.030-0500] {subprocess.py:106} INFO - 	at org.openqa.selenium.remote.ErrorFilter.lambda$apply$0(ErrorFilter.java:44)
[2025-02-02T22:12:41.031-0500] {subprocess.py:106} INFO - 	at org.openqa.selenium.remote.http.Filter$1.execute(Filter.java:63)
[2025-02-02T22:12:41.031-0500] {subprocess.py:106} INFO - 	at org.openqa.selenium.netty.server.SeleniumHandler.lambda$channelRead0$0(SeleniumHandler.java:49)
[2025-02-02T22:12:41.032-0500] {subprocess.py:106} INFO - 	at java.base/java.util.concurrent.Executors$RunnableAdapter.call(Executors.java:539)
[2025-02-02T22:12:41.032-0500] {subprocess.py:106} INFO - 	at java.base/java.util.concurrent.FutureTask.run(FutureTask.java:264)
[2025-02-02T22:12:41.033-0500] {subprocess.py:106} INFO - 	at java.base/java.util.concurrent.ThreadPoolExecutor.runWorker(ThreadPoolExecutor.java:1136)
[2025-02-02T22:12:41.033-0500] {subprocess.py:106} INFO - 	at java.base/java.util.concurrent.ThreadPoolExecutor$Worker.run(ThreadPoolExecutor.java:635)
[2025-02-02T22:12:41.034-0500] {subprocess.py:106} INFO - 	at java.base/java.lang.Thread.run(Thread.java:840)
[2025-02-02T22:12:41.034-0500] {subprocess.py:106} INFO - 
[2025-02-02T22:12:41.638-0500] {subprocess.py:110} INFO - Command exited with return code 1
[2025-02-02T22:12:41.692-0500] {taskinstance.py:3311} ERROR - Task failed with exception
Traceback (most recent call last):
  File "/home/airflow/.local/lib/python3.12/site-packages/airflow/models/taskinstance.py", line 767, in _execute_task
    result = _execute_callable(context=context, **execute_callable_kwargs)
             ^^^^^^^^^^^^^^^^^^^^^^^^^^^^^^^^^^^^^^^^^^^^^^^^^^^^^^^^^^^^^
  File "/home/airflow/.local/lib/python3.12/site-packages/airflow/models/taskinstance.py", line 733, in _execute_callable
    return ExecutionCallableRunner(
           ^^^^^^^^^^^^^^^^^^^^^^^^
  File "/home/airflow/.local/lib/python3.12/site-packages/airflow/utils/operator_helpers.py", line 252, in run
    return self.func(*args, **kwargs)
           ^^^^^^^^^^^^^^^^^^^^^^^^^^
  File "/home/airflow/.local/lib/python3.12/site-packages/airflow/models/baseoperator.py", line 422, in wrapper
    return func(self, *args, **kwargs)
           ^^^^^^^^^^^^^^^^^^^^^^^^^^^
  File "/home/airflow/.local/lib/python3.12/site-packages/airflow/operators/bash.py", line 276, in execute
    raise AirflowException(
airflow.exceptions.AirflowException: Bash command failed. The command returned a non-zero exit code 1.
[2025-02-02T22:12:41.726-0500] {taskinstance.py:1225} INFO - Marking task as UP_FOR_RETRY. dag_id=etl_reporte_como_vamos, task_id=task_bot_como_vamos, run_id=scheduled__2025-02-02T06:47:00+00:00, execution_date=20250202T064700, start_date=20250203T030117, end_date=20250203T031241
[2025-02-02T22:12:41.772-0500] {taskinstance.py:340} INFO - ::group::Post task execution logs
[2025-02-02T22:12:41.774-0500] {standard_task_runner.py:124} ERROR - Failed to execute job 15 for task task_bot_como_vamos (Bash command failed. The command returned a non-zero exit code 1.; 893)
Traceback (most recent call last):
  File "/home/airflow/.local/lib/python3.12/site-packages/airflow/task/task_runner/standard_task_runner.py", line 117, in _start_by_fork
    ret = args.func(args, dag=self.dag)
          ^^^^^^^^^^^^^^^^^^^^^^^^^^^^^
  File "/home/airflow/.local/lib/python3.12/site-packages/airflow/cli/cli_config.py", line 49, in command
    return func(*args, **kwargs)
           ^^^^^^^^^^^^^^^^^^^^^
  File "/home/airflow/.local/lib/python3.12/site-packages/airflow/utils/cli.py", line 116, in wrapper
    return f(*args, **kwargs)
           ^^^^^^^^^^^^^^^^^^
  File "/home/airflow/.local/lib/python3.12/site-packages/airflow/cli/commands/task_command.py", line 483, in task_run
    task_return_code = _run_task_by_selected_method(args, _dag, ti)
                       ^^^^^^^^^^^^^^^^^^^^^^^^^^^^^^^^^^^^^^^^^^^^
  File "/home/airflow/.local/lib/python3.12/site-packages/airflow/cli/commands/task_command.py", line 256, in _run_task_by_selected_method
    return _run_raw_task(args, ti)
           ^^^^^^^^^^^^^^^^^^^^^^^
  File "/home/airflow/.local/lib/python3.12/site-packages/airflow/cli/commands/task_command.py", line 341, in _run_raw_task
    return ti._run_raw_task(
           ^^^^^^^^^^^^^^^^^
  File "/home/airflow/.local/lib/python3.12/site-packages/airflow/utils/session.py", line 97, in wrapper
    return func(*args, session=session, **kwargs)
           ^^^^^^^^^^^^^^^^^^^^^^^^^^^^^^^^^^^^^^
  File "/home/airflow/.local/lib/python3.12/site-packages/airflow/models/taskinstance.py", line 3005, in _run_raw_task
    return _run_raw_task(
           ^^^^^^^^^^^^^^
  File "/home/airflow/.local/lib/python3.12/site-packages/airflow/models/taskinstance.py", line 273, in _run_raw_task
    TaskInstance._execute_task_with_callbacks(
  File "/home/airflow/.local/lib/python3.12/site-packages/airflow/models/taskinstance.py", line 3159, in _execute_task_with_callbacks
    result = self._execute_task(context, task_orig)
             ^^^^^^^^^^^^^^^^^^^^^^^^^^^^^^^^^^^^^^
  File "/home/airflow/.local/lib/python3.12/site-packages/airflow/models/taskinstance.py", line 3183, in _execute_task
    return _execute_task(self, context, task_orig)
           ^^^^^^^^^^^^^^^^^^^^^^^^^^^^^^^^^^^^^^^
  File "/home/airflow/.local/lib/python3.12/site-packages/airflow/models/taskinstance.py", line 767, in _execute_task
    result = _execute_callable(context=context, **execute_callable_kwargs)
             ^^^^^^^^^^^^^^^^^^^^^^^^^^^^^^^^^^^^^^^^^^^^^^^^^^^^^^^^^^^^^
  File "/home/airflow/.local/lib/python3.12/site-packages/airflow/models/taskinstance.py", line 733, in _execute_callable
    return ExecutionCallableRunner(
           ^^^^^^^^^^^^^^^^^^^^^^^^
  File "/home/airflow/.local/lib/python3.12/site-packages/airflow/utils/operator_helpers.py", line 252, in run
    return self.func(*args, **kwargs)
           ^^^^^^^^^^^^^^^^^^^^^^^^^^
  File "/home/airflow/.local/lib/python3.12/site-packages/airflow/models/baseoperator.py", line 422, in wrapper
    return func(self, *args, **kwargs)
           ^^^^^^^^^^^^^^^^^^^^^^^^^^^
  File "/home/airflow/.local/lib/python3.12/site-packages/airflow/operators/bash.py", line 276, in execute
    raise AirflowException(
airflow.exceptions.AirflowException: Bash command failed. The command returned a non-zero exit code 1.
[2025-02-02T22:12:41.813-0500] {local_task_job_runner.py:266} INFO - Task exited with return code 1
[2025-02-02T22:12:41.859-0500] {taskinstance.py:3895} INFO - 0 downstream tasks scheduled from follow-on schedule check
[2025-02-02T22:12:41.862-0500] {local_task_job_runner.py:245} INFO - ::endgroup::
