[2025-01-30T00:57:22.602+0000] {local_task_job_runner.py:123} INFO - ::group::Pre task execution logs
[2025-01-30T00:57:22.674+0000] {taskinstance.py:2613} INFO - Dependencies all met for dep_context=non-requeueable deps ti=<TaskInstance: etl_reporte_como_vamos.task_bot_como_vamos manual__2025-01-30T00:57:20.027124+00:00 [queued]>
[2025-01-30T00:57:22.714+0000] {taskinstance.py:2613} INFO - Dependencies all met for dep_context=requeueable deps ti=<TaskInstance: etl_reporte_como_vamos.task_bot_como_vamos manual__2025-01-30T00:57:20.027124+00:00 [queued]>
[2025-01-30T00:57:22.723+0000] {taskinstance.py:2866} INFO - Starting attempt 1 of 2
[2025-01-30T00:57:22.862+0000] {taskinstance.py:2889} INFO - Executing <Task(BashOperator): task_bot_como_vamos> on 2025-01-30 00:57:20.027124+00:00
[2025-01-30T00:57:22.900+0000] {warnings.py:112} WARNING - /home/***/.local/lib/python3.12/site-packages/***/task/task_runner/standard_task_runner.py:70: DeprecationWarning: This process (pid=343) is multi-threaded, use of fork() may lead to deadlocks in the child.
  pid = os.fork()

[2025-01-30T00:57:22.925+0000] {standard_task_runner.py:72} INFO - Started process 344 to run task
[2025-01-30T00:57:22.920+0000] {standard_task_runner.py:104} INFO - Running: ['***', 'tasks', 'run', 'etl_reporte_como_vamos', 'task_bot_como_vamos', 'manual__2025-01-30T00:57:20.027124+00:00', '--job-id', '9', '--raw', '--subdir', 'DAGS_FOLDER/etl_como_vamos_dag.py', '--cfg-path', '/tmp/tmpod_t4607']
[2025-01-30T00:57:22.929+0000] {standard_task_runner.py:105} INFO - Job 9: Subtask task_bot_como_vamos
[2025-01-30T00:57:23.149+0000] {task_command.py:467} INFO - Running <TaskInstance: etl_reporte_como_vamos.task_bot_como_vamos manual__2025-01-30T00:57:20.027124+00:00 [running]> on host 438c87da0b60
[2025-01-30T00:57:23.382+0000] {taskinstance.py:3132} INFO - Exporting env vars: AIRFLOW_CTX_DAG_OWNER='***' AIRFLOW_CTX_DAG_ID='etl_reporte_como_vamos' AIRFLOW_CTX_TASK_ID='task_bot_como_vamos' AIRFLOW_CTX_EXECUTION_DATE='2025-01-30T00:57:20.027124+00:00' AIRFLOW_CTX_TRY_NUMBER='1' AIRFLOW_CTX_DAG_RUN_ID='manual__2025-01-30T00:57:20.027124+00:00'
[2025-01-30T00:57:23.386+0000] {taskinstance.py:731} INFO - ::endgroup::
[2025-01-30T00:57:23.426+0000] {subprocess.py:78} INFO - Tmp dir root location: /tmp
[2025-01-30T00:57:23.431+0000] {subprocess.py:88} INFO - Running command: ['/usr/bin/bash', '-c', 'python /opt/***/scripts/bot_reporte_como_vamos.py']
[2025-01-30T00:57:23.456+0000] {subprocess.py:99} INFO - Output:
[2025-01-30T00:57:27.460+0000] {subprocess.py:106} INFO - ic| start_date: '01/01/2025', end_date: '30/01/2025'
[2025-01-30T00:57:27.461+0000] {subprocess.py:106} INFO - 2025-01-30 00:57:27,460 - bot_como_vamos - INFO - Starting script bot_como_vamos.py
[2025-01-30T00:57:27.667+0000] {subprocess.py:106} INFO - 2025-01-30 00:57:27,666 - bot_como_vamos - INFO - Conexi√≥n al Selenium Hub establecida correctamente
[2025-01-30T00:58:19.047+0000] {subprocess.py:106} INFO - Traceback (most recent call last):
[2025-01-30T00:58:19.048+0000] {subprocess.py:106} INFO -   File "/opt/***/scripts/bot_reporte_como_vamos.py", line 168, in <module>
[2025-01-30T00:58:19.054+0000] {subprocess.py:106} INFO -     main()
[2025-01-30T00:58:19.055+0000] {subprocess.py:106} INFO -   File "/opt/***/scripts/bot_reporte_como_vamos.py", line 90, in main
[2025-01-30T00:58:19.059+0000] {subprocess.py:106} INFO -     username_field = wait.until(EC.presence_of_element_located((By.ID, "usuario")))
[2025-01-30T00:58:19.059+0000] {subprocess.py:106} INFO -                      ^^^^^^^^^^^^^^^^^^^^^^^^^^^^^^^^^^^^^^^^^^^^^^^^^^^^^^^^^^^^^^
[2025-01-30T00:58:19.060+0000] {subprocess.py:106} INFO -   File "/home/***/.local/lib/python3.12/site-packages/selenium/webdriver/support/wait.py", line 146, in until
[2025-01-30T00:58:19.061+0000] {subprocess.py:106} INFO -     raise TimeoutException(message, screen, stacktrace)
[2025-01-30T00:58:19.061+0000] {subprocess.py:106} INFO - selenium.common.exceptions.TimeoutException: Message:
[2025-01-30T00:58:19.062+0000] {subprocess.py:106} INFO - Stacktrace:
[2025-01-30T00:58:19.063+0000] {subprocess.py:106} INFO - #0 0x5555e005fdca <unknown>
[2025-01-30T00:58:19.063+0000] {subprocess.py:106} INFO - #1 0x5555dfb563f0 <unknown>
[2025-01-30T00:58:19.064+0000] {subprocess.py:106} INFO - #2 0x5555dfba610c <unknown>
[2025-01-30T00:58:19.064+0000] {subprocess.py:106} INFO - #3 0x5555dfba6331 <unknown>
[2025-01-30T00:58:19.064+0000] {subprocess.py:106} INFO - #4 0x5555dfbec154 <unknown>
[2025-01-30T00:58:19.065+0000] {subprocess.py:106} INFO - #5 0x5555dfbcaabd <unknown>
[2025-01-30T00:58:19.065+0000] {subprocess.py:106} INFO - #6 0x5555dfbe94b3 <unknown>
[2025-01-30T00:58:19.066+0000] {subprocess.py:106} INFO - #7 0x5555dfbca833 <unknown>
[2025-01-30T00:58:19.066+0000] {subprocess.py:106} INFO - #8 0x5555dfb975a0 <unknown>
[2025-01-30T00:58:19.067+0000] {subprocess.py:106} INFO - #9 0x5555dfb98ece <unknown>
[2025-01-30T00:58:19.067+0000] {subprocess.py:106} INFO - #10 0x5555e0029bdb <unknown>
[2025-01-30T00:58:19.068+0000] {subprocess.py:106} INFO - #11 0x5555e002db67 <unknown>
[2025-01-30T00:58:19.069+0000] {subprocess.py:106} INFO - #12 0x5555e00153bc <unknown>
[2025-01-30T00:58:19.069+0000] {subprocess.py:106} INFO - #13 0x5555e002e727 <unknown>
[2025-01-30T00:58:19.070+0000] {subprocess.py:106} INFO - #14 0x5555dfff974f <unknown>
[2025-01-30T00:58:19.070+0000] {subprocess.py:106} INFO - #15 0x5555e004e938 <unknown>
[2025-01-30T00:58:19.071+0000] {subprocess.py:106} INFO - #16 0x5555e004eb00 <unknown>
[2025-01-30T00:58:19.071+0000] {subprocess.py:106} INFO - #17 0x5555e005ec46 <unknown>
[2025-01-30T00:58:19.072+0000] {subprocess.py:106} INFO - #18 0x7f0b13611a94 <unknown>
[2025-01-30T00:58:19.073+0000] {subprocess.py:106} INFO - #19 0x7f0b1369ec3c <unknown>
[2025-01-30T00:58:19.073+0000] {subprocess.py:106} INFO - 
[2025-01-30T00:58:19.196+0000] {subprocess.py:110} INFO - Command exited with return code 1
[2025-01-30T00:58:19.211+0000] {taskinstance.py:3311} ERROR - Task failed with exception
Traceback (most recent call last):
  File "/home/airflow/.local/lib/python3.12/site-packages/airflow/models/taskinstance.py", line 767, in _execute_task
    result = _execute_callable(context=context, **execute_callable_kwargs)
             ^^^^^^^^^^^^^^^^^^^^^^^^^^^^^^^^^^^^^^^^^^^^^^^^^^^^^^^^^^^^^
  File "/home/airflow/.local/lib/python3.12/site-packages/airflow/models/taskinstance.py", line 733, in _execute_callable
    return ExecutionCallableRunner(
           ^^^^^^^^^^^^^^^^^^^^^^^^
  File "/home/airflow/.local/lib/python3.12/site-packages/airflow/utils/operator_helpers.py", line 252, in run
    return self.func(*args, **kwargs)
           ^^^^^^^^^^^^^^^^^^^^^^^^^^
  File "/home/airflow/.local/lib/python3.12/site-packages/airflow/models/baseoperator.py", line 422, in wrapper
    return func(self, *args, **kwargs)
           ^^^^^^^^^^^^^^^^^^^^^^^^^^^
  File "/home/airflow/.local/lib/python3.12/site-packages/airflow/operators/bash.py", line 276, in execute
    raise AirflowException(
airflow.exceptions.AirflowException: Bash command failed. The command returned a non-zero exit code 1.
[2025-01-30T00:58:19.223+0000] {taskinstance.py:1225} INFO - Marking task as UP_FOR_RETRY. dag_id=etl_reporte_como_vamos, task_id=task_bot_como_vamos, run_id=manual__2025-01-30T00:57:20.027124+00:00, execution_date=20250130T005720, start_date=20250130T005722, end_date=20250130T005819
[2025-01-30T00:58:19.251+0000] {taskinstance.py:340} INFO - ::group::Post task execution logs
[2025-01-30T00:58:19.253+0000] {standard_task_runner.py:124} ERROR - Failed to execute job 9 for task task_bot_como_vamos (Bash command failed. The command returned a non-zero exit code 1.; 344)
Traceback (most recent call last):
  File "/home/airflow/.local/lib/python3.12/site-packages/airflow/task/task_runner/standard_task_runner.py", line 117, in _start_by_fork
    ret = args.func(args, dag=self.dag)
          ^^^^^^^^^^^^^^^^^^^^^^^^^^^^^
  File "/home/airflow/.local/lib/python3.12/site-packages/airflow/cli/cli_config.py", line 49, in command
    return func(*args, **kwargs)
           ^^^^^^^^^^^^^^^^^^^^^
  File "/home/airflow/.local/lib/python3.12/site-packages/airflow/utils/cli.py", line 116, in wrapper
    return f(*args, **kwargs)
           ^^^^^^^^^^^^^^^^^^
  File "/home/airflow/.local/lib/python3.12/site-packages/airflow/cli/commands/task_command.py", line 483, in task_run
    task_return_code = _run_task_by_selected_method(args, _dag, ti)
                       ^^^^^^^^^^^^^^^^^^^^^^^^^^^^^^^^^^^^^^^^^^^^
  File "/home/airflow/.local/lib/python3.12/site-packages/airflow/cli/commands/task_command.py", line 256, in _run_task_by_selected_method
    return _run_raw_task(args, ti)
           ^^^^^^^^^^^^^^^^^^^^^^^
  File "/home/airflow/.local/lib/python3.12/site-packages/airflow/cli/commands/task_command.py", line 341, in _run_raw_task
    return ti._run_raw_task(
           ^^^^^^^^^^^^^^^^^
  File "/home/airflow/.local/lib/python3.12/site-packages/airflow/utils/session.py", line 97, in wrapper
    return func(*args, session=session, **kwargs)
           ^^^^^^^^^^^^^^^^^^^^^^^^^^^^^^^^^^^^^^
  File "/home/airflow/.local/lib/python3.12/site-packages/airflow/models/taskinstance.py", line 3005, in _run_raw_task
    return _run_raw_task(
           ^^^^^^^^^^^^^^
  File "/home/airflow/.local/lib/python3.12/site-packages/airflow/models/taskinstance.py", line 273, in _run_raw_task
    TaskInstance._execute_task_with_callbacks(
  File "/home/airflow/.local/lib/python3.12/site-packages/airflow/models/taskinstance.py", line 3159, in _execute_task_with_callbacks
    result = self._execute_task(context, task_orig)
             ^^^^^^^^^^^^^^^^^^^^^^^^^^^^^^^^^^^^^^
  File "/home/airflow/.local/lib/python3.12/site-packages/airflow/models/taskinstance.py", line 3183, in _execute_task
    return _execute_task(self, context, task_orig)
           ^^^^^^^^^^^^^^^^^^^^^^^^^^^^^^^^^^^^^^^
  File "/home/airflow/.local/lib/python3.12/site-packages/airflow/models/taskinstance.py", line 767, in _execute_task
    result = _execute_callable(context=context, **execute_callable_kwargs)
             ^^^^^^^^^^^^^^^^^^^^^^^^^^^^^^^^^^^^^^^^^^^^^^^^^^^^^^^^^^^^^
  File "/home/airflow/.local/lib/python3.12/site-packages/airflow/models/taskinstance.py", line 733, in _execute_callable
    return ExecutionCallableRunner(
           ^^^^^^^^^^^^^^^^^^^^^^^^
  File "/home/airflow/.local/lib/python3.12/site-packages/airflow/utils/operator_helpers.py", line 252, in run
    return self.func(*args, **kwargs)
           ^^^^^^^^^^^^^^^^^^^^^^^^^^
  File "/home/airflow/.local/lib/python3.12/site-packages/airflow/models/baseoperator.py", line 422, in wrapper
    return func(self, *args, **kwargs)
           ^^^^^^^^^^^^^^^^^^^^^^^^^^^
  File "/home/airflow/.local/lib/python3.12/site-packages/airflow/operators/bash.py", line 276, in execute
    raise AirflowException(
airflow.exceptions.AirflowException: Bash command failed. The command returned a non-zero exit code 1.
[2025-01-30T00:58:19.273+0000] {local_task_job_runner.py:266} INFO - Task exited with return code 1
[2025-01-30T00:58:19.292+0000] {taskinstance.py:3895} INFO - 0 downstream tasks scheduled from follow-on schedule check
[2025-01-30T00:58:19.296+0000] {local_task_job_runner.py:245} INFO - ::endgroup::
