[2025-01-30T03:58:20.248+0000] {local_task_job_runner.py:123} INFO - ::group::Pre task execution logs
[2025-01-30T03:58:20.305+0000] {taskinstance.py:2613} INFO - Dependencies all met for dep_context=non-requeueable deps ti=<TaskInstance: etl_reporte_como_vamos.task_bot_como_vamos manual__2025-01-30T03:58:17.967695+00:00 [queued]>
[2025-01-30T03:58:20.331+0000] {taskinstance.py:2613} INFO - Dependencies all met for dep_context=requeueable deps ti=<TaskInstance: etl_reporte_como_vamos.task_bot_como_vamos manual__2025-01-30T03:58:17.967695+00:00 [queued]>
[2025-01-30T03:58:20.333+0000] {taskinstance.py:2866} INFO - Starting attempt 1 of 1
[2025-01-30T03:58:20.379+0000] {taskinstance.py:2889} INFO - Executing <Task(BashOperator): task_bot_como_vamos> on 2025-01-30 03:58:17.967695+00:00
[2025-01-30T03:58:20.394+0000] {warnings.py:112} WARNING - /home/***/.local/lib/python3.12/site-packages/***/task/task_runner/standard_task_runner.py:70: DeprecationWarning: This process (pid=2782) is multi-threaded, use of fork() may lead to deadlocks in the child.
  pid = os.fork()

[2025-01-30T03:58:20.402+0000] {standard_task_runner.py:72} INFO - Started process 2783 to run task
[2025-01-30T03:58:20.402+0000] {standard_task_runner.py:104} INFO - Running: ['***', 'tasks', 'run', 'etl_reporte_como_vamos', 'task_bot_como_vamos', 'manual__2025-01-30T03:58:17.967695+00:00', '--job-id', '29', '--raw', '--subdir', 'DAGS_FOLDER/etl_como_vamos_dag.py', '--cfg-path', '/tmp/tmp_gwidu7i']
[2025-01-30T03:58:20.405+0000] {standard_task_runner.py:105} INFO - Job 29: Subtask task_bot_como_vamos
[2025-01-30T03:58:20.524+0000] {task_command.py:467} INFO - Running <TaskInstance: etl_reporte_como_vamos.task_bot_como_vamos manual__2025-01-30T03:58:17.967695+00:00 [running]> on host 438c87da0b60
[2025-01-30T03:58:20.720+0000] {taskinstance.py:3132} INFO - Exporting env vars: AIRFLOW_CTX_DAG_OWNER='***' AIRFLOW_CTX_DAG_ID='etl_reporte_como_vamos' AIRFLOW_CTX_TASK_ID='task_bot_como_vamos' AIRFLOW_CTX_EXECUTION_DATE='2025-01-30T03:58:17.967695+00:00' AIRFLOW_CTX_TRY_NUMBER='1' AIRFLOW_CTX_DAG_RUN_ID='manual__2025-01-30T03:58:17.967695+00:00'
[2025-01-30T03:58:20.722+0000] {taskinstance.py:731} INFO - ::endgroup::
[2025-01-30T03:58:20.757+0000] {subprocess.py:78} INFO - Tmp dir root location: /tmp
[2025-01-30T03:58:20.760+0000] {subprocess.py:88} INFO - Running command: ['/usr/bin/bash', '-c', 'python /opt/***/scripts/bot_reporte_como_vamos.py']
[2025-01-30T03:58:20.778+0000] {subprocess.py:99} INFO - Output:
[2025-01-30T03:58:25.292+0000] {subprocess.py:106} INFO - ic| start_date: '01/01/2025', end_date: '30/01/2025'
[2025-01-30T03:58:25.293+0000] {subprocess.py:106} INFO - 2025-01-30 03:58:25,292 - bot_como_vamos - INFO - Starting script bot_como_vamos.py
[2025-01-30T03:58:25.440+0000] {subprocess.py:106} INFO - 2025-01-30 03:58:25,439 - bot_como_vamos - INFO - Conexi√≥n al Selenium Hub establecida correctamente
[2025-01-30T03:59:00.388+0000] {subprocess.py:106} INFO - ic| login_success: <selenium.webdriver.remote.webelement.WebElement (session="b5a84817dc55b44458caee9bba54752e", element="f.438677B8203AF668C09F030121F0AF29.d.D73D1C629D273C5BE661695FBD95B390.e.76")>
[2025-01-30T03:59:00.389+0000] {subprocess.py:106} INFO - 2025-01-30 03:59:00,388 - bot_como_vamos - INFO - Loging success
[2025-01-30T03:59:10.454+0000] {subprocess.py:106} INFO - 2025-01-30 03:59:10,454 - bot_como_vamos - ERROR - Execution error bot_reporte_como_vamos.py:
[2025-01-30T03:59:10.455+0000] {subprocess.py:106} INFO -  Error type: InvalidSessionIdException
[2025-01-30T03:59:10.456+0000] {subprocess.py:106} INFO - Error message: Message: invalid session id: session deleted as the browser has closed the connection
[2025-01-30T03:59:10.456+0000] {subprocess.py:106} INFO - from disconnected: not connected to DevTools
[2025-01-30T03:59:10.457+0000] {subprocess.py:106} INFO -   (Session info: chrome=132.0.6834.110)
[2025-01-30T03:59:10.458+0000] {subprocess.py:106} INFO - Stacktrace:
[2025-01-30T03:59:10.459+0000] {subprocess.py:106} INFO - #0 0x56253d2cedca <unknown>
[2025-01-30T03:59:10.459+0000] {subprocess.py:106} INFO - #1 0x56253cdc53f0 <unknown>
[2025-01-30T03:59:10.460+0000] {subprocess.py:106} INFO - #2 0x56253cdac0b5 <unknown>
[2025-01-30T03:59:10.461+0000] {subprocess.py:106} INFO - #3 0x56253cdabf93 <unknown>
[2025-01-30T03:59:10.462+0000] {subprocess.py:106} INFO - #4 0x56253cdc7762 <unknown>
[2025-01-30T03:59:10.462+0000] {subprocess.py:106} INFO - #5 0x56253ce57e7f <unknown>
[2025-01-30T03:59:10.463+0000] {subprocess.py:106} INFO - #6 0x56253ce39833 <unknown>
[2025-01-30T03:59:10.464+0000] {subprocess.py:106} INFO - #7 0x56253ce065a0 <unknown>
[2025-01-30T03:59:10.465+0000] {subprocess.py:106} INFO - #8 0x56253ce07ece <unknown>
[2025-01-30T03:59:10.466+0000] {subprocess.py:106} INFO - #9 0x56253d298bdb <unknown>
[2025-01-30T03:59:10.467+0000] {subprocess.py:106} INFO - #10 0x56253d29cb67 <unknown>
[2025-01-30T03:59:10.467+0000] {subprocess.py:106} INFO - #11 0x56253d2843bc <unknown>
[2025-01-30T03:59:10.468+0000] {subprocess.py:106} INFO - #12 0x56253d29d727 <unknown>
[2025-01-30T03:59:10.469+0000] {subprocess.py:106} INFO - #13 0x56253d26874f <unknown>
[2025-01-30T03:59:10.469+0000] {subprocess.py:106} INFO - #14 0x56253d2bd938 <unknown>
[2025-01-30T03:59:10.470+0000] {subprocess.py:106} INFO - #15 0x56253d2bdb00 <unknown>
[2025-01-30T03:59:10.471+0000] {subprocess.py:106} INFO - #16 0x56253d2cdc46 <unknown>
[2025-01-30T03:59:10.472+0000] {subprocess.py:106} INFO - #17 0x7fe12772ba94 <unknown>
[2025-01-30T03:59:10.472+0000] {subprocess.py:106} INFO - #18 0x7fe1277b8c3c <unknown>
[2025-01-30T03:59:10.473+0000] {subprocess.py:106} INFO - 
[2025-01-30T03:59:10.474+0000] {subprocess.py:106} INFO - Full Traceback: Traceback (most recent call last):
[2025-01-30T03:59:10.474+0000] {subprocess.py:106} INFO -   File "/opt/***/scripts/bot_reporte_como_vamos.py", line 114, in main
[2025-01-30T03:59:10.475+0000] {subprocess.py:106} INFO -     menu_button = driver.find_element(By.XPATH, "/html/body/div[3]/nav/ul[2]/li[2]/a")
[2025-01-30T03:59:10.476+0000] {subprocess.py:106} INFO -                   ^^^^^^^^^^^^^^^^^^^^^^^^^^^^^^^^^^^^^^^^^^^^^^^^^^^^^^^^^^^^^^^^^^^^
[2025-01-30T03:59:10.477+0000] {subprocess.py:106} INFO -   File "/home/***/.local/lib/python3.12/site-packages/selenium/webdriver/remote/webdriver.py", line 888, in find_element
[2025-01-30T03:59:10.478+0000] {subprocess.py:106} INFO -     return self.execute(Command.FIND_ELEMENT, {"using": by, "value": value})["value"]
[2025-01-30T03:59:10.479+0000] {subprocess.py:106} INFO -            ^^^^^^^^^^^^^^^^^^^^^^^^^^^^^^^^^^^^^^^^^^^^^^^^^^^^^^^^^^^^^^^^^
[2025-01-30T03:59:10.480+0000] {subprocess.py:106} INFO -   File "/home/***/.local/lib/python3.12/site-packages/selenium/webdriver/remote/webdriver.py", line 429, in execute
[2025-01-30T03:59:10.481+0000] {subprocess.py:106} INFO -     self.error_handler.check_response(response)
[2025-01-30T03:59:10.482+0000] {subprocess.py:106} INFO -   File "/home/***/.local/lib/python3.12/site-packages/selenium/webdriver/remote/errorhandler.py", line 232, in check_response
[2025-01-30T03:59:10.483+0000] {subprocess.py:106} INFO -     raise exception_class(message, screen, stacktrace)
[2025-01-30T03:59:10.484+0000] {subprocess.py:106} INFO - selenium.common.exceptions.InvalidSessionIdException: Message: invalid session id: session deleted as the browser has closed the connection
[2025-01-30T03:59:10.485+0000] {subprocess.py:106} INFO - from disconnected: not connected to DevTools
[2025-01-30T03:59:10.485+0000] {subprocess.py:106} INFO -   (Session info: chrome=132.0.6834.110)
[2025-01-30T03:59:10.486+0000] {subprocess.py:106} INFO - Stacktrace:
[2025-01-30T03:59:10.487+0000] {subprocess.py:106} INFO - #0 0x56253d2cedca <unknown>
[2025-01-30T03:59:10.487+0000] {subprocess.py:106} INFO - #1 0x56253cdc53f0 <unknown>
[2025-01-30T03:59:10.488+0000] {subprocess.py:106} INFO - #2 0x56253cdac0b5 <unknown>
[2025-01-30T03:59:10.488+0000] {subprocess.py:106} INFO - #3 0x56253cdabf93 <unknown>
[2025-01-30T03:59:10.488+0000] {subprocess.py:106} INFO - #4 0x56253cdc7762 <unknown>
[2025-01-30T03:59:10.489+0000] {subprocess.py:106} INFO - #5 0x56253ce57e7f <unknown>
[2025-01-30T03:59:10.489+0000] {subprocess.py:106} INFO - #6 0x56253ce39833 <unknown>
[2025-01-30T03:59:10.490+0000] {subprocess.py:106} INFO - #7 0x56253ce065a0 <unknown>
[2025-01-30T03:59:10.490+0000] {subprocess.py:106} INFO - #8 0x56253ce07ece <unknown>
[2025-01-30T03:59:10.491+0000] {subprocess.py:106} INFO - #9 0x56253d298bdb <unknown>
[2025-01-30T03:59:10.492+0000] {subprocess.py:106} INFO - #10 0x56253d29cb67 <unknown>
[2025-01-30T03:59:10.492+0000] {subprocess.py:106} INFO - #11 0x56253d2843bc <unknown>
[2025-01-30T03:59:10.493+0000] {subprocess.py:106} INFO - #12 0x56253d29d727 <unknown>
[2025-01-30T03:59:10.493+0000] {subprocess.py:106} INFO - #13 0x56253d26874f <unknown>
[2025-01-30T03:59:10.494+0000] {subprocess.py:106} INFO - #14 0x56253d2bd938 <unknown>
[2025-01-30T03:59:10.494+0000] {subprocess.py:106} INFO - #15 0x56253d2bdb00 <unknown>
[2025-01-30T03:59:10.495+0000] {subprocess.py:106} INFO - #16 0x56253d2cdc46 <unknown>
[2025-01-30T03:59:10.495+0000] {subprocess.py:106} INFO - #17 0x7fe12772ba94 <unknown>
[2025-01-30T03:59:10.496+0000] {subprocess.py:106} INFO - #18 0x7fe1277b8c3c <unknown>
[2025-01-30T03:59:10.496+0000] {subprocess.py:106} INFO - 
[2025-01-30T03:59:10.497+0000] {subprocess.py:106} INFO - 
[2025-01-30T03:59:10.498+0000] {subprocess.py:106} INFO - Traceback (most recent call last):
[2025-01-30T03:59:10.498+0000] {subprocess.py:106} INFO -   File "/opt/***/scripts/bot_reporte_como_vamos.py", line 173, in <module>
[2025-01-30T03:59:10.499+0000] {subprocess.py:106} INFO -     main()
[2025-01-30T03:59:10.500+0000] {subprocess.py:106} INFO -   File "/opt/***/scripts/bot_reporte_como_vamos.py", line 114, in main
[2025-01-30T03:59:10.500+0000] {subprocess.py:106} INFO -     menu_button = driver.find_element(By.XPATH, "/html/body/div[3]/nav/ul[2]/li[2]/a")
[2025-01-30T03:59:10.501+0000] {subprocess.py:106} INFO -                   ^^^^^^^^^^^^^^^^^^^^^^^^^^^^^^^^^^^^^^^^^^^^^^^^^^^^^^^^^^^^^^^^^^^^
[2025-01-30T03:59:10.502+0000] {subprocess.py:106} INFO -   File "/home/***/.local/lib/python3.12/site-packages/selenium/webdriver/remote/webdriver.py", line 888, in find_element
[2025-01-30T03:59:10.502+0000] {subprocess.py:106} INFO -     return self.execute(Command.FIND_ELEMENT, {"using": by, "value": value})["value"]
[2025-01-30T03:59:10.503+0000] {subprocess.py:106} INFO -            ^^^^^^^^^^^^^^^^^^^^^^^^^^^^^^^^^^^^^^^^^^^^^^^^^^^^^^^^^^^^^^^^^
[2025-01-30T03:59:10.503+0000] {subprocess.py:106} INFO -   File "/home/***/.local/lib/python3.12/site-packages/selenium/webdriver/remote/webdriver.py", line 429, in execute
[2025-01-30T03:59:10.504+0000] {subprocess.py:106} INFO -     self.error_handler.check_response(response)
[2025-01-30T03:59:10.505+0000] {subprocess.py:106} INFO -   File "/home/***/.local/lib/python3.12/site-packages/selenium/webdriver/remote/errorhandler.py", line 232, in check_response
[2025-01-30T03:59:10.505+0000] {subprocess.py:106} INFO -     raise exception_class(message, screen, stacktrace)
[2025-01-30T03:59:10.506+0000] {subprocess.py:106} INFO - selenium.common.exceptions.InvalidSessionIdException: Message: invalid session id: session deleted as the browser has closed the connection
[2025-01-30T03:59:10.507+0000] {subprocess.py:106} INFO - from disconnected: not connected to DevTools
[2025-01-30T03:59:10.508+0000] {subprocess.py:106} INFO -   (Session info: chrome=132.0.6834.110)
[2025-01-30T03:59:10.508+0000] {subprocess.py:106} INFO - Stacktrace:
[2025-01-30T03:59:10.509+0000] {subprocess.py:106} INFO - #0 0x56253d2cedca <unknown>
[2025-01-30T03:59:10.510+0000] {subprocess.py:106} INFO - #1 0x56253cdc53f0 <unknown>
[2025-01-30T03:59:10.511+0000] {subprocess.py:106} INFO - #2 0x56253cdac0b5 <unknown>
[2025-01-30T03:59:10.511+0000] {subprocess.py:106} INFO - #3 0x56253cdabf93 <unknown>
[2025-01-30T03:59:10.512+0000] {subprocess.py:106} INFO - #4 0x56253cdc7762 <unknown>
[2025-01-30T03:59:10.513+0000] {subprocess.py:106} INFO - #5 0x56253ce57e7f <unknown>
[2025-01-30T03:59:10.514+0000] {subprocess.py:106} INFO - #6 0x56253ce39833 <unknown>
[2025-01-30T03:59:10.515+0000] {subprocess.py:106} INFO - #7 0x56253ce065a0 <unknown>
[2025-01-30T03:59:10.515+0000] {subprocess.py:106} INFO - #8 0x56253ce07ece <unknown>
[2025-01-30T03:59:10.516+0000] {subprocess.py:106} INFO - #9 0x56253d298bdb <unknown>
[2025-01-30T03:59:10.517+0000] {subprocess.py:106} INFO - #10 0x56253d29cb67 <unknown>
[2025-01-30T03:59:10.518+0000] {subprocess.py:106} INFO - #11 0x56253d2843bc <unknown>
[2025-01-30T03:59:10.518+0000] {subprocess.py:106} INFO - #12 0x56253d29d727 <unknown>
[2025-01-30T03:59:10.519+0000] {subprocess.py:106} INFO - #13 0x56253d26874f <unknown>
[2025-01-30T03:59:10.520+0000] {subprocess.py:106} INFO - #14 0x56253d2bd938 <unknown>
[2025-01-30T03:59:10.521+0000] {subprocess.py:106} INFO - #15 0x56253d2bdb00 <unknown>
[2025-01-30T03:59:10.522+0000] {subprocess.py:106} INFO - #16 0x56253d2cdc46 <unknown>
[2025-01-30T03:59:10.523+0000] {subprocess.py:106} INFO - #17 0x7fe12772ba94 <unknown>
[2025-01-30T03:59:10.523+0000] {subprocess.py:106} INFO - #18 0x7fe1277b8c3c <unknown>
[2025-01-30T03:59:10.524+0000] {subprocess.py:106} INFO - 
[2025-01-30T03:59:10.602+0000] {subprocess.py:110} INFO - Command exited with return code 1
[2025-01-30T03:59:10.616+0000] {taskinstance.py:3311} ERROR - Task failed with exception
Traceback (most recent call last):
  File "/home/airflow/.local/lib/python3.12/site-packages/airflow/models/taskinstance.py", line 767, in _execute_task
    result = _execute_callable(context=context, **execute_callable_kwargs)
             ^^^^^^^^^^^^^^^^^^^^^^^^^^^^^^^^^^^^^^^^^^^^^^^^^^^^^^^^^^^^^
  File "/home/airflow/.local/lib/python3.12/site-packages/airflow/models/taskinstance.py", line 733, in _execute_callable
    return ExecutionCallableRunner(
           ^^^^^^^^^^^^^^^^^^^^^^^^
  File "/home/airflow/.local/lib/python3.12/site-packages/airflow/utils/operator_helpers.py", line 252, in run
    return self.func(*args, **kwargs)
           ^^^^^^^^^^^^^^^^^^^^^^^^^^
  File "/home/airflow/.local/lib/python3.12/site-packages/airflow/models/baseoperator.py", line 422, in wrapper
    return func(self, *args, **kwargs)
           ^^^^^^^^^^^^^^^^^^^^^^^^^^^
  File "/home/airflow/.local/lib/python3.12/site-packages/airflow/operators/bash.py", line 276, in execute
    raise AirflowException(
airflow.exceptions.AirflowException: Bash command failed. The command returned a non-zero exit code 1.
[2025-01-30T03:59:10.623+0000] {taskinstance.py:1225} INFO - Marking task as FAILED. dag_id=etl_reporte_como_vamos, task_id=task_bot_como_vamos, run_id=manual__2025-01-30T03:58:17.967695+00:00, execution_date=20250130T035817, start_date=20250130T035820, end_date=20250130T035910
[2025-01-30T03:59:10.653+0000] {taskinstance.py:340} INFO - ::group::Post task execution logs
[2025-01-30T03:59:10.654+0000] {standard_task_runner.py:124} ERROR - Failed to execute job 29 for task task_bot_como_vamos (Bash command failed. The command returned a non-zero exit code 1.; 2783)
Traceback (most recent call last):
  File "/home/airflow/.local/lib/python3.12/site-packages/airflow/task/task_runner/standard_task_runner.py", line 117, in _start_by_fork
    ret = args.func(args, dag=self.dag)
          ^^^^^^^^^^^^^^^^^^^^^^^^^^^^^
  File "/home/airflow/.local/lib/python3.12/site-packages/airflow/cli/cli_config.py", line 49, in command
    return func(*args, **kwargs)
           ^^^^^^^^^^^^^^^^^^^^^
  File "/home/airflow/.local/lib/python3.12/site-packages/airflow/utils/cli.py", line 116, in wrapper
    return f(*args, **kwargs)
           ^^^^^^^^^^^^^^^^^^
  File "/home/airflow/.local/lib/python3.12/site-packages/airflow/cli/commands/task_command.py", line 483, in task_run
    task_return_code = _run_task_by_selected_method(args, _dag, ti)
                       ^^^^^^^^^^^^^^^^^^^^^^^^^^^^^^^^^^^^^^^^^^^^
  File "/home/airflow/.local/lib/python3.12/site-packages/airflow/cli/commands/task_command.py", line 256, in _run_task_by_selected_method
    return _run_raw_task(args, ti)
           ^^^^^^^^^^^^^^^^^^^^^^^
  File "/home/airflow/.local/lib/python3.12/site-packages/airflow/cli/commands/task_command.py", line 341, in _run_raw_task
    return ti._run_raw_task(
           ^^^^^^^^^^^^^^^^^
  File "/home/airflow/.local/lib/python3.12/site-packages/airflow/utils/session.py", line 97, in wrapper
    return func(*args, session=session, **kwargs)
           ^^^^^^^^^^^^^^^^^^^^^^^^^^^^^^^^^^^^^^
  File "/home/airflow/.local/lib/python3.12/site-packages/airflow/models/taskinstance.py", line 3005, in _run_raw_task
    return _run_raw_task(
           ^^^^^^^^^^^^^^
  File "/home/airflow/.local/lib/python3.12/site-packages/airflow/models/taskinstance.py", line 273, in _run_raw_task
    TaskInstance._execute_task_with_callbacks(
  File "/home/airflow/.local/lib/python3.12/site-packages/airflow/models/taskinstance.py", line 3159, in _execute_task_with_callbacks
    result = self._execute_task(context, task_orig)
             ^^^^^^^^^^^^^^^^^^^^^^^^^^^^^^^^^^^^^^
  File "/home/airflow/.local/lib/python3.12/site-packages/airflow/models/taskinstance.py", line 3183, in _execute_task
    return _execute_task(self, context, task_orig)
           ^^^^^^^^^^^^^^^^^^^^^^^^^^^^^^^^^^^^^^^
  File "/home/airflow/.local/lib/python3.12/site-packages/airflow/models/taskinstance.py", line 767, in _execute_task
    result = _execute_callable(context=context, **execute_callable_kwargs)
             ^^^^^^^^^^^^^^^^^^^^^^^^^^^^^^^^^^^^^^^^^^^^^^^^^^^^^^^^^^^^^
  File "/home/airflow/.local/lib/python3.12/site-packages/airflow/models/taskinstance.py", line 733, in _execute_callable
    return ExecutionCallableRunner(
           ^^^^^^^^^^^^^^^^^^^^^^^^
  File "/home/airflow/.local/lib/python3.12/site-packages/airflow/utils/operator_helpers.py", line 252, in run
    return self.func(*args, **kwargs)
           ^^^^^^^^^^^^^^^^^^^^^^^^^^
  File "/home/airflow/.local/lib/python3.12/site-packages/airflow/models/baseoperator.py", line 422, in wrapper
    return func(self, *args, **kwargs)
           ^^^^^^^^^^^^^^^^^^^^^^^^^^^
  File "/home/airflow/.local/lib/python3.12/site-packages/airflow/operators/bash.py", line 276, in execute
    raise AirflowException(
airflow.exceptions.AirflowException: Bash command failed. The command returned a non-zero exit code 1.
[2025-01-30T03:59:10.684+0000] {local_task_job_runner.py:266} INFO - Task exited with return code 1
[2025-01-30T03:59:10.710+0000] {taskinstance.py:3895} INFO - 0 downstream tasks scheduled from follow-on schedule check
[2025-01-30T03:59:10.719+0000] {local_task_job_runner.py:245} INFO - ::endgroup::
