[2025-01-30T05:32:15.695+0000] {local_task_job_runner.py:123} INFO - ::group::Pre task execution logs
[2025-01-30T05:32:15.758+0000] {taskinstance.py:2613} INFO - Dependencies all met for dep_context=non-requeueable deps ti=<TaskInstance: etl_reporte_como_vamos.task_bot_como_vamos manual__2025-01-30T05:32:12.755274+00:00 [queued]>
[2025-01-30T05:32:15.784+0000] {taskinstance.py:2613} INFO - Dependencies all met for dep_context=requeueable deps ti=<TaskInstance: etl_reporte_como_vamos.task_bot_como_vamos manual__2025-01-30T05:32:12.755274+00:00 [queued]>
[2025-01-30T05:32:15.786+0000] {taskinstance.py:2866} INFO - Starting attempt 1 of 1
[2025-01-30T05:32:15.832+0000] {taskinstance.py:2889} INFO - Executing <Task(BashOperator): task_bot_como_vamos> on 2025-01-30 05:32:12.755274+00:00
[2025-01-30T05:32:15.846+0000] {warnings.py:112} WARNING - /home/***/.local/lib/python3.12/site-packages/***/task/task_runner/standard_task_runner.py:70: DeprecationWarning: This process (pid=93) is multi-threaded, use of fork() may lead to deadlocks in the child.
  pid = os.fork()

[2025-01-30T05:32:15.851+0000] {standard_task_runner.py:72} INFO - Started process 94 to run task
[2025-01-30T05:32:15.850+0000] {standard_task_runner.py:104} INFO - Running: ['***', 'tasks', 'run', 'etl_reporte_como_vamos', 'task_bot_como_vamos', 'manual__2025-01-30T05:32:12.755274+00:00', '--job-id', '37', '--raw', '--subdir', 'DAGS_FOLDER/etl_como_vamos_dag.py', '--cfg-path', '/tmp/tmp5_1t3xa8']
[2025-01-30T05:32:15.853+0000] {standard_task_runner.py:105} INFO - Job 37: Subtask task_bot_como_vamos
[2025-01-30T05:32:16.000+0000] {task_command.py:467} INFO - Running <TaskInstance: etl_reporte_como_vamos.task_bot_como_vamos manual__2025-01-30T05:32:12.755274+00:00 [running]> on host 8b55d0e14240
[2025-01-30T05:32:16.209+0000] {taskinstance.py:3132} INFO - Exporting env vars: AIRFLOW_CTX_DAG_OWNER='***' AIRFLOW_CTX_DAG_ID='etl_reporte_como_vamos' AIRFLOW_CTX_TASK_ID='task_bot_como_vamos' AIRFLOW_CTX_EXECUTION_DATE='2025-01-30T05:32:12.755274+00:00' AIRFLOW_CTX_TRY_NUMBER='1' AIRFLOW_CTX_DAG_RUN_ID='manual__2025-01-30T05:32:12.755274+00:00'
[2025-01-30T05:32:16.211+0000] {taskinstance.py:731} INFO - ::endgroup::
[2025-01-30T05:32:16.295+0000] {subprocess.py:78} INFO - Tmp dir root location: /tmp
[2025-01-30T05:32:16.299+0000] {subprocess.py:88} INFO - Running command: ['/usr/bin/bash', '-c', 'python /opt/***/scripts/bot_reporte_como_vamos.py']
[2025-01-30T05:32:16.319+0000] {subprocess.py:99} INFO - Output:
[2025-01-30T05:32:22.924+0000] {subprocess.py:106} INFO - ic| start_date: '01/01/2025', end_date: '30/01/2025'
[2025-01-30T05:32:22.925+0000] {subprocess.py:106} INFO - 2025-01-30 05:32:22,924 - bot_como_vamos - INFO - Starting script bot_como_vamos.py
[2025-01-30T05:32:25.279+0000] {subprocess.py:106} INFO - 2025-01-30 05:32:25,278 - bot_como_vamos - INFO - Conexi√≥n al Selenium Hub establecida correctamente
[2025-01-30T05:33:19.066+0000] {subprocess.py:106} INFO - ic| login_success: <selenium.webdriver.remote.webelement.WebElement (session="a4e84521944fb6e999ae30bccef0d5d2", element="f.3E5290BE7FD27BAE4D64220805E62C0E.d.72E1B321C276F3F787BE4E3CDCE741AB.e.76")>
[2025-01-30T05:33:19.069+0000] {subprocess.py:106} INFO - 2025-01-30 05:33:19,066 - bot_como_vamos - INFO - Loging success
[2025-01-30T05:33:29.248+0000] {subprocess.py:106} INFO - 2025-01-30 05:33:29,248 - bot_como_vamos - INFO - Click in menu button successfully
[2025-01-30T05:33:39.449+0000] {subprocess.py:106} INFO - 2025-01-30 05:33:39,449 - bot_como_vamos - INFO - Input dates successfully
[2025-01-30T05:33:49.727+0000] {subprocess.py:106} INFO - 2025-01-30 05:33:49,727 - bot_como_vamos - INFO - Click in 'Empresas Y Negocios' successfully
[2025-01-30T05:33:59.822+0000] {subprocess.py:106} INFO - 2025-01-30 05:33:59,822 - bot_como_vamos - ERROR - Execution error bot_reporte_como_vamos.py:
[2025-01-30T05:33:59.823+0000] {subprocess.py:106} INFO - ***Error type:*** ElementNotInteractableException
[2025-01-30T05:33:59.825+0000] {subprocess.py:106} INFO - ***Error message:*** Message: element not interactable
[2025-01-30T05:33:59.826+0000] {subprocess.py:106} INFO -   (Session info: chrome=132.0.6834.110)
[2025-01-30T05:33:59.827+0000] {subprocess.py:106} INFO - Stacktrace:
[2025-01-30T05:33:59.828+0000] {subprocess.py:106} INFO - #0 0x5605ac8d8dca <unknown>
[2025-01-30T05:33:59.829+0000] {subprocess.py:106} INFO - #1 0x5605ac3cf24d <unknown>
[2025-01-30T05:33:59.830+0000] {subprocess.py:106} INFO - #2 0x5605ac4202d9 <unknown>
[2025-01-30T05:33:59.831+0000] {subprocess.py:106} INFO - #3 0x5605ac4132bd <unknown>
[2025-01-30T05:33:59.832+0000] {subprocess.py:106} INFO - #4 0x5605ac443a92 <unknown>
[2025-01-30T05:33:59.835+0000] {subprocess.py:106} INFO - #5 0x5605ac412c48 <unknown>
[2025-01-30T05:33:59.836+0000] {subprocess.py:106} INFO - #6 0x5605ac443c5e <unknown>
[2025-01-30T05:33:59.837+0000] {subprocess.py:106} INFO - #7 0x5605ac4624b3 <unknown>
[2025-01-30T05:33:59.838+0000] {subprocess.py:106} INFO - #8 0x5605ac443833 <unknown>
[2025-01-30T05:33:59.839+0000] {subprocess.py:106} INFO - #9 0x5605ac4105a0 <unknown>
[2025-01-30T05:33:59.840+0000] {subprocess.py:106} INFO - #10 0x5605ac411ece <unknown>
[2025-01-30T05:33:59.841+0000] {subprocess.py:106} INFO - #11 0x5605ac8a2bdb <unknown>
[2025-01-30T05:33:59.842+0000] {subprocess.py:106} INFO - #12 0x5605ac8a6b67 <unknown>
[2025-01-30T05:33:59.843+0000] {subprocess.py:106} INFO - #13 0x5605ac88e3bc <unknown>
[2025-01-30T05:33:59.844+0000] {subprocess.py:106} INFO - #14 0x5605ac8a7727 <unknown>
[2025-01-30T05:33:59.845+0000] {subprocess.py:106} INFO - #15 0x5605ac87274f <unknown>
[2025-01-30T05:33:59.846+0000] {subprocess.py:106} INFO - #16 0x5605ac8c7938 <unknown>
[2025-01-30T05:33:59.847+0000] {subprocess.py:106} INFO - #17 0x5605ac8c7b00 <unknown>
[2025-01-30T05:33:59.848+0000] {subprocess.py:106} INFO - #18 0x5605ac8d7c46 <unknown>
[2025-01-30T05:33:59.849+0000] {subprocess.py:106} INFO - #19 0x7f1c6cb9ea94 <unknown>
[2025-01-30T05:33:59.850+0000] {subprocess.py:106} INFO - #20 0x7f1c6cc2bc3c <unknown>
[2025-01-30T05:33:59.851+0000] {subprocess.py:106} INFO - 
[2025-01-30T05:33:59.852+0000] {subprocess.py:106} INFO - ***Full Traceback:*** Traceback (most recent call last):
[2025-01-30T05:33:59.853+0000] {subprocess.py:106} INFO -   File "/opt/***/scripts/bot_reporte_como_vamos.py", line 137, in main
[2025-01-30T05:33:59.854+0000] {subprocess.py:106} INFO -     reporte_como_vamos.click()
[2025-01-30T05:33:59.856+0000] {subprocess.py:106} INFO -   File "/home/***/.local/lib/python3.12/site-packages/selenium/webdriver/remote/webelement.py", line 119, in click
[2025-01-30T05:33:59.857+0000] {subprocess.py:106} INFO -     self._execute(Command.CLICK_ELEMENT)
[2025-01-30T05:33:59.857+0000] {subprocess.py:106} INFO -   File "/home/***/.local/lib/python3.12/site-packages/selenium/webdriver/remote/webelement.py", line 570, in _execute
[2025-01-30T05:33:59.858+0000] {subprocess.py:106} INFO -     return self._parent.execute(command, params)
[2025-01-30T05:33:59.859+0000] {subprocess.py:106} INFO -            ^^^^^^^^^^^^^^^^^^^^^^^^^^^^^^^^^^^^^
[2025-01-30T05:33:59.860+0000] {subprocess.py:106} INFO -   File "/home/***/.local/lib/python3.12/site-packages/selenium/webdriver/remote/webdriver.py", line 429, in execute
[2025-01-30T05:33:59.861+0000] {subprocess.py:106} INFO -     self.error_handler.check_response(response)
[2025-01-30T05:33:59.862+0000] {subprocess.py:106} INFO -   File "/home/***/.local/lib/python3.12/site-packages/selenium/webdriver/remote/errorhandler.py", line 232, in check_response
[2025-01-30T05:33:59.863+0000] {subprocess.py:106} INFO -     raise exception_class(message, screen, stacktrace)
[2025-01-30T05:33:59.864+0000] {subprocess.py:106} INFO - selenium.common.exceptions.ElementNotInteractableException: Message: element not interactable
[2025-01-30T05:33:59.865+0000] {subprocess.py:106} INFO -   (Session info: chrome=132.0.6834.110)
[2025-01-30T05:33:59.866+0000] {subprocess.py:106} INFO - Stacktrace:
[2025-01-30T05:33:59.867+0000] {subprocess.py:106} INFO - #0 0x5605ac8d8dca <unknown>
[2025-01-30T05:33:59.868+0000] {subprocess.py:106} INFO - #1 0x5605ac3cf24d <unknown>
[2025-01-30T05:33:59.869+0000] {subprocess.py:106} INFO - #2 0x5605ac4202d9 <unknown>
[2025-01-30T05:33:59.869+0000] {subprocess.py:106} INFO - #3 0x5605ac4132bd <unknown>
[2025-01-30T05:33:59.870+0000] {subprocess.py:106} INFO - #4 0x5605ac443a92 <unknown>
[2025-01-30T05:33:59.871+0000] {subprocess.py:106} INFO - #5 0x5605ac412c48 <unknown>
[2025-01-30T05:33:59.872+0000] {subprocess.py:106} INFO - #6 0x5605ac443c5e <unknown>
[2025-01-30T05:33:59.873+0000] {subprocess.py:106} INFO - #7 0x5605ac4624b3 <unknown>
[2025-01-30T05:33:59.874+0000] {subprocess.py:106} INFO - #8 0x5605ac443833 <unknown>
[2025-01-30T05:33:59.875+0000] {subprocess.py:106} INFO - #9 0x5605ac4105a0 <unknown>
[2025-01-30T05:33:59.876+0000] {subprocess.py:106} INFO - #10 0x5605ac411ece <unknown>
[2025-01-30T05:33:59.877+0000] {subprocess.py:106} INFO - #11 0x5605ac8a2bdb <unknown>
[2025-01-30T05:33:59.878+0000] {subprocess.py:106} INFO - #12 0x5605ac8a6b67 <unknown>
[2025-01-30T05:33:59.879+0000] {subprocess.py:106} INFO - #13 0x5605ac88e3bc <unknown>
[2025-01-30T05:33:59.879+0000] {subprocess.py:106} INFO - #14 0x5605ac8a7727 <unknown>
[2025-01-30T05:33:59.881+0000] {subprocess.py:106} INFO - #15 0x5605ac87274f <unknown>
[2025-01-30T05:33:59.883+0000] {subprocess.py:106} INFO - #16 0x5605ac8c7938 <unknown>
[2025-01-30T05:33:59.884+0000] {subprocess.py:106} INFO - #17 0x5605ac8c7b00 <unknown>
[2025-01-30T05:33:59.886+0000] {subprocess.py:106} INFO - #18 0x5605ac8d7c46 <unknown>
[2025-01-30T05:33:59.887+0000] {subprocess.py:106} INFO - #19 0x7f1c6cb9ea94 <unknown>
[2025-01-30T05:33:59.888+0000] {subprocess.py:106} INFO - #20 0x7f1c6cc2bc3c <unknown>
[2025-01-30T05:33:59.890+0000] {subprocess.py:106} INFO - 
[2025-01-30T05:33:59.891+0000] {subprocess.py:106} INFO - 
[2025-01-30T05:33:59.892+0000] {subprocess.py:106} INFO - Traceback (most recent call last):
[2025-01-30T05:33:59.894+0000] {subprocess.py:106} INFO -   File "/opt/***/scripts/bot_reporte_como_vamos.py", line 173, in <module>
[2025-01-30T05:33:59.896+0000] {subprocess.py:106} INFO -     main()
[2025-01-30T05:33:59.897+0000] {subprocess.py:106} INFO -   File "/opt/***/scripts/bot_reporte_como_vamos.py", line 137, in main
[2025-01-30T05:33:59.899+0000] {subprocess.py:106} INFO -     reporte_como_vamos.click()
[2025-01-30T05:33:59.901+0000] {subprocess.py:106} INFO -   File "/home/***/.local/lib/python3.12/site-packages/selenium/webdriver/remote/webelement.py", line 119, in click
[2025-01-30T05:33:59.903+0000] {subprocess.py:106} INFO -     self._execute(Command.CLICK_ELEMENT)
[2025-01-30T05:33:59.904+0000] {subprocess.py:106} INFO -   File "/home/***/.local/lib/python3.12/site-packages/selenium/webdriver/remote/webelement.py", line 570, in _execute
[2025-01-30T05:33:59.905+0000] {subprocess.py:106} INFO -     return self._parent.execute(command, params)
[2025-01-30T05:33:59.907+0000] {subprocess.py:106} INFO -            ^^^^^^^^^^^^^^^^^^^^^^^^^^^^^^^^^^^^^
[2025-01-30T05:33:59.908+0000] {subprocess.py:106} INFO -   File "/home/***/.local/lib/python3.12/site-packages/selenium/webdriver/remote/webdriver.py", line 429, in execute
[2025-01-30T05:33:59.909+0000] {subprocess.py:106} INFO -     self.error_handler.check_response(response)
[2025-01-30T05:33:59.912+0000] {subprocess.py:106} INFO -   File "/home/***/.local/lib/python3.12/site-packages/selenium/webdriver/remote/errorhandler.py", line 232, in check_response
[2025-01-30T05:33:59.914+0000] {subprocess.py:106} INFO -     raise exception_class(message, screen, stacktrace)
[2025-01-30T05:33:59.916+0000] {subprocess.py:106} INFO - selenium.common.exceptions.ElementNotInteractableException: Message: element not interactable
[2025-01-30T05:33:59.924+0000] {subprocess.py:106} INFO -   (Session info: chrome=132.0.6834.110)
[2025-01-30T05:33:59.929+0000] {subprocess.py:106} INFO - Stacktrace:
[2025-01-30T05:33:59.933+0000] {subprocess.py:106} INFO - #0 0x5605ac8d8dca <unknown>
[2025-01-30T05:33:59.938+0000] {subprocess.py:106} INFO - #1 0x5605ac3cf24d <unknown>
[2025-01-30T05:33:59.944+0000] {subprocess.py:106} INFO - #2 0x5605ac4202d9 <unknown>
[2025-01-30T05:33:59.946+0000] {subprocess.py:106} INFO - #3 0x5605ac4132bd <unknown>
[2025-01-30T05:33:59.948+0000] {subprocess.py:106} INFO - #4 0x5605ac443a92 <unknown>
[2025-01-30T05:33:59.950+0000] {subprocess.py:106} INFO - #5 0x5605ac412c48 <unknown>
[2025-01-30T05:33:59.952+0000] {subprocess.py:106} INFO - #6 0x5605ac443c5e <unknown>
[2025-01-30T05:33:59.954+0000] {subprocess.py:106} INFO - #7 0x5605ac4624b3 <unknown>
[2025-01-30T05:33:59.956+0000] {subprocess.py:106} INFO - #8 0x5605ac443833 <unknown>
[2025-01-30T05:33:59.965+0000] {subprocess.py:106} INFO - #9 0x5605ac4105a0 <unknown>
[2025-01-30T05:33:59.966+0000] {subprocess.py:106} INFO - #10 0x5605ac411ece <unknown>
[2025-01-30T05:33:59.968+0000] {subprocess.py:106} INFO - #11 0x5605ac8a2bdb <unknown>
[2025-01-30T05:33:59.970+0000] {subprocess.py:106} INFO - #12 0x5605ac8a6b67 <unknown>
[2025-01-30T05:33:59.972+0000] {subprocess.py:106} INFO - #13 0x5605ac88e3bc <unknown>
[2025-01-30T05:33:59.978+0000] {subprocess.py:106} INFO - #14 0x5605ac8a7727 <unknown>
[2025-01-30T05:33:59.979+0000] {subprocess.py:106} INFO - #15 0x5605ac87274f <unknown>
[2025-01-30T05:33:59.981+0000] {subprocess.py:106} INFO - #16 0x5605ac8c7938 <unknown>
[2025-01-30T05:33:59.982+0000] {subprocess.py:106} INFO - #17 0x5605ac8c7b00 <unknown>
[2025-01-30T05:33:59.984+0000] {subprocess.py:106} INFO - #18 0x5605ac8d7c46 <unknown>
[2025-01-30T05:33:59.986+0000] {subprocess.py:106} INFO - #19 0x7f1c6cb9ea94 <unknown>
[2025-01-30T05:33:59.988+0000] {subprocess.py:106} INFO - #20 0x7f1c6cc2bc3c <unknown>
[2025-01-30T05:33:59.990+0000] {subprocess.py:106} INFO - 
[2025-01-30T05:34:00.316+0000] {subprocess.py:110} INFO - Command exited with return code 1
[2025-01-30T05:34:00.348+0000] {taskinstance.py:3311} ERROR - Task failed with exception
Traceback (most recent call last):
  File "/home/airflow/.local/lib/python3.12/site-packages/airflow/models/taskinstance.py", line 767, in _execute_task
    result = _execute_callable(context=context, **execute_callable_kwargs)
             ^^^^^^^^^^^^^^^^^^^^^^^^^^^^^^^^^^^^^^^^^^^^^^^^^^^^^^^^^^^^^
  File "/home/airflow/.local/lib/python3.12/site-packages/airflow/models/taskinstance.py", line 733, in _execute_callable
    return ExecutionCallableRunner(
           ^^^^^^^^^^^^^^^^^^^^^^^^
  File "/home/airflow/.local/lib/python3.12/site-packages/airflow/utils/operator_helpers.py", line 252, in run
    return self.func(*args, **kwargs)
           ^^^^^^^^^^^^^^^^^^^^^^^^^^
  File "/home/airflow/.local/lib/python3.12/site-packages/airflow/models/baseoperator.py", line 422, in wrapper
    return func(self, *args, **kwargs)
           ^^^^^^^^^^^^^^^^^^^^^^^^^^^
  File "/home/airflow/.local/lib/python3.12/site-packages/airflow/operators/bash.py", line 276, in execute
    raise AirflowException(
airflow.exceptions.AirflowException: Bash command failed. The command returned a non-zero exit code 1.
[2025-01-30T05:34:00.363+0000] {taskinstance.py:1225} INFO - Marking task as FAILED. dag_id=etl_reporte_como_vamos, task_id=task_bot_como_vamos, run_id=manual__2025-01-30T05:32:12.755274+00:00, execution_date=20250130T053212, start_date=20250130T053215, end_date=20250130T053400
[2025-01-30T05:34:00.414+0000] {taskinstance.py:340} INFO - ::group::Post task execution logs
[2025-01-30T05:34:00.416+0000] {standard_task_runner.py:124} ERROR - Failed to execute job 37 for task task_bot_como_vamos (Bash command failed. The command returned a non-zero exit code 1.; 94)
Traceback (most recent call last):
  File "/home/airflow/.local/lib/python3.12/site-packages/airflow/task/task_runner/standard_task_runner.py", line 117, in _start_by_fork
    ret = args.func(args, dag=self.dag)
          ^^^^^^^^^^^^^^^^^^^^^^^^^^^^^
  File "/home/airflow/.local/lib/python3.12/site-packages/airflow/cli/cli_config.py", line 49, in command
    return func(*args, **kwargs)
           ^^^^^^^^^^^^^^^^^^^^^
  File "/home/airflow/.local/lib/python3.12/site-packages/airflow/utils/cli.py", line 116, in wrapper
    return f(*args, **kwargs)
           ^^^^^^^^^^^^^^^^^^
  File "/home/airflow/.local/lib/python3.12/site-packages/airflow/cli/commands/task_command.py", line 483, in task_run
    task_return_code = _run_task_by_selected_method(args, _dag, ti)
                       ^^^^^^^^^^^^^^^^^^^^^^^^^^^^^^^^^^^^^^^^^^^^
  File "/home/airflow/.local/lib/python3.12/site-packages/airflow/cli/commands/task_command.py", line 256, in _run_task_by_selected_method
    return _run_raw_task(args, ti)
           ^^^^^^^^^^^^^^^^^^^^^^^
  File "/home/airflow/.local/lib/python3.12/site-packages/airflow/cli/commands/task_command.py", line 341, in _run_raw_task
    return ti._run_raw_task(
           ^^^^^^^^^^^^^^^^^
  File "/home/airflow/.local/lib/python3.12/site-packages/airflow/utils/session.py", line 97, in wrapper
    return func(*args, session=session, **kwargs)
           ^^^^^^^^^^^^^^^^^^^^^^^^^^^^^^^^^^^^^^
  File "/home/airflow/.local/lib/python3.12/site-packages/airflow/models/taskinstance.py", line 3005, in _run_raw_task
    return _run_raw_task(
           ^^^^^^^^^^^^^^
  File "/home/airflow/.local/lib/python3.12/site-packages/airflow/models/taskinstance.py", line 273, in _run_raw_task
    TaskInstance._execute_task_with_callbacks(
  File "/home/airflow/.local/lib/python3.12/site-packages/airflow/models/taskinstance.py", line 3159, in _execute_task_with_callbacks
    result = self._execute_task(context, task_orig)
             ^^^^^^^^^^^^^^^^^^^^^^^^^^^^^^^^^^^^^^
  File "/home/airflow/.local/lib/python3.12/site-packages/airflow/models/taskinstance.py", line 3183, in _execute_task
    return _execute_task(self, context, task_orig)
           ^^^^^^^^^^^^^^^^^^^^^^^^^^^^^^^^^^^^^^^
  File "/home/airflow/.local/lib/python3.12/site-packages/airflow/models/taskinstance.py", line 767, in _execute_task
    result = _execute_callable(context=context, **execute_callable_kwargs)
             ^^^^^^^^^^^^^^^^^^^^^^^^^^^^^^^^^^^^^^^^^^^^^^^^^^^^^^^^^^^^^
  File "/home/airflow/.local/lib/python3.12/site-packages/airflow/models/taskinstance.py", line 733, in _execute_callable
    return ExecutionCallableRunner(
           ^^^^^^^^^^^^^^^^^^^^^^^^
  File "/home/airflow/.local/lib/python3.12/site-packages/airflow/utils/operator_helpers.py", line 252, in run
    return self.func(*args, **kwargs)
           ^^^^^^^^^^^^^^^^^^^^^^^^^^
  File "/home/airflow/.local/lib/python3.12/site-packages/airflow/models/baseoperator.py", line 422, in wrapper
    return func(self, *args, **kwargs)
           ^^^^^^^^^^^^^^^^^^^^^^^^^^^
  File "/home/airflow/.local/lib/python3.12/site-packages/airflow/operators/bash.py", line 276, in execute
    raise AirflowException(
airflow.exceptions.AirflowException: Bash command failed. The command returned a non-zero exit code 1.
[2025-01-30T05:34:00.450+0000] {local_task_job_runner.py:266} INFO - Task exited with return code 1
[2025-01-30T05:34:00.508+0000] {taskinstance.py:3895} INFO - 0 downstream tasks scheduled from follow-on schedule check
[2025-01-30T05:34:00.518+0000] {local_task_job_runner.py:245} INFO - ::endgroup::
