[2025-02-13T06:47:27.506-0500] {local_task_job_runner.py:123} INFO - ::group::Pre task execution logs
[2025-02-13T06:47:27.531-0500] {taskinstance.py:2613} INFO - Dependencies all met for dep_context=non-requeueable deps ti=<TaskInstance: etl_reporte_como_vamos.bot_ex_bbva scheduled__2025-02-12T11:30:00+00:00 [queued]>
[2025-02-13T06:47:27.543-0500] {taskinstance.py:2613} INFO - Dependencies all met for dep_context=requeueable deps ti=<TaskInstance: etl_reporte_como_vamos.bot_ex_bbva scheduled__2025-02-12T11:30:00+00:00 [queued]>
[2025-02-13T06:47:27.544-0500] {taskinstance.py:2866} INFO - Starting attempt 4 of 4
[2025-02-13T06:47:27.564-0500] {taskinstance.py:2889} INFO - Executing <Task(BashOperator): bot_ex_bbva> on 2025-02-12 11:30:00+00:00
[2025-02-13T06:47:27.573-0500] {standard_task_runner.py:104} INFO - Running: ['***', 'tasks', 'run', 'etl_reporte_como_vamos', 'bot_ex_bbva', 'scheduled__2025-02-12T11:30:00+00:00', '--job-id', '110', '--raw', '--subdir', 'DAGS_FOLDER/etl_como_vamos_dag.py', '--cfg-path', '/tmp/tmpca2nqdt0']
[2025-02-13T06:47:27.573-0500] {warnings.py:112} WARNING - /home/***/.local/lib/python3.12/site-packages/***/task/task_runner/standard_task_runner.py:70: DeprecationWarning: This process (pid=43449) is multi-threaded, use of fork() may lead to deadlocks in the child.
  pid = os.fork()

[2025-02-13T06:47:27.575-0500] {standard_task_runner.py:105} INFO - Job 110: Subtask bot_ex_bbva
[2025-02-13T06:47:27.576-0500] {standard_task_runner.py:72} INFO - Started process 43450 to run task
[2025-02-13T06:47:27.630-0500] {task_command.py:467} INFO - Running <TaskInstance: etl_reporte_como_vamos.bot_ex_bbva scheduled__2025-02-12T11:30:00+00:00 [running]> on host 21f1c1b48730
[2025-02-13T06:47:27.726-0500] {taskinstance.py:3132} INFO - Exporting env vars: AIRFLOW_CTX_DAG_OWNER='***' AIRFLOW_CTX_DAG_ID='etl_reporte_como_vamos' AIRFLOW_CTX_TASK_ID='bot_ex_bbva' AIRFLOW_CTX_EXECUTION_DATE='2025-02-12T11:30:00+00:00' AIRFLOW_CTX_TRY_NUMBER='4' AIRFLOW_CTX_DAG_RUN_ID='scheduled__2025-02-12T11:30:00+00:00'
[2025-02-13T06:47:27.727-0500] {taskinstance.py:731} INFO - ::endgroup::
[2025-02-13T06:47:27.746-0500] {subprocess.py:78} INFO - Tmp dir root location: /tmp
[2025-02-13T06:47:27.747-0500] {subprocess.py:88} INFO - Running command: ['/usr/bin/bash', '-c', 'python /opt/***/scripts/bot_etl_ex_bbva.py']
[2025-02-13T06:47:27.761-0500] {subprocess.py:99} INFO - Output:
[2025-02-13T06:47:28.850-0500] {subprocess.py:106} INFO - 2025-02-13 06:47:28,850 - bot_etl_ex_bbva - INFO - Bot ETL Exito-BBVA started
[2025-02-13T06:47:29.477-0500] {subprocess.py:106} INFO - 2025-02-13 06:47:29,477 - bot_etl_ex_bbva - INFO - Conexi√≥n al Selenium Hub establecida correctamente
[2025-02-13T06:47:30.423-0500] {subprocess.py:106} INFO - 2025-02-13 06:47:30,423 - bot_etl_ex_bbva - INFO - Credentials input success
[2025-02-13T06:47:31.972-0500] {subprocess.py:106} INFO - 2025-02-13 06:47:31,972 - bot_etl_ex_bbva - INFO - Click in login button
[2025-02-13T06:47:41.996-0500] {subprocess.py:106} INFO - 2025-02-13 06:47:41,996 - bot_etl_ex_bbva - INFO - Loging success
[2025-02-13T06:47:42.235-0500] {subprocess.py:106} INFO - 2025-02-13 06:47:42,235 - bot_etl_ex_bbva - ERROR - Error Loading Cerrados.xlsx to ETL:
[2025-02-13T06:47:42.236-0500] {subprocess.py:106} INFO - ***Error type:*** ElementNotInteractableException
[2025-02-13T06:47:42.237-0500] {subprocess.py:106} INFO - ***Error message:*** Message: element not interactable
[2025-02-13T06:47:42.238-0500] {subprocess.py:106} INFO -   (Session info: chrome=132.0.6834.110)
[2025-02-13T06:47:42.238-0500] {subprocess.py:106} INFO - Stacktrace:
[2025-02-13T06:47:42.239-0500] {subprocess.py:106} INFO - #0 0x562ca9e8adca <unknown>
[2025-02-13T06:47:42.240-0500] {subprocess.py:106} INFO - #1 0x562ca998124d <unknown>
[2025-02-13T06:47:42.240-0500] {subprocess.py:106} INFO - #2 0x562ca99d22d9 <unknown>
[2025-02-13T06:47:42.241-0500] {subprocess.py:106} INFO - #3 0x562ca99c52bd <unknown>
[2025-02-13T06:47:42.241-0500] {subprocess.py:106} INFO - #4 0x562ca99f5a92 <unknown>
[2025-02-13T06:47:42.242-0500] {subprocess.py:106} INFO - #5 0x562ca99c4c48 <unknown>
[2025-02-13T06:47:42.242-0500] {subprocess.py:106} INFO - #6 0x562ca99f5c5e <unknown>
[2025-02-13T06:47:42.243-0500] {subprocess.py:106} INFO - #7 0x562ca9a144b3 <unknown>
[2025-02-13T06:47:42.243-0500] {subprocess.py:106} INFO - #8 0x562ca99f5833 <unknown>
[2025-02-13T06:47:42.244-0500] {subprocess.py:106} INFO - #9 0x562ca99c25a0 <unknown>
[2025-02-13T06:47:42.244-0500] {subprocess.py:106} INFO - #10 0x562ca99c3ece <unknown>
[2025-02-13T06:47:42.245-0500] {subprocess.py:106} INFO - #11 0x562ca9e54bdb <unknown>
[2025-02-13T06:47:42.245-0500] {subprocess.py:106} INFO - #12 0x562ca9e58b67 <unknown>
[2025-02-13T06:47:42.246-0500] {subprocess.py:106} INFO - #13 0x562ca9e403bc <unknown>
[2025-02-13T06:47:42.246-0500] {subprocess.py:106} INFO - #14 0x562ca9e59727 <unknown>
[2025-02-13T06:47:42.247-0500] {subprocess.py:106} INFO - #15 0x562ca9e2474f <unknown>
[2025-02-13T06:47:42.247-0500] {subprocess.py:106} INFO - #16 0x562ca9e79938 <unknown>
[2025-02-13T06:47:42.248-0500] {subprocess.py:106} INFO - #17 0x562ca9e79b00 <unknown>
[2025-02-13T06:47:42.248-0500] {subprocess.py:106} INFO - #18 0x562ca9e89c46 <unknown>
[2025-02-13T06:47:42.249-0500] {subprocess.py:106} INFO - #19 0x7f597ec8ca94 <unknown>
[2025-02-13T06:47:42.249-0500] {subprocess.py:106} INFO - #20 0x7f597ed19c3c <unknown>
[2025-02-13T06:47:42.250-0500] {subprocess.py:106} INFO - 
[2025-02-13T06:47:42.250-0500] {subprocess.py:106} INFO - ***Full Traceback:*** Traceback (most recent call last):
[2025-02-13T06:47:42.250-0500] {subprocess.py:106} INFO -   File "/opt/***/scripts/bot_etl_ex_bbva.py", line 105, in main
[2025-02-13T06:47:42.251-0500] {subprocess.py:106} INFO -     up_button.click()
[2025-02-13T06:47:42.252-0500] {subprocess.py:106} INFO -   File "/home/***/.local/lib/python3.12/site-packages/selenium/webdriver/remote/webelement.py", line 119, in click
[2025-02-13T06:47:42.252-0500] {subprocess.py:106} INFO -     self._execute(Command.CLICK_ELEMENT)
[2025-02-13T06:47:42.253-0500] {subprocess.py:106} INFO -   File "/home/***/.local/lib/python3.12/site-packages/selenium/webdriver/remote/webelement.py", line 570, in _execute
[2025-02-13T06:47:42.254-0500] {subprocess.py:106} INFO -     return self._parent.execute(command, params)
[2025-02-13T06:47:42.254-0500] {subprocess.py:106} INFO -            ^^^^^^^^^^^^^^^^^^^^^^^^^^^^^^^^^^^^^
[2025-02-13T06:47:42.255-0500] {subprocess.py:106} INFO -   File "/home/***/.local/lib/python3.12/site-packages/selenium/webdriver/remote/webdriver.py", line 429, in execute
[2025-02-13T06:47:42.255-0500] {subprocess.py:106} INFO -     self.error_handler.check_response(response)
[2025-02-13T06:47:42.255-0500] {subprocess.py:106} INFO -   File "/home/***/.local/lib/python3.12/site-packages/selenium/webdriver/remote/errorhandler.py", line 232, in check_response
[2025-02-13T06:47:42.256-0500] {subprocess.py:106} INFO -     raise exception_class(message, screen, stacktrace)
[2025-02-13T06:47:42.256-0500] {subprocess.py:106} INFO - selenium.common.exceptions.ElementNotInteractableException: Message: element not interactable
[2025-02-13T06:47:42.257-0500] {subprocess.py:106} INFO -   (Session info: chrome=132.0.6834.110)
[2025-02-13T06:47:42.257-0500] {subprocess.py:106} INFO - Stacktrace:
[2025-02-13T06:47:42.258-0500] {subprocess.py:106} INFO - #0 0x562ca9e8adca <unknown>
[2025-02-13T06:47:42.258-0500] {subprocess.py:106} INFO - #1 0x562ca998124d <unknown>
[2025-02-13T06:47:42.259-0500] {subprocess.py:106} INFO - #2 0x562ca99d22d9 <unknown>
[2025-02-13T06:47:42.259-0500] {subprocess.py:106} INFO - #3 0x562ca99c52bd <unknown>
[2025-02-13T06:47:42.264-0500] {subprocess.py:106} INFO - #4 0x562ca99f5a92 <unknown>
[2025-02-13T06:47:42.268-0500] {subprocess.py:106} INFO - #5 0x562ca99c4c48 <unknown>
[2025-02-13T06:47:42.269-0500] {subprocess.py:106} INFO - #6 0x562ca99f5c5e <unknown>
[2025-02-13T06:47:42.270-0500] {subprocess.py:106} INFO - #7 0x562ca9a144b3 <unknown>
[2025-02-13T06:47:42.271-0500] {subprocess.py:106} INFO - #8 0x562ca99f5833 <unknown>
[2025-02-13T06:47:42.271-0500] {subprocess.py:106} INFO - #9 0x562ca99c25a0 <unknown>
[2025-02-13T06:47:42.273-0500] {subprocess.py:106} INFO - #10 0x562ca99c3ece <unknown>
[2025-02-13T06:47:42.277-0500] {subprocess.py:106} INFO - #11 0x562ca9e54bdb <unknown>
[2025-02-13T06:47:42.278-0500] {subprocess.py:106} INFO - #12 0x562ca9e58b67 <unknown>
[2025-02-13T06:47:42.278-0500] {subprocess.py:106} INFO - #13 0x562ca9e403bc <unknown>
[2025-02-13T06:47:42.279-0500] {subprocess.py:106} INFO - #14 0x562ca9e59727 <unknown>
[2025-02-13T06:47:42.280-0500] {subprocess.py:106} INFO - #15 0x562ca9e2474f <unknown>
[2025-02-13T06:47:42.281-0500] {subprocess.py:106} INFO - #16 0x562ca9e79938 <unknown>
[2025-02-13T06:47:42.281-0500] {subprocess.py:106} INFO - #17 0x562ca9e79b00 <unknown>
[2025-02-13T06:47:42.283-0500] {subprocess.py:106} INFO - #18 0x562ca9e89c46 <unknown>
[2025-02-13T06:47:42.283-0500] {subprocess.py:106} INFO - #19 0x7f597ec8ca94 <unknown>
[2025-02-13T06:47:42.284-0500] {subprocess.py:106} INFO - #20 0x7f597ed19c3c <unknown>
[2025-02-13T06:47:42.285-0500] {subprocess.py:106} INFO - 
[2025-02-13T06:47:42.286-0500] {subprocess.py:106} INFO - 
[2025-02-13T06:47:42.318-0500] {subprocess.py:106} INFO - 2025-02-13 06:47:42,318 - bot_etl_ex_bbva - INFO - bot_etl_ex_bbva finish execution
[2025-02-13T06:47:42.324-0500] {subprocess.py:106} INFO - Traceback (most recent call last):
[2025-02-13T06:47:42.325-0500] {subprocess.py:106} INFO -   File "/opt/***/scripts/bot_etl_ex_bbva.py", line 136, in <module>
[2025-02-13T06:47:42.329-0500] {subprocess.py:106} INFO -     main()
[2025-02-13T06:47:42.330-0500] {subprocess.py:106} INFO -   File "/opt/***/scripts/bot_etl_ex_bbva.py", line 131, in main
[2025-02-13T06:47:42.334-0500] {subprocess.py:106} INFO -     driver.quit()
[2025-02-13T06:47:42.334-0500] {subprocess.py:106} INFO -   File "/home/***/.local/lib/python3.12/site-packages/selenium/webdriver/remote/webdriver.py", line 589, in quit
[2025-02-13T06:47:42.335-0500] {subprocess.py:106} INFO -     self.execute(Command.QUIT)
[2025-02-13T06:47:42.336-0500] {subprocess.py:106} INFO -   File "/home/***/.local/lib/python3.12/site-packages/selenium/webdriver/remote/webdriver.py", line 429, in execute
[2025-02-13T06:47:42.336-0500] {subprocess.py:106} INFO -     self.error_handler.check_response(response)
[2025-02-13T06:47:42.337-0500] {subprocess.py:106} INFO -   File "/home/***/.local/lib/python3.12/site-packages/selenium/webdriver/remote/errorhandler.py", line 232, in check_response
[2025-02-13T06:47:42.337-0500] {subprocess.py:106} INFO -     raise exception_class(message, screen, stacktrace)
[2025-02-13T06:47:42.338-0500] {subprocess.py:106} INFO - selenium.common.exceptions.InvalidSessionIdException: Message: Unable to find session with ID: 97eb7dc65779113675267ca90ef5f859
[2025-02-13T06:47:42.338-0500] {subprocess.py:106} INFO - Build info: version: '4.28.1', revision: '73f5ad48a2'
[2025-02-13T06:47:42.339-0500] {subprocess.py:106} INFO - System info: os.name: 'Linux', os.arch: 'amd64', os.version: '5.15.153.1-microsoft-standard-WSL2', java.version: '17.0.13'
[2025-02-13T06:47:42.339-0500] {subprocess.py:106} INFO - Driver info: driver.version: unknown
[2025-02-13T06:47:42.340-0500] {subprocess.py:106} INFO - Stacktrace:
[2025-02-13T06:47:42.340-0500] {subprocess.py:106} INFO - org.openqa.selenium.NoSuchSessionException: Unable to find session with ID: 97eb7dc65779113675267ca90ef5f859
[2025-02-13T06:47:42.341-0500] {subprocess.py:106} INFO - Build info: version: '4.28.1', revision: '73f5ad48a2'
[2025-02-13T06:47:42.341-0500] {subprocess.py:106} INFO - System info: os.name: 'Linux', os.arch: 'amd64', os.version: '5.15.153.1-microsoft-standard-WSL2', java.version: '17.0.13'
[2025-02-13T06:47:42.342-0500] {subprocess.py:106} INFO - Driver info: driver.version: unknown
[2025-02-13T06:47:42.343-0500] {subprocess.py:106} INFO - 	at org.openqa.selenium.grid.sessionmap.local.LocalSessionMap.get(LocalSessionMap.java:117)
[2025-02-13T06:47:42.343-0500] {subprocess.py:106} INFO - 	at org.openqa.selenium.grid.sessionmap.SessionMap.getUri(SessionMap.java:84)
[2025-02-13T06:47:42.344-0500] {subprocess.py:106} INFO - 	at org.openqa.selenium.grid.router.HandleSession.lambda$loadSessionId$4(HandleSession.java:225)
[2025-02-13T06:47:42.344-0500] {subprocess.py:106} INFO - 	at org.openqa.selenium.grid.router.HandleSession.execute(HandleSession.java:182)
[2025-02-13T06:47:42.345-0500] {subprocess.py:106} INFO - 	at org.openqa.selenium.remote.http.Route$PredicatedRoute.handle(Route.java:397)
[2025-02-13T06:47:42.345-0500] {subprocess.py:106} INFO - 	at org.openqa.selenium.remote.http.Route.execute(Route.java:69)
[2025-02-13T06:47:42.346-0500] {subprocess.py:106} INFO - 	at org.openqa.selenium.remote.http.Route$CombinedRoute.handle(Route.java:360)
[2025-02-13T06:47:42.346-0500] {subprocess.py:106} INFO - 	at org.openqa.selenium.remote.http.Route.execute(Route.java:69)
[2025-02-13T06:47:42.347-0500] {subprocess.py:106} INFO - 	at org.openqa.selenium.grid.router.Router.execute(Router.java:89)
[2025-02-13T06:47:42.347-0500] {subprocess.py:106} INFO - 	at org.openqa.selenium.grid.web.EnsureSpecCompliantResponseHeaders.lambda$apply$0(EnsureSpecCompliantResponseHeaders.java:34)
[2025-02-13T06:47:42.348-0500] {subprocess.py:106} INFO - 	at org.openqa.selenium.remote.http.Filter$1.execute(Filter.java:63)
[2025-02-13T06:47:42.348-0500] {subprocess.py:106} INFO - 	at org.openqa.selenium.remote.http.Route$CombinedRoute.handle(Route.java:360)
[2025-02-13T06:47:42.349-0500] {subprocess.py:106} INFO - 	at org.openqa.selenium.remote.http.Route.execute(Route.java:69)
[2025-02-13T06:47:42.350-0500] {subprocess.py:106} INFO - 	at org.openqa.selenium.remote.AddWebDriverSpecHeaders.lambda$apply$0(AddWebDriverSpecHeaders.java:35)
[2025-02-13T06:47:42.350-0500] {subprocess.py:106} INFO - 	at org.openqa.selenium.remote.ErrorFilter.lambda$apply$0(ErrorFilter.java:44)
[2025-02-13T06:47:42.351-0500] {subprocess.py:106} INFO - 	at org.openqa.selenium.remote.http.Filter$1.execute(Filter.java:63)
[2025-02-13T06:47:42.351-0500] {subprocess.py:106} INFO - 	at org.openqa.selenium.remote.ErrorFilter.lambda$apply$0(ErrorFilter.java:44)
[2025-02-13T06:47:42.352-0500] {subprocess.py:106} INFO - 	at org.openqa.selenium.remote.http.Filter$1.execute(Filter.java:63)
[2025-02-13T06:47:42.353-0500] {subprocess.py:106} INFO - 	at org.openqa.selenium.netty.server.SeleniumHandler.lambda$channelRead0$0(SeleniumHandler.java:49)
[2025-02-13T06:47:42.353-0500] {subprocess.py:106} INFO - 	at java.base/java.util.concurrent.Executors$RunnableAdapter.call(Executors.java:539)
[2025-02-13T06:47:42.354-0500] {subprocess.py:106} INFO - 	at java.base/java.util.concurrent.FutureTask.run(FutureTask.java:264)
[2025-02-13T06:47:42.355-0500] {subprocess.py:106} INFO - 	at java.base/java.util.concurrent.ThreadPoolExecutor.runWorker(ThreadPoolExecutor.java:1136)
[2025-02-13T06:47:42.357-0500] {subprocess.py:106} INFO - 	at java.base/java.util.concurrent.ThreadPoolExecutor$Worker.run(ThreadPoolExecutor.java:635)
[2025-02-13T06:47:42.358-0500] {subprocess.py:106} INFO - 	at java.base/java.lang.Thread.run(Thread.java:840)
[2025-02-13T06:47:42.359-0500] {subprocess.py:106} INFO - 
[2025-02-13T06:47:42.372-0500] {subprocess.py:110} INFO - Command exited with return code 1
[2025-02-13T06:47:42.385-0500] {taskinstance.py:3311} ERROR - Task failed with exception
Traceback (most recent call last):
  File "/home/airflow/.local/lib/python3.12/site-packages/airflow/models/taskinstance.py", line 767, in _execute_task
    result = _execute_callable(context=context, **execute_callable_kwargs)
             ^^^^^^^^^^^^^^^^^^^^^^^^^^^^^^^^^^^^^^^^^^^^^^^^^^^^^^^^^^^^^
  File "/home/airflow/.local/lib/python3.12/site-packages/airflow/models/taskinstance.py", line 733, in _execute_callable
    return ExecutionCallableRunner(
           ^^^^^^^^^^^^^^^^^^^^^^^^
  File "/home/airflow/.local/lib/python3.12/site-packages/airflow/utils/operator_helpers.py", line 252, in run
    return self.func(*args, **kwargs)
           ^^^^^^^^^^^^^^^^^^^^^^^^^^
  File "/home/airflow/.local/lib/python3.12/site-packages/airflow/models/baseoperator.py", line 422, in wrapper
    return func(self, *args, **kwargs)
           ^^^^^^^^^^^^^^^^^^^^^^^^^^^
  File "/home/airflow/.local/lib/python3.12/site-packages/airflow/operators/bash.py", line 276, in execute
    raise AirflowException(
airflow.exceptions.AirflowException: Bash command failed. The command returned a non-zero exit code 1.
[2025-02-13T06:47:42.392-0500] {taskinstance.py:1225} INFO - Marking task as FAILED. dag_id=etl_reporte_como_vamos, task_id=bot_ex_bbva, run_id=scheduled__2025-02-12T11:30:00+00:00, execution_date=20250212T113000, start_date=20250213T114727, end_date=20250213T114742
[2025-02-13T06:47:42.408-0500] {taskinstance.py:340} INFO - ::group::Post task execution logs
[2025-02-13T06:47:42.408-0500] {standard_task_runner.py:124} ERROR - Failed to execute job 110 for task bot_ex_bbva (Bash command failed. The command returned a non-zero exit code 1.; 43450)
Traceback (most recent call last):
  File "/home/airflow/.local/lib/python3.12/site-packages/airflow/task/task_runner/standard_task_runner.py", line 117, in _start_by_fork
    ret = args.func(args, dag=self.dag)
          ^^^^^^^^^^^^^^^^^^^^^^^^^^^^^
  File "/home/airflow/.local/lib/python3.12/site-packages/airflow/cli/cli_config.py", line 49, in command
    return func(*args, **kwargs)
           ^^^^^^^^^^^^^^^^^^^^^
  File "/home/airflow/.local/lib/python3.12/site-packages/airflow/utils/cli.py", line 116, in wrapper
    return f(*args, **kwargs)
           ^^^^^^^^^^^^^^^^^^
  File "/home/airflow/.local/lib/python3.12/site-packages/airflow/cli/commands/task_command.py", line 483, in task_run
    task_return_code = _run_task_by_selected_method(args, _dag, ti)
                       ^^^^^^^^^^^^^^^^^^^^^^^^^^^^^^^^^^^^^^^^^^^^
  File "/home/airflow/.local/lib/python3.12/site-packages/airflow/cli/commands/task_command.py", line 256, in _run_task_by_selected_method
    return _run_raw_task(args, ti)
           ^^^^^^^^^^^^^^^^^^^^^^^
  File "/home/airflow/.local/lib/python3.12/site-packages/airflow/cli/commands/task_command.py", line 341, in _run_raw_task
    return ti._run_raw_task(
           ^^^^^^^^^^^^^^^^^
  File "/home/airflow/.local/lib/python3.12/site-packages/airflow/utils/session.py", line 97, in wrapper
    return func(*args, session=session, **kwargs)
           ^^^^^^^^^^^^^^^^^^^^^^^^^^^^^^^^^^^^^^
  File "/home/airflow/.local/lib/python3.12/site-packages/airflow/models/taskinstance.py", line 3005, in _run_raw_task
    return _run_raw_task(
           ^^^^^^^^^^^^^^
  File "/home/airflow/.local/lib/python3.12/site-packages/airflow/models/taskinstance.py", line 273, in _run_raw_task
    TaskInstance._execute_task_with_callbacks(
  File "/home/airflow/.local/lib/python3.12/site-packages/airflow/models/taskinstance.py", line 3159, in _execute_task_with_callbacks
    result = self._execute_task(context, task_orig)
             ^^^^^^^^^^^^^^^^^^^^^^^^^^^^^^^^^^^^^^
  File "/home/airflow/.local/lib/python3.12/site-packages/airflow/models/taskinstance.py", line 3183, in _execute_task
    return _execute_task(self, context, task_orig)
           ^^^^^^^^^^^^^^^^^^^^^^^^^^^^^^^^^^^^^^^
  File "/home/airflow/.local/lib/python3.12/site-packages/airflow/models/taskinstance.py", line 767, in _execute_task
    result = _execute_callable(context=context, **execute_callable_kwargs)
             ^^^^^^^^^^^^^^^^^^^^^^^^^^^^^^^^^^^^^^^^^^^^^^^^^^^^^^^^^^^^^
  File "/home/airflow/.local/lib/python3.12/site-packages/airflow/models/taskinstance.py", line 733, in _execute_callable
    return ExecutionCallableRunner(
           ^^^^^^^^^^^^^^^^^^^^^^^^
  File "/home/airflow/.local/lib/python3.12/site-packages/airflow/utils/operator_helpers.py", line 252, in run
    return self.func(*args, **kwargs)
           ^^^^^^^^^^^^^^^^^^^^^^^^^^
  File "/home/airflow/.local/lib/python3.12/site-packages/airflow/models/baseoperator.py", line 422, in wrapper
    return func(self, *args, **kwargs)
           ^^^^^^^^^^^^^^^^^^^^^^^^^^^
  File "/home/airflow/.local/lib/python3.12/site-packages/airflow/operators/bash.py", line 276, in execute
    raise AirflowException(
airflow.exceptions.AirflowException: Bash command failed. The command returned a non-zero exit code 1.
[2025-02-13T06:47:42.446-0500] {local_task_job_runner.py:266} INFO - Task exited with return code 1
[2025-02-13T06:47:42.466-0500] {taskinstance.py:3895} INFO - 0 downstream tasks scheduled from follow-on schedule check
[2025-02-13T06:47:42.471-0500] {local_task_job_runner.py:245} INFO - ::endgroup::
