[2025-01-30T03:26:19.570+0000] {local_task_job_runner.py:123} INFO - ::group::Pre task execution logs
[2025-01-30T03:26:19.628+0000] {taskinstance.py:2613} INFO - Dependencies all met for dep_context=non-requeueable deps ti=<TaskInstance: etl_reporte_como_vamos.task_bot_como_vamos manual__2025-01-30T03:25:01.598874+00:00 [queued]>
[2025-01-30T03:26:19.648+0000] {taskinstance.py:2613} INFO - Dependencies all met for dep_context=requeueable deps ti=<TaskInstance: etl_reporte_como_vamos.task_bot_como_vamos manual__2025-01-30T03:25:01.598874+00:00 [queued]>
[2025-01-30T03:26:19.650+0000] {taskinstance.py:2866} INFO - Starting attempt 3 of 4
[2025-01-30T03:26:19.706+0000] {taskinstance.py:2889} INFO - Executing <Task(BashOperator): task_bot_como_vamos> on 2025-01-30 03:25:01.598874+00:00
[2025-01-30T03:26:19.733+0000] {warnings.py:112} WARNING - /home/***/.local/lib/python3.12/site-packages/***/task/task_runner/standard_task_runner.py:70: DeprecationWarning: This process (pid=2325) is multi-threaded, use of fork() may lead to deadlocks in the child.
  pid = os.fork()

[2025-01-30T03:26:19.740+0000] {standard_task_runner.py:72} INFO - Started process 2326 to run task
[2025-01-30T03:26:19.739+0000] {standard_task_runner.py:104} INFO - Running: ['***', 'tasks', 'run', 'etl_reporte_como_vamos', 'task_bot_como_vamos', 'manual__2025-01-30T03:25:01.598874+00:00', '--job-id', '22', '--raw', '--subdir', 'DAGS_FOLDER/etl_como_vamos_dag.py', '--cfg-path', '/tmp/tmp2yajdlnf']
[2025-01-30T03:26:19.744+0000] {standard_task_runner.py:105} INFO - Job 22: Subtask task_bot_como_vamos
[2025-01-30T03:26:19.870+0000] {task_command.py:467} INFO - Running <TaskInstance: etl_reporte_como_vamos.task_bot_como_vamos manual__2025-01-30T03:25:01.598874+00:00 [running]> on host 438c87da0b60
[2025-01-30T03:26:20.039+0000] {taskinstance.py:3132} INFO - Exporting env vars: AIRFLOW_CTX_DAG_OWNER='***' AIRFLOW_CTX_DAG_ID='etl_reporte_como_vamos' AIRFLOW_CTX_TASK_ID='task_bot_como_vamos' AIRFLOW_CTX_EXECUTION_DATE='2025-01-30T03:25:01.598874+00:00' AIRFLOW_CTX_TRY_NUMBER='3' AIRFLOW_CTX_DAG_RUN_ID='manual__2025-01-30T03:25:01.598874+00:00'
[2025-01-30T03:26:20.041+0000] {taskinstance.py:731} INFO - ::endgroup::
[2025-01-30T03:26:20.078+0000] {subprocess.py:78} INFO - Tmp dir root location: /tmp
[2025-01-30T03:26:20.080+0000] {subprocess.py:88} INFO - Running command: ['/usr/bin/bash', '-c', 'python /opt/***/scripts/bot_reporte_como_vamos.py']
[2025-01-30T03:26:20.098+0000] {subprocess.py:99} INFO - Output:
[2025-01-30T03:26:24.516+0000] {subprocess.py:106} INFO - ic| start_date: '01/01/2025', end_date: '30/01/2025'
[2025-01-30T03:26:24.518+0000] {subprocess.py:106} INFO - 2025-01-30 03:26:24,516 - bot_como_vamos - INFO - Starting script bot_como_vamos.py
[2025-01-30T03:26:24.673+0000] {subprocess.py:106} INFO - 2025-01-30 03:26:24,672 - bot_como_vamos - INFO - Conexi√≥n al Selenium Hub establecida correctamente
[2025-01-30T03:26:35.041+0000] {local_task_job_runner.py:346} WARNING - State of this instance has been externally set to restarting. Terminating instance.
[2025-01-30T03:26:35.042+0000] {local_task_job_runner.py:245} INFO - ::endgroup::
[2025-01-30T03:26:35.045+0000] {process_utils.py:132} INFO - Sending 15 to group 2326. PIDs of all processes in the group: [2328, 2326]
[2025-01-30T03:26:35.046+0000] {process_utils.py:87} INFO - Sending the signal 15 to group 2326
[2025-01-30T03:26:35.048+0000] {taskinstance.py:3093} ERROR - Received SIGTERM. Terminating subprocesses.
[2025-01-30T03:26:35.051+0000] {subprocess.py:117} INFO - Sending SIGTERM signal to process group
[2025-01-30T03:26:35.082+0000] {taskinstance.py:3311} ERROR - Task failed with exception
Traceback (most recent call last):
  File "/home/airflow/.local/lib/python3.12/site-packages/airflow/models/taskinstance.py", line 767, in _execute_task
    result = _execute_callable(context=context, **execute_callable_kwargs)
             ^^^^^^^^^^^^^^^^^^^^^^^^^^^^^^^^^^^^^^^^^^^^^^^^^^^^^^^^^^^^^
  File "/home/airflow/.local/lib/python3.12/site-packages/airflow/models/taskinstance.py", line 733, in _execute_callable
    return ExecutionCallableRunner(
           ^^^^^^^^^^^^^^^^^^^^^^^^
  File "/home/airflow/.local/lib/python3.12/site-packages/airflow/utils/operator_helpers.py", line 252, in run
    return self.func(*args, **kwargs)
           ^^^^^^^^^^^^^^^^^^^^^^^^^^
  File "/home/airflow/.local/lib/python3.12/site-packages/airflow/models/baseoperator.py", line 422, in wrapper
    return func(self, *args, **kwargs)
           ^^^^^^^^^^^^^^^^^^^^^^^^^^^
  File "/home/airflow/.local/lib/python3.12/site-packages/airflow/operators/bash.py", line 257, in execute
    result = self._run_inline_command(bash_path=bash_path, env=env)
             ^^^^^^^^^^^^^^^^^^^^^^^^^^^^^^^^^^^^^^^^^^^^^^^^^^^^^^
  File "/home/airflow/.local/lib/python3.12/site-packages/airflow/operators/bash.py", line 284, in _run_inline_command
    return self.subprocess_hook.run_command(
           ^^^^^^^^^^^^^^^^^^^^^^^^^^^^^^^^^
  File "/home/airflow/.local/lib/python3.12/site-packages/airflow/hooks/subprocess.py", line 104, in run_command
    for raw_line in iter(self.sub_process.stdout.readline, b""):
                    ^^^^^^^^^^^^^^^^^^^^^^^^^^^^^^^^^^^^^^^^^^^
  File "/home/airflow/.local/lib/python3.12/site-packages/airflow/models/taskinstance.py", line 3095, in signal_handler
    raise AirflowTaskTerminated("Task received SIGTERM signal")
airflow.exceptions.AirflowTaskTerminated: Task received SIGTERM signal
[2025-01-30T03:26:35.095+0000] {taskinstance.py:1225} INFO - Marking task as UP_FOR_RETRY. dag_id=etl_reporte_como_vamos, task_id=task_bot_como_vamos, run_id=manual__2025-01-30T03:25:01.598874+00:00, execution_date=20250130T032501, start_date=20250130T032619, end_date=20250130T032635
[2025-01-30T03:26:35.125+0000] {taskinstance.py:340} INFO - ::group::Post task execution logs
[2025-01-30T03:26:35.181+0000] {process_utils.py:80} INFO - Process psutil.Process(pid=2328, status='terminated', started='03:26:19') (2328) terminated with exit code None
[2025-01-30T03:26:35.183+0000] {process_utils.py:80} INFO - Process psutil.Process(pid=2326, status='terminated', exitcode=2, started='03:26:19') (2326) terminated with exit code 2
