[2025-01-30T00:39:25.874+0000] {local_task_job_runner.py:123} INFO - ::group::Pre task execution logs
[2025-01-30T00:39:25.914+0000] {taskinstance.py:2613} INFO - Dependencies all met for dep_context=non-requeueable deps ti=<TaskInstance: etl_reporte_como_vamos.task_bot_como_vamos manual__2025-01-30T00:39:23.899785+00:00 [queued]>
[2025-01-30T00:39:25.933+0000] {taskinstance.py:2613} INFO - Dependencies all met for dep_context=requeueable deps ti=<TaskInstance: etl_reporte_como_vamos.task_bot_como_vamos manual__2025-01-30T00:39:23.899785+00:00 [queued]>
[2025-01-30T00:39:25.935+0000] {taskinstance.py:2866} INFO - Starting attempt 1 of 2
[2025-01-30T00:39:25.974+0000] {taskinstance.py:2889} INFO - Executing <Task(BashOperator): task_bot_como_vamos> on 2025-01-30 00:39:23.899785+00:00
[2025-01-30T00:39:25.984+0000] {warnings.py:112} WARNING - /home/***/.local/lib/python3.12/site-packages/***/task/task_runner/standard_task_runner.py:70: DeprecationWarning: This process (pid=89) is multi-threaded, use of fork() may lead to deadlocks in the child.
  pid = os.fork()

[2025-01-30T00:39:25.989+0000] {standard_task_runner.py:72} INFO - Started process 90 to run task
[2025-01-30T00:39:25.988+0000] {standard_task_runner.py:104} INFO - Running: ['***', 'tasks', 'run', 'etl_reporte_como_vamos', 'task_bot_como_vamos', 'manual__2025-01-30T00:39:23.899785+00:00', '--job-id', '6', '--raw', '--subdir', 'DAGS_FOLDER/etl_como_vamos_dag.py', '--cfg-path', '/tmp/tmpv4slqnpe']
[2025-01-30T00:39:25.991+0000] {standard_task_runner.py:105} INFO - Job 6: Subtask task_bot_como_vamos
[2025-01-30T00:39:26.113+0000] {task_command.py:467} INFO - Running <TaskInstance: etl_reporte_como_vamos.task_bot_como_vamos manual__2025-01-30T00:39:23.899785+00:00 [running]> on host 438c87da0b60
[2025-01-30T00:39:26.291+0000] {taskinstance.py:3132} INFO - Exporting env vars: AIRFLOW_CTX_DAG_OWNER='***' AIRFLOW_CTX_DAG_ID='etl_reporte_como_vamos' AIRFLOW_CTX_TASK_ID='task_bot_como_vamos' AIRFLOW_CTX_EXECUTION_DATE='2025-01-30T00:39:23.899785+00:00' AIRFLOW_CTX_TRY_NUMBER='1' AIRFLOW_CTX_DAG_RUN_ID='manual__2025-01-30T00:39:23.899785+00:00'
[2025-01-30T00:39:26.293+0000] {taskinstance.py:731} INFO - ::endgroup::
[2025-01-30T00:39:26.327+0000] {subprocess.py:78} INFO - Tmp dir root location: /tmp
[2025-01-30T00:39:26.330+0000] {subprocess.py:88} INFO - Running command: ['/usr/bin/bash', '-c', 'python /opt/***/scripts/bot_reporte_como_vamos.py']
[2025-01-30T00:39:26.345+0000] {subprocess.py:99} INFO - Output:
[2025-01-30T00:39:31.671+0000] {subprocess.py:106} INFO - ic| start_date: '01/01/2025', end_date: '30/01/2025'
[2025-01-30T00:39:31.674+0000] {subprocess.py:106} INFO - 2025-01-30 00:39:31,671 - bot_como_vamos - INFO - Starting script bot_como_vamos.py
[2025-01-30T00:44:31.763+0000] {subprocess.py:106} INFO - Traceback (most recent call last):
[2025-01-30T00:44:31.765+0000] {subprocess.py:106} INFO -   File "/opt/***/scripts/bot_reporte_como_vamos.py", line 167, in <module>
[2025-01-30T00:44:31.770+0000] {subprocess.py:106} INFO -     main()
[2025-01-30T00:44:31.771+0000] {subprocess.py:106} INFO -   File "/opt/***/scripts/bot_reporte_como_vamos.py", line 82, in main
[2025-01-30T00:44:31.778+0000] {subprocess.py:106} INFO -     driver = webdriver.Remote(command_executor='http://selenium-hub:4444', options=chrome_options)
[2025-01-30T00:44:31.779+0000] {subprocess.py:106} INFO -              ^^^^^^^^^^^^^^^^^^^^^^^^^^^^^^^^^^^^^^^^^^^^^^^^^^^^^^^^^^^^^^^^^^^^^^^^^^^^^^^^^^^^^
[2025-01-30T00:44:31.780+0000] {subprocess.py:106} INFO -   File "/home/***/.local/lib/python3.12/site-packages/selenium/webdriver/remote/webdriver.py", line 250, in __init__
[2025-01-30T00:44:31.781+0000] {subprocess.py:106} INFO -     self.start_session(capabilities)
[2025-01-30T00:44:31.781+0000] {subprocess.py:106} INFO -   File "/home/***/.local/lib/python3.12/site-packages/selenium/webdriver/remote/webdriver.py", line 342, in start_session
[2025-01-30T00:44:31.782+0000] {subprocess.py:106} INFO -     response = self.execute(Command.NEW_SESSION, caps)["value"]
[2025-01-30T00:44:31.783+0000] {subprocess.py:106} INFO -                ^^^^^^^^^^^^^^^^^^^^^^^^^^^^^^^^^^^^^^^
[2025-01-30T00:44:31.783+0000] {subprocess.py:106} INFO -   File "/home/***/.local/lib/python3.12/site-packages/selenium/webdriver/remote/webdriver.py", line 429, in execute
[2025-01-30T00:44:31.784+0000] {subprocess.py:106} INFO -     self.error_handler.check_response(response)
[2025-01-30T00:44:31.784+0000] {subprocess.py:106} INFO -   File "/home/***/.local/lib/python3.12/site-packages/selenium/webdriver/remote/errorhandler.py", line 232, in check_response
[2025-01-30T00:44:31.785+0000] {subprocess.py:106} INFO -     raise exception_class(message, screen, stacktrace)
[2025-01-30T00:44:31.786+0000] {subprocess.py:106} INFO - selenium.common.exceptions.SessionNotCreatedException: Message: Could not start a new session. New session request timed out
[2025-01-30T00:44:31.786+0000] {subprocess.py:106} INFO - Host info: host: 'f4133a14f217', ip: '172.18.0.4'
[2025-01-30T00:44:31.787+0000] {subprocess.py:106} INFO - Build info: version: '4.28.1', revision: '73f5ad48a2'
[2025-01-30T00:44:31.788+0000] {subprocess.py:106} INFO - System info: os.name: 'Linux', os.arch: 'amd64', os.version: '5.15.153.1-microsoft-standard-WSL2', java.version: '17.0.13'
[2025-01-30T00:44:31.789+0000] {subprocess.py:106} INFO - Driver info: driver.version: unknown
[2025-01-30T00:44:31.789+0000] {subprocess.py:106} INFO - Stacktrace:
[2025-01-30T00:44:31.790+0000] {subprocess.py:106} INFO -     at org.openqa.selenium.grid.sessionqueue.local.LocalNewSessionQueue.addToQueue (LocalNewSessionQueue.java:224)
[2025-01-30T00:44:31.791+0000] {subprocess.py:106} INFO -     at org.openqa.selenium.grid.sessionqueue.NewSessionQueue.lambda$new$0 (NewSessionQueue.java:68)
[2025-01-30T00:44:31.792+0000] {subprocess.py:106} INFO -     at org.openqa.selenium.remote.http.Route$TemplatizedRoute.handle (Route.java:192)
[2025-01-30T00:44:31.793+0000] {subprocess.py:106} INFO -     at org.openqa.selenium.remote.http.Route.execute (Route.java:69)
[2025-01-30T00:44:31.793+0000] {subprocess.py:106} INFO -     at org.openqa.selenium.remote.http.Route$CombinedRoute.handle (Route.java:360)
[2025-01-30T00:44:31.794+0000] {subprocess.py:106} INFO -     at org.openqa.selenium.remote.http.Route.execute (Route.java:69)
[2025-01-30T00:44:31.795+0000] {subprocess.py:106} INFO -     at org.openqa.selenium.grid.sessionqueue.NewSessionQueue.execute (NewSessionQueue.java:128)
[2025-01-30T00:44:31.796+0000] {subprocess.py:106} INFO -     at org.openqa.selenium.remote.tracing.SpanWrappedHttpHandler.execute (SpanWrappedHttpHandler.java:87)
[2025-01-30T00:44:31.797+0000] {subprocess.py:106} INFO -     at org.openqa.selenium.remote.http.Filter$1.execute (Filter.java:63)
[2025-01-30T00:44:31.797+0000] {subprocess.py:106} INFO -     at org.openqa.selenium.remote.http.Route$CombinedRoute.handle (Route.java:360)
[2025-01-30T00:44:31.798+0000] {subprocess.py:106} INFO -     at org.openqa.selenium.remote.http.Route.execute (Route.java:69)
[2025-01-30T00:44:31.799+0000] {subprocess.py:106} INFO -     at org.openqa.selenium.grid.router.Router.execute (Router.java:89)
[2025-01-30T00:44:31.800+0000] {subprocess.py:106} INFO -     at org.openqa.selenium.grid.web.EnsureSpecCompliantResponseHeaders.lambda$apply$0 (EnsureSpecCompliantResponseHeaders.java:34)
[2025-01-30T00:44:31.800+0000] {subprocess.py:106} INFO -     at org.openqa.selenium.remote.http.Filter$1.execute (Filter.java:63)
[2025-01-30T00:44:31.801+0000] {subprocess.py:106} INFO -     at org.openqa.selenium.remote.http.Route$CombinedRoute.handle (Route.java:360)
[2025-01-30T00:44:31.802+0000] {subprocess.py:106} INFO -     at org.openqa.selenium.remote.http.Route.execute (Route.java:69)
[2025-01-30T00:44:31.803+0000] {subprocess.py:106} INFO -     at org.openqa.selenium.remote.AddWebDriverSpecHeaders.lambda$apply$0 (AddWebDriverSpecHeaders.java:35)
[2025-01-30T00:44:31.804+0000] {subprocess.py:106} INFO -     at org.openqa.selenium.remote.ErrorFilter.lambda$apply$0 (ErrorFilter.java:44)
[2025-01-30T00:44:31.805+0000] {subprocess.py:106} INFO -     at org.openqa.selenium.remote.http.Filter$1.execute (Filter.java:63)
[2025-01-30T00:44:31.806+0000] {subprocess.py:106} INFO -     at org.openqa.selenium.remote.ErrorFilter.lambda$apply$0 (ErrorFilter.java:44)
[2025-01-30T00:44:31.807+0000] {subprocess.py:106} INFO -     at org.openqa.selenium.remote.http.Filter$1.execute (Filter.java:63)
[2025-01-30T00:44:31.807+0000] {subprocess.py:106} INFO -     at org.openqa.selenium.netty.server.SeleniumHandler.lambda$channelRead0$0 (SeleniumHandler.java:49)
[2025-01-30T00:44:31.808+0000] {subprocess.py:106} INFO -     at java.util.concurrent.Executors$RunnableAdapter.call (Executors.java:539)
[2025-01-30T00:44:31.809+0000] {subprocess.py:106} INFO -     at java.util.concurrent.FutureTask.run (FutureTask.java:264)
[2025-01-30T00:44:31.810+0000] {subprocess.py:106} INFO -     at java.util.concurrent.ThreadPoolExecutor.runWorker (ThreadPoolExecutor.java:1136)
[2025-01-30T00:44:31.810+0000] {subprocess.py:106} INFO -     at java.util.concurrent.ThreadPoolExecutor$Worker.run (ThreadPoolExecutor.java:635)
[2025-01-30T00:44:31.811+0000] {subprocess.py:106} INFO -     at java.lang.Thread.run (Thread.java:840)
[2025-01-30T00:44:31.931+0000] {subprocess.py:110} INFO - Command exited with return code 1
[2025-01-30T00:44:31.943+0000] {taskinstance.py:3311} ERROR - Task failed with exception
Traceback (most recent call last):
  File "/home/airflow/.local/lib/python3.12/site-packages/airflow/models/taskinstance.py", line 767, in _execute_task
    result = _execute_callable(context=context, **execute_callable_kwargs)
             ^^^^^^^^^^^^^^^^^^^^^^^^^^^^^^^^^^^^^^^^^^^^^^^^^^^^^^^^^^^^^
  File "/home/airflow/.local/lib/python3.12/site-packages/airflow/models/taskinstance.py", line 733, in _execute_callable
    return ExecutionCallableRunner(
           ^^^^^^^^^^^^^^^^^^^^^^^^
  File "/home/airflow/.local/lib/python3.12/site-packages/airflow/utils/operator_helpers.py", line 252, in run
    return self.func(*args, **kwargs)
           ^^^^^^^^^^^^^^^^^^^^^^^^^^
  File "/home/airflow/.local/lib/python3.12/site-packages/airflow/models/baseoperator.py", line 422, in wrapper
    return func(self, *args, **kwargs)
           ^^^^^^^^^^^^^^^^^^^^^^^^^^^
  File "/home/airflow/.local/lib/python3.12/site-packages/airflow/operators/bash.py", line 276, in execute
    raise AirflowException(
airflow.exceptions.AirflowException: Bash command failed. The command returned a non-zero exit code 1.
[2025-01-30T00:44:31.952+0000] {taskinstance.py:1225} INFO - Marking task as UP_FOR_RETRY. dag_id=etl_reporte_como_vamos, task_id=task_bot_como_vamos, run_id=manual__2025-01-30T00:39:23.899785+00:00, execution_date=20250130T003923, start_date=20250130T003925, end_date=20250130T004431
[2025-01-30T00:44:31.981+0000] {taskinstance.py:340} INFO - ::group::Post task execution logs
[2025-01-30T00:44:31.982+0000] {standard_task_runner.py:124} ERROR - Failed to execute job 6 for task task_bot_como_vamos (Bash command failed. The command returned a non-zero exit code 1.; 90)
Traceback (most recent call last):
  File "/home/airflow/.local/lib/python3.12/site-packages/airflow/task/task_runner/standard_task_runner.py", line 117, in _start_by_fork
    ret = args.func(args, dag=self.dag)
          ^^^^^^^^^^^^^^^^^^^^^^^^^^^^^
  File "/home/airflow/.local/lib/python3.12/site-packages/airflow/cli/cli_config.py", line 49, in command
    return func(*args, **kwargs)
           ^^^^^^^^^^^^^^^^^^^^^
  File "/home/airflow/.local/lib/python3.12/site-packages/airflow/utils/cli.py", line 116, in wrapper
    return f(*args, **kwargs)
           ^^^^^^^^^^^^^^^^^^
  File "/home/airflow/.local/lib/python3.12/site-packages/airflow/cli/commands/task_command.py", line 483, in task_run
    task_return_code = _run_task_by_selected_method(args, _dag, ti)
                       ^^^^^^^^^^^^^^^^^^^^^^^^^^^^^^^^^^^^^^^^^^^^
  File "/home/airflow/.local/lib/python3.12/site-packages/airflow/cli/commands/task_command.py", line 256, in _run_task_by_selected_method
    return _run_raw_task(args, ti)
           ^^^^^^^^^^^^^^^^^^^^^^^
  File "/home/airflow/.local/lib/python3.12/site-packages/airflow/cli/commands/task_command.py", line 341, in _run_raw_task
    return ti._run_raw_task(
           ^^^^^^^^^^^^^^^^^
  File "/home/airflow/.local/lib/python3.12/site-packages/airflow/utils/session.py", line 97, in wrapper
    return func(*args, session=session, **kwargs)
           ^^^^^^^^^^^^^^^^^^^^^^^^^^^^^^^^^^^^^^
  File "/home/airflow/.local/lib/python3.12/site-packages/airflow/models/taskinstance.py", line 3005, in _run_raw_task
    return _run_raw_task(
           ^^^^^^^^^^^^^^
  File "/home/airflow/.local/lib/python3.12/site-packages/airflow/models/taskinstance.py", line 273, in _run_raw_task
    TaskInstance._execute_task_with_callbacks(
  File "/home/airflow/.local/lib/python3.12/site-packages/airflow/models/taskinstance.py", line 3159, in _execute_task_with_callbacks
    result = self._execute_task(context, task_orig)
             ^^^^^^^^^^^^^^^^^^^^^^^^^^^^^^^^^^^^^^
  File "/home/airflow/.local/lib/python3.12/site-packages/airflow/models/taskinstance.py", line 3183, in _execute_task
    return _execute_task(self, context, task_orig)
           ^^^^^^^^^^^^^^^^^^^^^^^^^^^^^^^^^^^^^^^
  File "/home/airflow/.local/lib/python3.12/site-packages/airflow/models/taskinstance.py", line 767, in _execute_task
    result = _execute_callable(context=context, **execute_callable_kwargs)
             ^^^^^^^^^^^^^^^^^^^^^^^^^^^^^^^^^^^^^^^^^^^^^^^^^^^^^^^^^^^^^
  File "/home/airflow/.local/lib/python3.12/site-packages/airflow/models/taskinstance.py", line 733, in _execute_callable
    return ExecutionCallableRunner(
           ^^^^^^^^^^^^^^^^^^^^^^^^
  File "/home/airflow/.local/lib/python3.12/site-packages/airflow/utils/operator_helpers.py", line 252, in run
    return self.func(*args, **kwargs)
           ^^^^^^^^^^^^^^^^^^^^^^^^^^
  File "/home/airflow/.local/lib/python3.12/site-packages/airflow/models/baseoperator.py", line 422, in wrapper
    return func(self, *args, **kwargs)
           ^^^^^^^^^^^^^^^^^^^^^^^^^^^
  File "/home/airflow/.local/lib/python3.12/site-packages/airflow/operators/bash.py", line 276, in execute
    raise AirflowException(
airflow.exceptions.AirflowException: Bash command failed. The command returned a non-zero exit code 1.
[2025-01-30T00:44:32.011+0000] {local_task_job_runner.py:266} INFO - Task exited with return code 1
[2025-01-30T00:44:32.041+0000] {taskinstance.py:3895} INFO - 0 downstream tasks scheduled from follow-on schedule check
[2025-01-30T00:44:32.045+0000] {local_task_job_runner.py:245} INFO - ::endgroup::
